Workbook

Sheet PYG 
A1: EQUIORIENTE LTDA
A2: INFORMES FINAL AÑO 2019
C4: ENERO 2019 | G4: FEBRERO 2019 | J4: MARZO 2019 | N4: ABRIL 2019 | R4: MAYO 2019 | V4: JUNIO 2019 | Y4: JULIO 2019 | AC4: AGOSTO 2019 | AG4: SEPTIEMBRE 2019 | AK4: OCTUBRE 2019 | AO4: NOVIEMBRE 2019 | AS4: DICIEMBRE 2019
A5: Cuenta | C5: Mov. 02/01/2019 a 31/01/2019 | E5: Saldos a 31/01/2019 | G5: Mov. 01/02/2019 a 28/02/2019 | I5: Saldos a 28/02/2019 | J5: Mov. 01/03/2019 a 31/03/2019 | L5: Saldos a 31/03/2019 | N5: Mov. 01/04/2019 a 30/04/2019 | P5: Saldos a 30/04/2019 | R5: Mov. 02/05/2019 a 31/05/2019 | T5: Saldos a 31/01/2019 | V5: Mov. 01/06/2019 a 30/06/2019 | X5: Saldos a 28/06/2019 | Y5: Mov. 01/07/2019 a 31/07/2019 | AA5: Saldos a 31/07/2019 | AC5: Mov. 01/08/2019 a 30/08/2019 | AE5: Saldos a 30/08/2019 | AG5: Mov. 01/09/2019 a 31/09/2019 | AI5: Saldos a 31/09/2019 | AK5: Mov. 01/10/2019 a 31/10/2019 | AM5: Saldos a 31/10/2019 | AO5: Mov. 01/11/2019 a 30/11/2019 | AQ5: Saldos a 30/11/2019 | AS5: Mov. 01/12/2019 a 30/12/2019 | AU5: Saldos a 31/12/2019
A6: Cód. | B6: Nombre | C6: Débitos | D6: Créditos | E6: Saldo actual | G6: Débitos | H6: Créditos | I6: Saldo actual | J6: Débitos | K6: Créditos | L6: Saldo actual | N6: Débitos | O6: Créditos | P6: Saldo actual | R6: Débitos | S6: Créditos | T6: Saldo actual | V6: Débitos | W6: Créditos | X6: Saldo actual | Y6: Débitos | Z6: Créditos | AA6: Saldo actual | AC6: Débitos | AD6: Créditos | AE6: Saldo actual | AG6: Débitos | AH6: Créditos | AI6: Saldo actual | AK6: Débitos | AL6: Créditos | AM6: Saldo actual | AO6: Débitos | AP6: Créditos | AQ6: Saldo actual | AS6: Débitos | AT6: Créditos | AU6: Saldo actual
A7: 4 | B7: INGRESOS | C7: 0 | D7: =D8+D14 -> 15080037 | E7: =E8+E14 -> 15080037 | G7: 0 | H7: =H8+H14 -> 13559340 | I7: =E7+H7 -> 28639377 | J7: 0 | K7: =K8+K14 -> 12451739 | L7: =I7+K7 -> 41091116 | N7: 0 | O7: =O8+O14 -> 16172397 | P7: =L7+O7 -> 57263513 | R7: 0 | S7: =S8+S14 -> 13539222 | T7: =+P7+S7 -> 70802735 | V7: 0 | W7: =W8+W14 -> 10214483 | X7: =+T7+W7 -> 81017218 | Y7: 0 | Z7: =Z8+Z14 -> 7723804 | AA7: =+X7+Z7 -> 88741022 | AC7: 0 | AD7: =AD8+AD14 -> 10099562 | AE7: =AA7+AD7 -> 98840584 | AG7: 0 | AH7: =AH8+AH14 -> 8971745 | AI7: =AE7+AH7 -> 107812329 | AK7: 0 | AL7: =AL8+AL14 -> 9132517 | AM7: =AI7+AL7 -> 116944846 | AO7: 0 | AP7: =AP8+AP14 -> 14339766 | AQ7: =AM7+AP7 -> 131284612 | AS7: 0 | AT7: =AT8+AT14 -> 15672122 | AU7: =AQ7+AT7 -> 146956734
A8: 41 | B8: Operacionales | C8: 0 | D8: =D9 -> 5232922 | E8: =E9 -> 5232922 | G8: 0 | H8: =H9 -> 6735984 | I8: =E8+H8 -> 11968906 | J8: 0 | K8: =K9 -> 4072345 | L8: =I8+K8 -> 16041251 | N8: 0 | O8: =O9 -> 8902568 | P8: =L8+O8 -> 24943819 | R8: 0 | S8: =S9 -> 4831245 | T8: =+P8+S8 -> 29775064 | V8: 0 | W8: =W9 -> 2541098 | X8: =T8+W8 -> 32316162 | Y8: 0 | Z8: =Z9 -> 2060928 | AA8: =+X8+Z8 -> 34377090 | AC8: 0 | AD8: =AD9 -> 722060 | AE8: =AA8+AD8 -> 35099150 | AG8: 0 | AH8: =AH9 -> 1921510 | AI8: =AE8+AH8 -> 37020660 | AK8: 0 | AL8: =AL9 -> 1940050 | AM8: =AI8+AL8 -> 38960710 | AO8: =AK8+AN8 -> 0 | AP8: =AP9 -> 6096979 | AQ8: =AM8+AP8 -> 45057689 | AS8: =AO8+AR8 -> 0 | AT8: =AT9 -> 10802895 | AU8: =AQ8+AT8 -> 55860584
A9: 4155 | B9: Actividades inmobiliarias, empresariales y de alquiler | C9: 0 | D9: =+D10+D11+D12 -> 5232922 | E9: =D9 -> 5232922 | G9: 0 | H9: =+H10+H11+H12 -> 6735984 | I9: =E9+H9 -> 11968906 | J9: 0 | K9: =K10+K11+K12 -> 4072345 | L9: =I9+K9 -> 16041251 | N9: 0 | O9: =O10+O11+O12 -> 8902568 | P9: =L9+O9 -> 24943819 | R9: 0 | S9: =+S10+S11+S12 -> 4831245 | T9: =+P9+S9 -> 29775064 | V9: 0 | W9: =+W10+W11+W12 -> 2541098 | X9: =T9+W9 -> 32316162 | Y9: 0 | Z9: =+Z10+Z12 -> 2060928 | AA9: =+AA10+AA11+AA12 -> 34377090 | AC9: 0 | AD9: =+AD10+AD11+AD12 -> 722060 | AE9: =AA9+AD9 -> 35099150 | AG9: =AC9+AF9 -> 0 | AH9: =+AH10+AH11+AH12 -> 1921510 | AI9: =AE9+AH9 -> 37020660 | AK9: =AG9+AJ9 -> 0 | AL9: =+AL10+AL11+AL12 -> 1940050 | AM9: =AI9+AL9 -> 38960710 | AO9: =AK9+AN9 -> 0 | AP9: =+AP10+AP11+AP12 -> 6096979 | AQ9: =AM9+AP9 -> 45057689 | AS9: =AO9+AR9 -> 0 | AT9: =+AT10+AT11+AT12 -> 10802895 | AU9: =AQ9+AT9 -> 55860584
A10: 415520 | B10: Alquiler IVA | C10: 0 | D10: 4907922 | E10: =+D10 -> 4907922 | G10: 0 | H10: 6635984 | I10: =E10+H10 -> 11543906 | J10: 0 | K10: 4072345 | L10: =I10+K10 -> 15616251 | N10: 0 | O10: 8155068 | P10: =L10+O10 -> 23771319 | R10: 0 | S10: 4596245 | T10: =+P10+S10 -> 28367564 | V10: 0 | W10: 2343598 | X10: =T10+W10 -> 30711162 | Y10: 0 | Z10: 1900928 | AA10: =+X10+Z10 -> 32612090 | AC10: 0 | AD10: 497060 | AE10: =AA10+AD10 -> 33109150 | AG10: 0 | AH10: 1771510 | AI10: =AE10+AH10 -> 34880660 | AK10: 0 | AL10: 1735050 | AM10: =AI10+AL10 -> 36615710 | AO10: 0 | AP10: 5463429 | AQ10: =AM10+AP10 -> 42079139 | AS10: 0 | AT10: 10412895 | AU10: =AQ10+AT10 -> 52492034
A11: 415525 | B11: VENTA EQUIPO | D11: 0 | E11: =+D11 -> 0 | G11: 0 | H11: 0 | I11: =E11+H11 -> 0 | K11: =+K12 -> 0 | L11: =I11+K11 -> 0 | O11: 0 | P11: =L11+O11 -> 0 | S11: 0 | T11: =+P11+S11 -> 0 | V11: 0 | W11: 0 | X11: =T11+W11 -> 0 | Y11: 0 | Z11: 0 | AA11: =+X11+Z11 -> 0 | AC11: 0 | AD11: 0 | AE11: =AA11+AD11 -> 0 | AG11: 0 | AH11: 0 | AI11: =AE11+AH11 -> 0 | AK11: 0 | AL11: 0 | AM11: =AI11+AL11 -> 0 | AO11: 0 | AP11: 168550 | AQ11: =AM11+AP11 -> 168550 | AS11: 0 | AT11: 0 | AU11: =AQ11+AT11 -> 168550
A12: 415515 | B12: Transporte | C12: 0 | D12: 325000 | E12: =+D12 -> 325000 | G12: 0 | H12: 100000 | I12: =E12+H12 -> 425000 | J12: 0 | K12: 0 | L12: =I12+K12 -> 425000 | N12: 0 | O12: 747500 | P12: =L12+O12 -> 1172500 | R12: 0 | S12: 235000 | T12: =+P12+S12 -> 1407500 | V12: 0 | W12: 197500 | X12: =T12+W12 -> 1605000 | Y12: 0 | Z12: 160000 | AA12: =+X12+Z12 -> 1765000 | AC12: 0 | AD12: 225000 | AE12: =AA12+AD12 -> 1990000 | AG12: 0 | AH12: 150000 | AI12: =AE12+AH12 -> 2140000 | AK12: 0 | AL12: 205000 | AM12: =AI12+AL12 -> 2345000 | AO12: 0 | AP12: 465000 | AQ12: =AM12+AP12 -> 2810000 | AS12: 0 | AT12: 390000 | AU12: =AQ12+AT12 -> 3200000
L13: =I13+K13 -> 0 | AA13: =+X13+Z13 -> 0
A14: 42 | B14: No operacionales | C14: 0 | D14: =D15+D19+D22 -> 9847115 | E14: =+D14 -> 9847115 | G14: 0 | H14: =H15+H19+H22+H24 -> 6823356 | I14: =E14+H14 -> 16670471 | J14: 0 | K14: =K15+K19+K22 -> 8379394 | L14: =I14+K14 -> 25049865 | N14: 0 | O14: =O15+O19+O22 -> 7269829 | P14: =L14+O14 -> 32319694 | R14: 0 | S14: =S15+S19+S22+S24 -> 8707977 | T14: =+P14+S14 -> 41027671 | V14: 0 | W14: =+W15+W19+W22+W24 -> 7673385 | X14: =+T14+W14 -> 48701056 | Y14: 0 | Z14: =+Z15+Z19+Z22+Z24 -> 5662876 | AA14: =X14+Z14 -> 54363932 | AC14: 0 | AD14: =AD15+AD19+AD22+AD24 -> 9377502 | AE14: =AA14+AD14 -> 63741434 | AG14: 0 | AH14: =AH15+AH19+AH22+AH24 -> 7050235 | AI14: =AE14+AH14 -> 70791669 | AK14: 0 | AL14: =AL15+AL19+AL22+AL24 -> 7192467 | AM14: =AI14+AL14 -> 77984136 | AO14: 0 | AP14: =AP15+AP19+AP22+AP24 -> 8242787 | AQ14: =AM14+AP14 -> 86226923 | AS14: 0 | AT14: =AT15+AT19+AT22+AT24 -> 4869227 | AU14: =AQ14+AT14 -> 91096150
A15: 4210 | B15: Financieros | C15: 0 | D15: 8491 | E15: =+D15 -> 8491 | G15: 0 | H15: =+H16 -> 11670 | I15: =E15+H15 -> 20161 | J15: 0 | K15: 14542 | L15: =I15+K15 -> 34703 | N15: 0 | O15: =O16 -> 16079 | P15: =L15+O15 -> 50782 | R15: 0 | S15: 12936 | T15: =+P15+S15 -> 63718 | V15: 0 | W15: =+W16+W17 -> 171494 | X15: =+T15+W15 -> 235212 | Y15: 0 | Z15: =+Z16+Z17 -> 76252 | AA15: =+X15+Z15 -> 311464 | AC15: 0 | AD15: =+AD16+AD17 -> 73730 | AE15: =AA15+AD15 -> 385194 | AG15: 0 | AH15: =+AH16+AH17 -> 69406 | AI15: =AE15+AH15 -> 454600 | AK15: 0 | AL15: =+AL16+AL17 -> 64152 | AM15: =AI15+AL15 -> 518752 | AO15: 0 | AP15: =+AP16+AP17 -> 56845 | AQ15: =AM15+AP15 -> 575597 | AS15: 0 | AT15: =+AT16+AT17 -> 103419 | AU15: =AQ15+AT15 -> 679016
A16: 421005 | B16: Intereses | C16: 0 | D16: =+D15 -> 8491 | E16: =+D16 -> 8491 | G16: 0 | H16: 11670 | I16: =E16+H16 -> 20161 | J16: 0 | K16: =+K15 -> 14542 | L16: =I16+K16 -> 34703 | N16: 0 | O16: 16079 | P16: =L16+O16 -> 50782 | R16: 0 | S16: =+S15 -> 12936 | T16: =+P16+S16 -> 63718 | V16: 0 | W16: 104053 | X16: =+T16+W16 -> 167771 | Y16: 0 | Z16: 11408 | AA16: =+X16+Z16 -> 179179 | AC16: 0 | AD16: 11503 | AE16: =AA16+AD16 -> 190682 | AG16: 0 | AH16: 9812 | AI16: =AE16+AH16 -> 200494 | AK16: 0 | AL16: 7209 | AM16: =AI16+AL16 -> 207703 | AO16: 0 | AP16: 2571 | AQ16: =AM16+AP16 -> 210274 | AS16: 0 | AT16: 245 | AU16: =AQ16+AT16 -> 210519
A17: 421095 | B17: intereses prestamos socios | W17: 67441 | X17: =+T17+W17 -> 67441 | Z17: 64844 | AA17: =+X17+Z17 -> 132285 | AD17: 62227 | AE17: =AA17+AD17 -> 194512 | AH17: 59594 | AI17: =AE17+AH17 -> 254106 | AL17: 56943 | AM17: =AI17+AL17 -> 311049 | AP17: 54274 | AQ17: =AM17+AP17 -> 365323 | AT17: 103174 | AU17: =AQ17+AT17 -> 468497
L18: =I18+K18 -> 0 | T18: =+P18+S18 -> 0 | X18: =+T18+W18 -> 0 | AA18: =+X18+Z18 -> 0 | AE18: =AA18+AD18 -> 0 | AI18: =AE18+AH18 -> 0 | AM18: =AI18+AL18 -> 0 | AQ18: =AM18+AP18 -> 0 | AU18: =AQ18+AT18 -> 0
A19: 4220 | B19: ARRENDAMIENTOS APARTAMENTOS | C19: 0 | D19: =D20 -> 1849000 | E19: =+D19 -> 1849000 | G19: 0 | H19: =H20 -> 1849000 | I19: =E19+H19 -> 3698000 | J19: 0 | K19: 1249000 | L19: =I19+K19 -> 4947000 | N19: 0 | O19: =O20 -> 1268900 | P19: =L19+O19 -> 6215900 | R19: 0 | S19: 1288800 | T19: =+P19+S19 -> 7504700 | V19: 0 | W19: 1288800 | X19: =+T19+W19 -> 8793500 | Y19: 0 | Z19: 1288800 | AA19: =+X19+Z19 -> 10082300 | AC19: 0 | AD19: 1288800 | AE19: =AA19+AD19 -> 11371100 | AG19: 0 | AH19: 1288800 | AI19: =AE19+AH19 -> 12659900 | AK19: 0 | AL19: 1288800 | AM19: =AI19+AL19 -> 13948700 | AO19: 0 | AP19: 1288800 | AQ19: =AM19+AP19 -> 15237500 | AS19: 0 | AT19: 1288800 | AU19: =AQ19+AT19 -> 16526300
A20: 422010 | B20: Apartamentos Arrendados | C20: 0 | D20: 1849000 | E20: =+D20 -> 1849000 | G20: 0 | H20: 1849000 | I20: =E20+H20 -> 3698000 | J20: 0 | K20: =+K19 -> 1249000 | L20: =I20+K20 -> 4947000 | N20: 0 | O20: 1268900 | P20: =L20+O20 -> 6215900 | R20: 0 | S20: =+S19 -> 1288800 | T20: =+P20+S20 -> 7504700 | V20: 0 | W20: =+W19 -> 1288800 | X20: =+T20+W20 -> 8793500 | Y20: 0 | Z20: =+Z19 -> 1288800 | AA20: =+X20+Z20 -> 10082300 | AC20: 0 | AD20: =+AD19 -> 1288800 | AE20: =AA20+AD20 -> 11371100 | AG20: 0 | AH20: =+AH19 -> 1288800 | AI20: =AE20+AH20 -> 12659900 | AK20: 0 | AL20: =+AL19 -> 1288800 | AM20: =AI20+AL20 -> 13948700 | AO20: 0 | AP20: =+AP19 -> 1288800 | AQ20: =AM20+AP20 -> 15237500 | AS20: 0 | AT20: =+AT19 -> 1288800 | AU20: =AQ20+AT20 -> 16526300
L21: =I21+K21 -> 0 | T21: =+P21+S21 -> 0 | X21: =+T21+W21 -> 0 | AA21: =+X21+Z21 -> 0
A22: 4235 | B22: Servicios | C22: 0 | D22: =D23 -> 7989624 | E22: =+D22 -> 7989624 | G22: 0 | H22: =H23 -> 4962680 | I22: =E22+H22 -> 12952304 | J22: 0 | K22: =K23 -> 7115852 | L22: =I22+K22 -> 20068156 | N22: 0 | O22: =O23 -> 5984850 | P22: =L22+O22 -> 26053006 | R22: 0 | S22: =S23 -> 7406240 | T22: =+P22+S22 -> 33459246 | V22: 0 | W22: =+W23 -> 6213000 | X22: =+T22+W22 -> 39672246 | Y22: 0 | Z22: 4295391 | AA22: =+X22+Z22 -> 43967637 | AC22: 0 | AD22: =AD23 -> 8014677 | AE22: =AA22+AD22 -> 51982314 | AG22: 0 | AH22: =AH23 -> 5691827 | AI22: =AE22+AH22 -> 57674141 | AK22: 0 | AL22: =AL23 -> 5839339 | AM22: =AI22+AL22 -> 63513480 | AO22: 0 | AP22: =AP23 -> 6896946 | AQ22: =AM22+AP22 -> 70410426 | AS22: 0 | AT22: =AT23 -> 3471702 | AU22: =AQ22+AT22 -> 73882128
A23: 423510 | B23: VENTAS SIN IVA | C23: 0 | D23: 7989624 | E23: =+D23 -> 7989624 | G23: 0 | H23: 4962680 | I23: =E23+H23 -> 12952304 | J23: 0 | K23: 7115852 | L23: =I23+K23 -> 20068156 | N23: 0 | O23: 5984850 | P23: =L23+O23 -> 26053006 | R23: 0 | S23: 7406240 | T23: =+P23+S23 -> 33459246 | V23: 0 | W23: 6213000 | X23: =+T23+W23 -> 39672246 | Y23: 0 | Z23: =+Z22 -> 4295391 | AA23: =+X23+Z23 -> 43967637 | AC23: 0 | AD23: 8014677 | AE23: =AA23+AD23 -> 51982314 | AG23: 0 | AH23: 5691827 | AI23: =AE23+AH23 -> 57674141 | AK23: 0 | AL23: 5839339 | AM23: =AI23+AL23 -> 63513480 | AO23: 0 | AP23: 6896946 | AQ23: =AM23+AP23 -> 70410426 | AS23: 0 | AT23: 3471702 | AU23: =AQ23+AT23 -> 73882128
A24: 4295 | B24: DIVERSOS | C24: 0 | D24: 0 | E24: =+D24 -> 0 | G24: 0 | H24: =+H25 -> 6 | I24: =E24+H24 -> 6 | J24: 0 | K24: =+K25 -> 43 | L24: =I24+K24 -> 49 | N24: 0 | O24: =+O25 -> 75 | P24: =L24+O24 -> 124 | R24: 0 | S24: 1 | T24: =+P24+S24 -> 125 | V24: 0 | W24: 91 | X24: =+T24+W24 -> 216 | Y24: 0 | Z24: 2433 | AA24: =+X24+Z24 -> 2649 | AC24: 0 | AD24: =175+120 -> 295 | AE24: =AA24+AD24 -> 2944 | AG24: 0 | AH24: =+AH25 -> 202 | AI24: =AE24+AH24 -> 3146 | AK24: 0 | AL24: =+AL25 -> 176 | AM24: =AI24+AL24 -> 3322 | AO24: 0 | AP24: =+AP25 -> 196 | AQ24: =AM24+AP24 -> 3518 | AS24: 0 | AT24: =+AT25 -> 5306 | AU24: =AQ24+AT24 -> 8824
A25: 429581 | B25: Ajuste al peso | C25: 0 | D25: 0 | E25: =+D25 -> 0 | G25: 0 | H25: 6 | I25: =E25+H25 -> 6 | J25: 0 | K25: 43 | L25: =I25+K25 -> 49 | N25: 0 | O25: 75 | P25: =L25+O25 -> 124 | R25: 0 | S25: 1 | T25: =+P25+S25 -> 125 | V25: 0 | W25: 91 | X25: =+T25+W25 -> 216 | Y25: 0 | Z25: =+Z24 -> 2433 | AA25: =+X25+Z25 -> 2649 | AC25: 0 | AD25: =+AD24 -> 295 | AE25: =AA25+AD25 -> 2944 | AG25: 0 | AH25: 202 | AI25: =AE25+AH25 -> 3146 | AK25: 0 | AL25: 176 | AM25: =AI25+AL25 -> 3322 | AO25: 0 | AP25: 196 | AQ25: =AM25+AP25 -> 3518 | AS25: 0 | AT25: 5306 | AU25: =AQ25+AT25 -> 8824
A27: 5 | B27: GASTOS | C27: =C28+C136+C114 -> 8400620 | D27: 0 | E27: =+C27 -> 8400620 | G27: =G28+G136+G114 -> 9693071 | H27: 0 | I27: =E27+G27 -> 18093691 | J27: =J28+J136+J114 -> 8371715 | K27: 0 | L27: =I27+J27 -> 26465406 | N27: =N28+N136+N114 -> 12711829 | O27: 0 | P27: =L27+N27 -> 39177235 | R27: =R28+R136+R114 -> 10565555 | S27: 0 | T27: =+P27+R27 -> 49742790 | V27: =V28+V136+V114 -> 8819295 | W27: 0 | X27: =T27+V27 -> 58562085 | Y27: =Y28+Y136+Y114 -> 9153751 | Z27: 0 | AA27: =X27+Y27 -> 67715836 | AC27: =AC28+AC136+AC114 -> 13697507 | AD27: 0 | AE27: =AA27+AC27 -> 81413343 | AG27: =AG28+AG136+AG114 -> 12742610 | AH27: 0 | AI27: =AE27+AG27 -> 94155953 | AK27: =AK28+AK136+AK114 -> 14189430 | AL27: 0 | AM27: =AI27+AK27 -> 1.0834538e+08 | AO27: =AO28+AO136+AO114 -> 12547220 | AP27: 0 | AQ27: =AM27+AO27 -> 1.208926e+08 | AS27: =AS28+AS136+AS114 -> 9955164.8 | AT27: 0 | AU27: =AQ27+AS27 -> 130847767
A28: 51 | B28: Operacionales de administración | C28: =C29+C44+C55+C49+C62+C65+C75+C81+C87+C101+C59 -> 8116046 | D28: 0 | E28: =+C28 -> 8116046 | G28: =G29+G44+G49+G55+G62+G65+G75+G81+G87+G101 -> 7966455 | H28: 0 | I28: =E28+G28 -> 16082501 | J28: =J29+J44+J49+J55+J62+J65+J75+J81+J87+J101 -> 7903971 | K28: 0 | L28: =I28+J28 -> 23986472 | N28: =N29+N44+N49+N55+N62+N65+N75+N81+N87+N101 -> 11049135 | O28: 0 | P28: =L28+N28 -> 35035607 | R28: =R29+R44+R55+R49+R62+R65+R75+R81+R87+R101+R59 -> 9890052 | S28: 0 | T28: =+P28+R28 -> 44925659 | V28: =V29+V44+V49+V55+V62+V65+V75+V81+V87+V101 -> 8345602 | W28: 0 | X28: =T28+V28 -> 53271261 | Y28: =Y29+Y44+Y49+Y55+Y62+Y65+Y75+Y81+Y87+Y101 -> 8661808 | Z28: 0 | AA28: =X28+Y28 -> 61933069 | AC28: =AC29+AC44+AC49+AC55+AC62+AC65+AC75+AC81+AC87+AC101 -> 10142788 | AD28: 0 | AE28: =AA28+AC28 -> 72075857 | AG28: =AG29+AG44+AG49+AG55+AG62+AG65+AG75+AG81+AG87+AG101+AG93 -> 12198219 | AH28: 0 | AI28: =AE28+AG28 -> 84274076 | AK28: =AK29+AK44+AK49+AK55+AK62+AK65+AK75+AK81+AK87+AK101+AK93 -> 13649169 | AL28: 0 | AM28: =AI28+AK28 -> 97923244 | AO28: =AO29+AO44+AO49+AO55+AO62+AO65+AO75+AO81+AO87+AO101+AO93 -> 12035857 | AP28: 0 | AQ28: =AM28+AO28 -> 1.099591e+08 | AS28: =AS29+AS44+AS49+AS55+AS62+AS65+AS75+AS81+AS87+AS101+AS93 -> 9451620.8 | AT28: 0 | AU28: =AQ28+AS28 -> 119410722
A29: 5105 | B29: Gastos de personal | C29: =C30+C32+C33+C34+C35+C36+C37+C38+C39+C40+C41+C42 -> 1600392 | D29: 0 | E29: =+C29 -> 1600392 | G29: =SUM(G30:G42) -> 4130279 | H29: 0 | I29: =E29+G29 -> 5730671 | J29: =SUM(J30:J42) -> 4439790 | K29: 0 | L29: =I29+J29 -> 10170461 | N29: =N30+N32+N33+N34+N35+N36+N37+N38+N39+N40+N41+N42 -> 4419929 | O29: 0 | P29: =L29+N29 -> 14590390 | R29: =SUM(R30:R42) -> 4484929 | S29: 0 | T29: =+P29+R29 -> 19075319 | V29: =SUM(V30:V42) -> 4419929 | W29: 0 | X29: =T29+V29 -> 23495248 | Y29: =SUM(Y30:Y42) -> 4836778 | Z29: 0 | AA29: =X29+Y29 -> 28332026 | AC29: =AC30+AC32+AC33+AC34+AC35+AC36+AC37+AC38+AC39+AC40+AC41+AC42 -> 4599929 | AD29: 0 | AE29: =AA29+AC29 -> 32931955 | AG29: =AG30+AG32+AG33+AG34+AG35+AG36+AG37+AG38+AG39+AG40+AG41+AG42 -> 4419929 | AH29: 0 | AI29: =AE29+AG29 -> 37351884 | AK29: =AK30+AK32+AK33+AK34+AK35+AK36+AK37+AK38+AK39+AK40+AK41+AK42 -> 4419929 | AL29: 0 | AM29: =AI29+AK29 -> 41771813 | AO29: =AO30+AO32+AO33+AO34+AO35+AO36+AO37+AO38+AO39+AO40+AO41+AO42 -> 4469929 | AP29: 0 | AQ29: =AM29+AO29 -> 46241742 | AS29: =AS30+AS32+AS33+AS34+AS35+AS36+AS37+AS38+AS39+AS40+AS41+AS42 -> 3285180 | AT29: 0 | AU29: =AQ29+AS29 -> 49526922
A30: 510506 | B30: Sueldos | C30: 929368 | D30: 0 | E30: =+C30 -> 929368 | G30: 2643170 | H30: 0 | I30: =E30+G30 -> 3572538 | J30: 2841503 | K30: 0 | L30: =I30+J30 -> 6414041 | N30: 2841503 | O30: 0 | P30: =L30+N30 -> 9255544 | R30: 2841503 | S30: 0 | T30: =+P30+R30 -> 12097047 | V30: 2841503 | W30: 0 | X30: =T30+V30 -> 14938550 | Y30: 2841503 | Z30: 0 | AA30: =X30+Y30 -> 17780053 | AC30: 2841503 | AD30: 0 | AE30: =AA30+AC30 -> 20621556 | AG30: 2841503 | AH30: 0 | AI30: =AE30+AG30 -> 23463059 | AK30: 2841503 | AL30: 0 | AM30: =AI30+AK30 -> 26304562 | AO30: 2841503 | AP30: 0 | AQ30: =AM30+AO30 -> 29146065 | AS30: 1989052 | AT30: 0 | AU30: =AQ30+AS30 -> 31135117
A31: 5105 | B31: Horas extras | C31: 0 | D31: 0 | E31: 0 | G31: 0 | H31: 0 | I31: 0 | J31: 0 | K31: 0 | L31: 0 | N31: 0 | O31: 0 | P31: 0 | R31: 5000 | T31: =+P31+R31 -> 5000 | V31: 0
A32: 510527 | B32: Auxilio de transporte | C32: 0 | D32: 0 | E32: =+C32 -> 0 | G32: 74391 | H32: 0 | I32: =E32+G32 -> 74391 | J32: 97032 | K32: 0 | L32: =I32+J32 -> 171423 | N32: 97032 | O32: 0 | P32: =L32+N32 -> 268455 | R32: 97032 | S32: 0 | T32: =+P32+R32 -> 365487 | V32: 97032 | W32: 0 | X32: =T32+V32 -> 462519 | Y32: 97032 | Z32: 0 | AA32: =X32+Y32 -> 559551 | AC32: 97032 | AD32: 0 | AE32: =AA32+AC32 -> 656583 | AG32: 97032 | AH32: 0 | AI32: =AE32+AG32 -> 753615 | AK32: 97032 | AL32: 0 | AM32: =AI32+AK32 -> 850647 | AO32: 97032 | AP32: 0 | AQ32: =AM32+AO32 -> 947679 | AS32: 67922 | AT32: 0 | AU32: =AQ32+AS32 -> 1015601
A33: 510530 | B33: Cesantías | C33: 77416 | D33: 0 | E33: =+C33 -> 77416 | G33: 226373 | H33: 0 | I33: =E33+G33 -> 303789 | J33: 244780 | K33: 0 | L33: =I33+J33 -> 548569 | N33: 244780 | O33: 0 | P33: =L33+N33 -> 793349 | R33: 244780 | S33: 0 | T33: =+P33+R33 -> 1038129 | V33: 244780 | W33: 0 | X33: =T33+V33 -> 1282909 | Y33: 244780 | Z33: 0 | AA33: =X33+Y33 -> 1527689 | AC33: 244780 | AD33: 0 | AE33: =AA33+AC33 -> 1772469 | AG33: 244780 | AH33: 0 | AI33: =AE33+AG33 -> 2017249 | AK33: 244780 | AL33: 0 | AM33: =AI33+AK33 -> 2262029 | AO33: 244780 | AP33: 0 | AQ33: =AM33+AO33 -> 2506809 | AS33: 244780 | AT33: 0 | AU33: =AQ33+AS33 -> 2751589
A34: 510533 | B34: Intereses sobre cesantías | C34: 9289 | D34: 0 | E34: =+C34 -> 9289 | G34: 27176 | H34: 0 | I34: =E34+G34 -> 36465 | J34: 29385 | K34: 0 | L34: =I34+J34 -> 65850 | N34: 29385 | O34: 0 | P34: =L34+N34 -> 95235 | R34: 29385 | S34: 0 | T34: =+P34+R34 -> 124620 | V34: 29385 | W34: 0 | X34: =T34+V34 -> 154005 | Y34: 29385 | Z34: 0 | AA34: =X34+Y34 -> 183390 | AC34: 29385 | AD34: 0 | AE34: =AA34+AC34 -> 212775 | AG34: 29385 | AH34: 0 | AI34: =AE34+AG34 -> 242160 | AK34: 29385 | AL34: 0 | AM34: =AI34+AK34 -> 271545 | AO34: 29385 | AP34: 0 | AQ34: =AM34+AO34 -> 300930 | AS34: 29385 | AT34: 0 | AU34: =AQ34+AS34 -> 330315
A35: 510536 | B35: Prima de servicios | C35: 77416 | D35: 0 | E35: =+C35 -> 77416 | G35: 110220 | H35: 0 | I35: =E35+G35 -> 187636 | J35: 118491 | K35: 0 | L35: =I35+J35 -> 306127 | N35: 118491 | O35: 0 | P35: =L35+N35 -> 424618 | R35: 118491 | S35: 0 | T35: =+P35+R35 -> 543109 | V35: 118491 | W35: 0 | X35: =T35+V35 -> 661600 | Y35: 118491 | Z35: 0 | AA35: =X35+Y35 -> 780091 | AC35: 118491 | AD35: 0 | AE35: =AA35+AC35 -> 898582 | AG35: 118491 | AH35: 0 | AI35: =AE35+AG35 -> 1017073 | AK35: 118491 | AL35: 0 | AM35: =AI35+AK35 -> 1135564 | AO35: 118491 | AP35: 0 | AQ35: =AM35+AO35 -> 1254055 | AS35: 118491 | AT35: 0 | AU35: =AQ35+AS35 -> 1372546
A36: 510539 | B36: Vacaciones | C36: 38755 | D36: 0 | E36: =+C36 -> 38755 | G36: 226373 | H36: 0 | I36: =E36+G36 -> 265128 | J36: 244780 | K36: 0 | L36: =I36+J36 -> 509908 | N36: 244780 | O36: 0 | P36: =L36+N36 -> 754688 | R36: 244780 | S36: 0 | T36: =+P36+R36 -> 999468 | V36: 244780 | W36: 0 | X36: =T36+V36 -> 1244248 | Y36: 244780 | Z36: 0 | AA36: =X36+Y36 -> 1489028 | AC36: 244780 | AD36: 0 | AE36: =AA36+AC36 -> 1733808 | AG36: 244780 | AH36: 0 | AI36: =AE36+AG36 -> 1978588 | AK36: 244780 | AL36: 0 | AM36: =AI36+AK36 -> 2223368 | AO36: 244780 | AP36: 0 | AQ36: =AM36+AO36 -> 2468148 | AS36: 244780 | AT36: 0 | AU36: =AQ36+AS36 -> 2712928
A37: 510545 | B37: Auxilios | C37: 149248 | D37: 0 | E37: =+C37 -> 149248 | G37: 319818 | H37: 0 | I37: =E37+G37 -> 469066 | J37: 319818 | K37: 0 | L37: =I37+J37 -> 788884 | N37: 319818 | O37: 0 | P37: =L37+N37 -> 1108702 | R37: 319818 | S37: 0 | T37: =+P37+R37 -> 1428520 | V37: 319818 | W37: 0 | X37: =T37+V37 -> 1748338 | Y37: 319818 | Z37: 0 | AA37: =X37+Y37 -> 2068156 | AC37: 319818 | AD37: 0 | AE37: =AA37+AC37 -> 2387974 | AG37: 319818 | AH37: 0 | AI37: =AE37+AG37 -> 2707792 | AK37: 319818 | AL37: 0 | AM37: =AI37+AK37 -> 3027610 | AO37: 319818 | AP37: 0 | AQ37: =AM37+AO37 -> 3347428 | AS37: 223873 | AT37: 0 | AU37: =AQ37+AS37 -> 3571301
A38: 510551 | B38: Dotación y elementos seguridad trabajadores | C38: 0 | D38: 0 | E38: =+C38 -> 0 | H38: 0 | I38: =E38+G38 -> 0 | J38: 19861 | K38: 0 | L38: =I38+J38 -> 19861 | N38: 0 | O38: 0 | P38: =L38+N38 -> 19861 | R38: 60000 | S38: 0 | T38: =+P38+R38 -> 79861 | V38: 0 | W38: 0 | X38: =T38+V38 -> 79861 | Y38: 416849 | Z38: 0 | AA38: =X38+Y38 -> 496710 | AC38: 180000 | AD38: 0 | AE38: =AA38+AC38 -> 676710 | AH38: 0 | AI38: =AE38+AG38 -> 676710 | AK38: 0 | AL38: 0 | AM38: =AI38+AK38 -> 676710 | AO38: 50000 | AP38: 0 | AQ38: =AM38+AO38 -> 726710 | AS38: 0 | AT38: 0 | AU38: =AQ38+AS38 -> 726710
A39: 510568 | B39: Aportes a administradoras de riesgos profesionales arp | C39: 9500 | D39: 0 | E39: =+C39 -> 9500 | G39: 64500 | H39: 0 | I39: =E39+G39 -> 74000 | J39: 69400 | K39: 0 | L39: =I39+J39 -> 143400 | N39: 69400 | O39: 0 | P39: =L39+N39 -> 212800 | R39: 69400 | S39: 0 | T39: =+P39+R39 -> 282200 | V39: 69400 | W39: 0 | X39: =T39+V39 -> 351600 | Y39: 69400 | Z39: 0 | AA39: =X39+Y39 -> 421000 | AC39: 69400 | AD39: 0 | AE39: =AA39+AC39 -> 490400 | AG39: 69400 | AH39: 0 | AI39: =AE39+AG39 -> 559800 | AK39: 69400 | AL39: 0 | AM39: =AI39+AK39 -> 629200 | AO39: 69400 | AP39: 0 | AQ39: =AM39+AO39 -> 698600 | AS39: 48579 | AT39: 0 | AU39: =AQ39+AS39 -> 747179
A40: 510569 | B40: Aportes a entidades promotoras de salud eps | C40: 0 | D40: 0 | E40: =+C40 -> 0 | G40: 0 | H40: 0 | I40: =E40+G40 -> 0 | J40: 0 | K40: 0 | L40: =I40+J40 -> 0 | N40: 0 | O40: 0 | P40: =L40+N40 -> 0 | R40: 0 | S40: 0 | T40: =+P40+R40 -> 0 | V40: 0 | W40: 0 | X40: =T40+V40 -> 0 | Y40: 0 | Z40: 0 | AA40: =X40+Y40 -> 0 | AC40: 0 | AD40: 0 | AE40: =AA40+AC40 -> 0 | AG40: 0 | AH40: 0 | AI40: =AE40+AG40 -> 0 | AK40: 0 | AL40: 0 | AM40: =AI40+AK40 -> 0 | AO40: 0 | AP40: 0 | AQ40: =AM40+AO40 -> 0 | AS40: 0 | AT40: 0 | AU40: =AQ40+AS40 -> 0
A41: 510570 | B41: Aportes a fondos de pensiones y/o cesantías | C41: 232000 | D41: 0 | E41: =+C41 -> 232000 | G41: 332458 | H41: 0 | I41: =E41+G41 -> 564458 | J41: 341040 | K41: 0 | L41: =I41+J41 -> 905498 | N41: 341040 | O41: 0 | P41: =L41+N41 -> 1246538 | R41: 341040 | S41: 0 | T41: =+P41+R41 -> 1587578 | V41: 341040 | W41: 0 | X41: =T41+V41 -> 1928618 | Y41: 341040 | Z41: 0 | AA41: =X41+Y41 -> 2269658 | AC41: 341040 | AD41: 0 | AE41: =AA41+AC41 -> 2610698 | AG41: 341040 | AH41: 0 | AI41: =AE41+AG41 -> 2951738 | AK41: 341040 | AL41: 0 | AM41: =AI41+AK41 -> 3292778 | AO41: 341040 | AP41: 0 | AQ41: =AM41+AO41 -> 3633818 | AS41: 238728 | AT41: 0 | AU41: =AQ41+AS41 -> 3872546
A42: 510572 | B42: Aportes cajas de compensación familiar | C42: 77400 | D42: 0 | E42: =+C42 -> 77400 | G42: 105800 | H42: 0 | I42: =E42+G42 -> 183200 | J42: 113700 | K42: 0 | L42: =I42+J42 -> 296900 | N42: 113700 | O42: 0 | P42: =L42+N42 -> 410600 | R42: 113700 | S42: 0 | T42: =+P42+R42 -> 524300 | V42: 113700 | W42: 0 | X42: =T42+V42 -> 638000 | Y42: 113700 | Z42: 0 | AA42: =X42+Y42 -> 751700 | AC42: 113700 | AD42: 0 | AE42: =AA42+AC42 -> 865400 | AG42: 113700 | AH42: 0 | AI42: =AE42+AG42 -> 979100 | AK42: 113700 | AL42: 0 | AM42: =AI42+AK42 -> 1092800 | AO42: 113700 | AP42: 0 | AQ42: =AM42+AO42 -> 1206500 | AS42: 79590 | AT42: 0 | AU42: =AQ42+AS42 -> 1286090
...

Sheet GRAFICAS PYG
B5: MES | C5: VENTAS FISCALES 2019 | D5: VENTAS FISCALES 2018 | E5: VENTAS FISCALES 2017 | F5: VENTAS SIN IVA 2019 | G5: VENTAS SIN IVA 2018 | H5: VENTAS SIN IVA 2017 | I5: GASTOS 2019 | J5: GASTOS 2018 | K5: GASTOS 2017 | L5: UTILIDAD 2019 | M5: UTILIDAD 2018 | N5: UTILIDAD 2017
B6: ENERO | C6: 5232922 | D6: 20519674 | E6: =522963+299991+2769114+199640+276690 -> 4068398 | F6: =7998115 -> 7998115 | G6: 5489862 | H6: 3111549 | I6: =+'PYG '!C149 -> 8192569 | J6: 7055307 | K6: 10452832 | L6: =+C6+F6-I6 -> 5038468 | M6: 18954229 | N6: -3272885
B7: FEBRERO | C7: 6735984 | D7: 347610 | E7: =34155+356641+30000+185495+199640+2769114+52440+124200+30000 -> 3781685 | F7: =4974356-1 -> 4974355 | G7: 7374328 | H7: 8157506 | I7: =+'PYG '!G149 -> 8084721 | J7: 8975623 | K7: 8843670 | L7: =+C7+F7-I7 -> 3625618 | M7: -1253685 | N7: 3095521
B8: MARZO | C8: 4072345 | D8: =245268+260 -> 245528 | E8: =2501135+199640+393580+80730+29750+34510+25000 -> 3264345 | F8: =7130394+43 -> 7130437 | G8: 5439456 | H8: 5780617 | I8: =+'PYG '!J149 -> 8025783 | J8: 9788704 | K8: 8621927 | L8: =+C8+F8-I8 -> 3176999 | M8: -4103720 | N8: 423035
B9: ABRIL | C9: 8902568 | D9: =44268+102185+80587+29750+50000+4998 -> 311788 | E9: =2769114+199640+549053+161460+430560+90000+267950+437283+714714+17250+40000+37500 -> 5714524 | F9: =6000929+75 -> 6001004 | G9: 7142915 | H9: 5636163 | I9: =+'PYG '!N149 -> 11161681 | J9: 9211395 | K9: 6162384 | L9: =+C9+F9-I9 -> 3741891 | M9: -1756692 | N9: 5188303
B10: MAYO | C10: 4831245 | D10: 2070588 | E10: 1563099 | F10: 7419178 | G10: 5721041 | H10: 13796936 | I10: =+'PYG '!R149 -> 10164486 | J10: 8014528 | K10: 10155182 | L10: =+C10+F10-I10 -> 2085937 | M10: -222899 | N10: 5204853
B11: JUNIO | C11: 2541098 | D11: 4186225 | E11: 2504537 | F11: =6384494+91 -> 6384585 | G11: 4021740 | H11: 6565667 | I11: =+'PYG '!V149 -> 8433671 | J11: 7385244 | K11: 14240736 | L11: =+C11+F11-I11 -> 492012 | M11: 822721 | N11: -5170532
B12: JULIO | C12: 2060928 | D12: 3502320 | E12: 14376812 | F12: 4374077 | G12: 1959742 | H12: 6138041 | I12: =+'PYG '!Y149 -> 8752682 | J12: 7676064 | K12: 10531315 | L12: =+C12+F12-I12 -> -2317677 | M12: -2214002 | N12: 9983538
B13: AGOSTO | C13: 722060 | D13: 13456626 | E13: 9843168 | F13: =8088407+176 -> 8088583 | G13: 4820282 | H13: 5449400 | I13: =+'PYG '!AC149 -> 10250005 | J13: 9472439 | K13: 10083753 | L13: =+C13+F13-I13 -> -1439362 | M13: 8804469 | N13: 5208815
B14: SEPTIEMBRE | C14: =+'PYG '!AH8 -> 1921510 | D14: 0 | E14: 6807513 | F14: 5761435 | G14: 6035931 | H14: 6941815 | I14: =+'PYG '!AG149 -> 12341541 | J14: 16476675 | K14: 13656658 | L14: =+C14+F14-I14 -> -4658595.8 | M14: -10440744 | N14: 92670
B15: OCTUBRE | C15: =+'PYG '!AL8 -> 1940050 | D15: =+'[1]PYG '!AP8 -> 53036592 | E15: 3921439 | F15: 5903667 | G15: 10697305 | H15: 5541550 | I15: =+'PYG '!AK149 -> 13788361 | J15: 10699836 | K15: 12463405 | L15: =+C15+F15-I15 -> -5944643.8 | M15: 4755101 | N15: -3000416
B16: NOVIEMBRE | C16: =+'PYG '!AP8 -> 6096979 | D16: =+'[1]PYG '!AT8 -> 58092377 | E16: 2545390 | F16: 6953987 | G16: 7259988 | H16: 6901480 | I16: =+'PYG '!AO149 -> 12146151 | J16: 12696365 | K16: 13179987 | L16: =+C16+F16-I16 -> 904815.25 | M16: -380592 | N16: -3733117
B17: DICIEMBRE | C17: =+'PYG '!AT8 -> 10802895 | D17: =+'[1]PYG '!AX8 -> 63938027 | E17: 68513641 | F17: 3580427 | G17: 8230584 | H17: 7106144 | I17: =+'PYG '!AS149 -> 9554095.8 | J17: 8852048 | K17: 27294325 | L17: =+C17+F17-I17 -> 4829226.2 | M17: 5224186 | N17: 48325460
B19: TOTAL | C19: =SUM(C6:C18) -> 55860584 | D19: =SUM(D6:D18) -> 219707355 | E19: =SUM(E6:E18) -> 126904551 | F19: =SUM(F6:F18) -> 74569850 | G19: =SUM(G6:G18) -> 74193174 | H19: =SUM(H6:H18) -> 81126868 | I19: =SUM(I6:I18) -> 120895746 | J19: =SUM(J6:J18) -> 116304228 | ... N19: =SUM(N6:N18) -> 62345245
B44: MES | C44: VENTAS FISCALES 2019 | D44: VENTAS FISCALES 2018 | E44: VENTAS FISCALES 2017
B45: ENERO | C45: 5232922 | D45: 20519674 | E45: =522963+299991+2769114+199640+276690 -> 4068398
B46: FEBRERO | C46: 6735984 | D46: 347610 | E46: =34155+356641+30000+185495+199640+2769114+52440+124200+30000 -> 3781685
B47: MARZO | C47: 4072345 | D47: =245268+260 -> 245528 | E47: =2501135+199640+393580+80730+29750+34510+25000 -> 3264345
B48: ABRIL | C48: 8902568 | D48: =44268+102185+80587+29750+50000+4998 -> 311788 | E48: =2769114+199640+549053+161460+430560+90000+267950+437283+714714+17250+40000+37500 -> 5714524
B49: MAYO | C49: 4831245 | D49: 2070588 | E49: 1563099
B50: JUNIO | C50: 2541098 | D50: 4186225 | E50: 2504537
B51: JULIO | C51: 2060928 | D51: 3502320 | E51: 14376812
B52: AGOSTO | C52: 722060 | D52: 13456626 | E52: 9843168
B53: SEPTIEMBRE | C53: 1921510 | D53: 0 | E53: 6807513
B54: OCTUBRE | C54: 1940050 | D54: =+'[1]PYG '!AP47 -> 11000000 | E54: 3921439
B55: NOVIEMBRE | C55: 6096979 | D55: =+'[1]PYG '!AT47 -> 12000000 | E55: 2545390
B56: DICIEMBRE | C56: 10802895 | D56: =+'[1]PYG '!AX47 -> 13000000 | E56: 68513641
B58: TOTAL | C58: =SUM(C45:C57) -> 55860584 | D58: =SUM(D45:D57) -> 80640359 | E58: =SUM(E45:E57) -> 126904551
B70: MES | C70: VENTAS SIN IVA 2019 | D70: VENTAS SIN IVA 2018 | E70: VENTAS SIN IVA 2017
B71: ENERO | C71: 7998115 | D71: 5489862 | E71: 3111549
B72: FEBRERO | C72: 4974355 | D72: 7374328 | E72: 8157506
B73: MARZO | C73: 7130437 | D73: 5439456 | E73: 5780617
B74: ABRIL | C74: 6001004 | D74: 7142915 | E74: 5636163
B75: MAYO | C75: 7419178 | D75: 5721041 | E75: 13796936
B76: JUNIO | C76: 6384585 | D76: 4021740 | E76: 6565667
B77: JULIO | C77: 4374077 | D77: 1959742 | E77: 6138041
B78: AGOSTO | C78: 8088583 | D78: 4820282 | E78: 5449400
B79: SEPTIEMBRE | C79: 5761435 | D79: 6035931 | E79: 6941815
B80: OCTUBRE | C80: 5903667 | D80: 10697305 | E80: 5541550
B81: NOVIEMBRE | C81: 6953987 | D81: 7259988 | E81: 6901480
...

Sheet DICIEMBRE
A1: EQUIORIENTE LTDA
A2: SITUACION FINANCIERA
A3: A 31 DE DICIEMBRE DE 2019
A6: 1 | C6: ACTIVO
A8: 11 | C8: Efectivo y equivalentes al efectivo
A9: 1105 | C9: Caja | E9: =+D10 -> 2895707
A10: 110505 | C10: Caja general | D10: 2895707
A11: 1120 | C11: Cuentas de ahorro
A12: 112005 | C12: Bancos | E12: =+D13+D14 -> 9512760
A13: 11200501 | C13: BBVA | D13: 5639481
A14: 11200502 | C14: Davivienda | D14: 3873279
A16: 1120 | C16: CDT | E16: =+D17 -> 15000652
A17: 112005 | C17: Cdt | D17: 15000652
A21: 13 | C21: Cuentas por cobrar (instrumentos financieros)
A22: 1305 | C22: Clientes | E22: =SUM(D24:D29) -> 24838151
A23: 130505 | C23: Nacionales
C24: Aurbana | D24: =+'[2] AURBANA'!$E$24 -> 646807
C25: Dinoxcol | D25: 1076700
C26: Fenix Constructores | D26: 9176470
C27: Gonzales Bohoruqez | D27: 565344
C28: CONSTRUCASA | D28: =+[2]CONSTRUCASA!$E$12 -> 11054406
C29: Consorcio san Ignacio | D29: 2318424
A31: 130515 | C31: Deudores facturacion sin iva | E31: =+D32+D33 -> 6829806
C32: Miriam Serrano | D32: 6743406
C33: leidy carolina saavedra | D33: 86400
A36: 1310 | C36: CUENTAS POR COBRAR A SOCIOS | E36: 6968498
A37: 112005 | C37: John Jaimes | D37: =+E36 -> 6968498
A39: 1395 | C39: Cuentas por cobrar | E39: =+D40 -> 1314587
C40: Inmboliaria ajc | D40: 1314587
A42: 1355 | C42: Anticipo de impuestos y contribuciones o saldos a favor | E42: =SUM(D43:D46) -> 3094161
A43: 135505 | C43: Anticipo de impuestos de renta y complementarios | D43: 1080000
A44: 135515 | C44: Retención en la fuente vtas | D44: 1548161
A45: 135517 | C45: Impuesto a las ventas retenido | D45: 185000
A46: 13559006 | C46: Autorretencion de renta | D46: 281000
A48: 14 | C48: Inventarios | E48: =+D49 -> 149182534
A49: 1435 | C49: Mercancías no fabricadas por la empresa | D49: 149182534
A52: 15 | C52: Propiedades planta y equipo | E52: =+D53+D55+D58+D60+D62+D64 -> 397051240
A53: 1512 | C53: Maquinaria y equipos en montaje | D53: 447920
A54: 151210 | C54: Equipo de oficina | D54: 447920
A55: 1516 | C55: Construcciones y edificaciones | D55: =+D56+D57 -> 381000000
...

Sheet INDICADORES
A1: Razones Financieras
A2: Liquidez
A4: Liquidez | B4: Activos Circulantes | C4: =+DICIEMBRE!E74 -> 6.1923708e+08 | D4: =+C4/C5 -> 83.676181 | E4: La empresa cuenta con el 84% de respaldo de los activos
B5: Pasivos Circulantes | C5: =+DICIEMBRE!E113 -> 7400398.4
A7: Prueba Acida | B7: Activos Circulantes - Inventarios | C7: =+DICIEMBRE!E74-DICIEMBRE!E48 -> 4.7005454e+08 | D7: =+C7/C8 -> 63.517465 | E7: con el activo que tenemos hay el 62,59% para pagar el pasivo
B8: Pasivos Circulantes | C8: =+C5 -> 7400398.4
A10: Administración de Activos
A12: Rotación Activos Fijos | B12: Ventas | C12: 136687592 | D12: =+C12/C13 -> 0.34425681 | E12: la empresa roto su activo el 0,34
B13: Activos Fijos Netos | C13: =+DICIEMBRE!E52 -> 397051240
A15: Rotación Activos Totales | B15: Ventas | C15: =+C12 -> 136687592 | D15: =+C15/C16 -> 0.22073548 | E15: la empresa roto su activo totales el 0,21
B16: Activos Totales | C16: =+C4 -> 6.1923708e+08
A18: Administración de Deudas
A20: Razón de Endeudamiento | B20: Deudas Totales | C20: =+DICIEMBRE!E113 -> 7400398.4 | D20: =+C20/C21 -> 0.011950832 | E20: la empresa de los activos debe el 0,01
B21: Activos totales | C21: =+DICIEMBRE!E74 -> 6.1923708e+08
A23: Rentabilidad
A25: Margen de utilidad | B25: Utilidad Neta | C25: =+'PYG '!AU150 -> 9534688 | D25: =+C25/C26*100 -> 7.3106592 | E25: el margen de utilidad es del 11,7%
B26: Ventas | C26: =+'PYG '!AU8+'PYG '!AU15+'PYG '!AU22 -> 130421728
A28: Rendimiento sobre los activos totales (RAT) | B28: Utilidad Neta | C28: =+C25 -> 9534688 | D28: =+C28/C29*100 -> 1.5397476 | E28: la empresa puede utilizarr el 2,57% de sus activos para generar ventas
B29: Activos totales | C29: =+C16 -> 6.1923708e+08

Sheet PRESUPUESTO
A1: EQUIORIENTE PRESUPUESTO
A4: INGRESOS | B4: INGRESO MENSUAL | C4: INGRESO ANUAL
A5: VENTAS CON IVA
A7: VENTAS SIN IVA
A9: total ingresos | B9: =+B66 -> 9294206.1 | C9: =+C66 -> 53487580
A11: GASTOS | B11: GASTO MENSUAL | C11: GASTO ANUAL
A13: Sueldos | B13: =2110993+900000 -> 3010993 | C13: =+B13*12 -> 36131916
A14: Auxilio de transporte | B14: 102854 | C14: =+B14*12 -> 1234248
A15: Bono de alimentacion | B15: 339007 | C15: =+B15*12 -> 4068084
A16: Dotacion | B16: =480000/12 -> 40000 | C16: =+B16*12 -> 480000
A17: Prestaciones Sociales | B17: =+(B13+B14)*21.83% -> 679752.8 | C17: =+B17*12 -> 8157033.6
A18: Parafiscales | B18: =+B13*18.43% -> 554926.01 | C18: =+B18*12 -> 6659112.1
A20: HONORARIOS CONTADOR | B20: 320000 | C20: =+B20*12 -> 3840000
A21: EXOGENA | B21: 20000 | C21: =+B21*12 -> 240000
A23: IMPUESTOS
A24: Vehiculos | B24: 61000 | C24: =+B24*12 -> 732000
A26: ARRENDAMIENTOS | B26: 1060000 | C26: =+B26*12 -> 12720000
A27: Bodega
A29: SEGURO
A30: Vehiculo | B30: 55340 | C30: =+B30*12 -> 664080
A31: Tecnicomecanica | B31: 17000 | C31: =+B31*12 -> 204000
A33: SERVICIO GENERAL DE ASEO | B33: 30000 | C33: =+B33*12 -> 360000
A34: TEMPORALES | B34: 1200000 | C34: =+B34*12 -> 14400000
A35: ACUEDUCTO | B35: 60000 | C35: =+B35*12 -> 720000
A36: ELECTRIFICADORA DE SANTANDER | B36: 90000 | C36: =+B36*12 -> 1080000
A37: TELEFONIA FIJA | B37: 87000 | C37: =+B37*12 -> 1044000
A38: CELULAR | B38: 173000 | C38: =+B38*12 -> 2076000
A39: TRANSPORTES Y FLETES | B39: 100000 | C39: 300000
A40: AFILIACION A SERVICIO PUBLICO | B40: =130000/12 -> 10833.333 | C40: =+B40*12 -> 130000
A42: GASTOS LEGALES
A43: Registro mercantil | B43: =1000000/12 -> 83333.333 | C43: =+B43*12 -> 1000000
A44: Impuesto de industria y comercio | B44: 25000 | C44: =+B44*12 -> 300000
A46: MANTENIMIENTO | B46: =+C46/12 -> 0
A47: Maquinaria y equipo | B47: =680000/12 -> 56666.667 | C47: =+B47*12 -> 680000
A48: Equipo de oficina | B48: =150000/12 -> 12500 | C48: =+B48 -> 12500
A49: Equipo de computación y comunicación | B49: =300000/12 -> 25000 | C49: =+B49 -> 25000
A50: Flota y equipo de transportes | B50: 100000 | C50: =+B50*12 -> 1200000
A52: Reparaciones locativas | B52: 40000 | C52: =+B52*12 -> 480000
B54: =+C54/12 -> 0
A55: PAPELERIA Y FOTOCOPIAS | B55: 60000 | C55: =+B55*12 -> 720000
...
