Workbook

Sheet DICIEMBRE
A1: EQUIORIENTE LTDA
A2: SITUACION FINANCIERA
A3: A 31 DE DICIEMBRE DE 2020
A6: 1 | C6: ACTIVO
A8: 11 | C8: Efectivo y equivalentes al efectivo
A9: 1105 | C9: Caja | E9: =+D10 -> 18368749
A10: 110505 | C10: Caja general | D10: 18368749
A11: 1120 | C11: Cuentas de ahorro
A12: 112005 | C12: Bancos | E12: =+D13 -> 43071060
A13: 11200501 | C13: BBVA | D13: 43071060
A14: 11200502 | C14: Davivienda | D14: 1289007
A16: 13 | C16: Cuentas por cobrar (instrumentos financieros)
A17: 1305 | C17: Clientes | E17: =SUM(D19:D20) -> 6075013.7
A18: 130505 | C18: Nacionales
C19: Fenix Constructores | D19: 5655681.7
C20: Gonzalez Bohorques | D20: =193113+226219 -> 419332
C21: Ajc Inmobiliaria | D21: 1314587
A23: 130515 | C23: Deudores facturacion sin iva | E23: =+D24+D25 -> 12177061
C24: Miriam Serrano | D24: 6423723
C25: Clientes varios | D25: 5753338
A27: 1355 | C27: Anticipo de impuestos y contribuciones o saldos a favor | E27: =SUM(D28:D32) -> 4253045
A28: 135505 | C28: Anticipo de impuestos de renta y complementarios | D28: 413000
A29: 135518 | C29: Reteica | D29: 326615
A30: 135515 | C30: Retención en la fuente | D30: 3006385
A31: 135517 | C31: Impuesto a las ventas retenido | D31: 153045
A32: 13559006 | C32: Autorretencion de renta | D32: =43000+41000+121000+2000+69000+78000 -> 354000
A34: 14 | C34: Inventarios | E34: =+D35 -> 163235452
A35: 1435 | C35: Mercancías no fabricadas por la empresa | D35: =163654784-419332 -> 163235452
A38: 15 | C38: Propiedades planta y equipo | E38: =+D39+D41+D44+D46+D48+D50 -> 373330511
A39: 1512 | C39: Maquinaria y equipos en montaje | D39: =+D40 -> 10126196
A40: 151210 | C40: Equipo de oficina | D40: 10126196
A41: 1516 | C41: Construcciones y edificaciones | D41: =+D42+D43 -> 381000000
A42: 151605 | C42: Apto sion | D42: 91000000
A43: 151610 | C43: Apto tamara | D43: 290000000
A44: 1524 | C44: Equipo de oficina | D44: =+D45 -> 1070000
A45: 152410 | C45: Equipos | D45: 1070000
A46: 1528 | C46: Equipo de computación y comunicación | D46: =+D47 -> 3109000
A47: 152805 | C47: Equipo de procesamiento de datos | D47: 3109000
A48: 1540 | C48: Flota y equipo de transporte | D48: 34596000
A49: 154008 | C49: Camiones, volquetas y furgones | D49: 34596000
...

Sheet PYG 
A1: EQUIORIENTE LTDA
A2: INFORMES AÑO 2020
C4: 43831 | G4: 43862 | J4: 43891 | N4: 43922 | R4: 43952 | V4: 43983 | Y4: 44013 | AC4: 44044 | AG4: 44075 | AK4: 44105 | AO4: 44136 | AS4: 44166
A5: Cuenta | C5: Mov. 02/01/2020 a 31/01/2020 | E5: Saldos a 31/01/2020 | G5: Mov. 01/02/2020 a 28/02/2020 | I5: Saldos a 28/02/2020 | J5: Mov. 01/03/2020 a 31/03/2020 | L5: Saldos a 31/03/2020 | N5: Mov. 01/04/2020 a 30/04/2020 | P5: Saldos a 30/04/2020 | R5: Mov. 02/05/2020 a 31/05/2020 | T5: Saldos a 31/01/2020 | V5: Mov. 01/06/2020 a 30/06/2020 | X5: Saldos a 28/06/2020 | Y5: Mov. 01/07/2020 a 31/07/2020 | AA5: Saldos a 31/07/2020 | AC5: Mov. 01/08/2020 a 30/08/2020 | AE5: Saldos a 30/08/2020 | AG5: Mov. 01/09/2020 a 31/09/2020 | AI5: Saldos a 31/09/2020 | AK5: Mov. 01/10/2020 a 31/10/2020 | AM5: Saldos a 31/10/2020 | AO5: Mov. 01/11/2020 a 30/11/2020 | AQ5: Saldos a 30/11/2020 | AS5: Mov. 01/12/2020 a 30/12/2020 | AU5: Saldos a 31/12/2020
A6: Cód. | B6: Nombre | C6: Débitos | D6: Créditos | E6: Saldo actual | G6: Débitos | H6: Créditos | I6: Saldo actual | J6: Débitos | K6: Créditos | L6: Saldo actual | N6: Débitos | O6: Créditos | P6: Saldo actual | R6: Débitos | S6: Créditos | T6: Saldo actual | V6: Débitos | W6: Créditos | X6: Saldo actual | Y6: Débitos | Z6: Créditos | AA6: Saldo actual | AC6: Débitos | AD6: Créditos | AE6: Saldo actual | AG6: Débitos | AH6: Créditos | AI6: Saldo actual | AK6: Débitos | AL6: Créditos | AM6: Saldo actual | AO6: Débitos | AP6: Créditos | AQ6: Saldo actual | AS6: Débitos | AT6: Créditos | AU6: Saldo actual
A7: 4 | B7: INGRESOS | C7: 0 | D7: =D8+D14 -> 16317677 | E7: =E8+E14 -> 16317677 | G7: 0 | H7: =H8+H14 -> 18355496 | I7: =E7+H7 -> 34673173 | J7: 0 | K7: =K8+K14 -> 19002187 | L7: =I7+K7 -> 53675360 | N7: 0 | O7: =O8+O14 -> 2118814 | P7: =L7+O7 -> 55794174 | R7: 0 | S7: =S8+S14 -> 3692905 | T7: =+P7+S7 -> 59487079 | V7: 0 | W7: =W8+W14 -> 22654975 | X7: =+T7+W7 -> 82142054 | Y7: 0 | Z7: =Z8+Z14 -> 15859686 | AA7: =+X7+Z7 -> 98001740 | AC7: 0 | AD7: =AD8+AD14 -> 13147172 | AE7: =AA7+AD7 -> 111148912 | AG7: 0 | AH7: =AH8+AH14 -> 16313657 | AI7: =AE7+AH7 -> 127462569 | AK7: 0 | AL7: =AL8+AL14 -> 19079630 | AM7: =AI7+AL7 -> 1.465422e+08 | AO7: 0 | AP7: =AP8+AP14 -> 15904178 | AQ7: =AM7+AP7 -> 1.6244638e+08 | AS7: 0 | AT7: =AT8+AT14 -> 18762225 | AU7: =AQ7+AT7 -> 1.812086e+08
A8: 41 | B8: Operacionales | C8: 0 | D8: =D9 -> 9772741 | E8: =E9 -> 9772741 | G8: 0 | H8: =H9 -> 8662267 | I8: =E8+H8 -> 18435008 | J8: 0 | K8: =K9 -> 11213082 | L8: =I8+K8 -> 29648090 | N8: 0 | O8: =O9 -> 109000 | P8: =L8+O8 -> 29757090 | R8: 0 | S8: =S9 -> 0 | T8: =+P8+S8 -> 29757090 | V8: 0 | W8: =W9 -> 15088775 | X8: =T8+W8 -> 44845865 | Y8: 0 | Z8: =Z9 -> 5107405 | AA8: =+X8+Z8 -> 49953270 | AC8: 0 | AD8: =AD9 -> 4348355 | AE8: =AA8+AD8 -> 54301625 | AG8: 0 | AH8: =AH9 -> 5343486 | AI8: =AE8+AH8 -> 59645111 | AK8: 0 | AL8: =AL9 -> 5206920 | AM8: =AI8+AL8 -> 64852031 | AO8: =AK8+AN8 -> 0 | AP8: =AP9 -> 4539945 | AQ8: =AM8+AP8 -> 69391976 | AS8: =AO8+AR8 -> 0 | AT8: =AT9 -> 5671900 | AU8: =AQ8+AT8 -> 75063876
A9: 4155 | B9: Actividades inmobiliarias, empresariales y de alquiler | C9: 0 | D9: =+D10+D11+D12 -> 9772741 | E9: =D9 -> 9772741 | G9: 0 | H9: =H10+H11+H12 -> 8662267 | I9: =E9+H9 -> 18435008 | J9: 0 | K9: =K10+K11+K12 -> 11213082 | L9: =I9+K9 -> 29648090 | N9: 0 | O9: =O10+O11+O12 -> 109000 | P9: =L9+O9 -> 29757090 | R9: 0 | S9: =+S10+S11+S12 -> 0 | T9: =+P9+S9 -> 29757090 | V9: 0 | W9: =+W10+W11+W12 -> 15088775 | X9: =T9+W9 -> 44845865 | Y9: 0 | Z9: =+Z10+Z12 -> 5107405 | AA9: =+AA10+AA11+AA12 -> 49953270 | AC9: 0 | AD9: =+AD10+AD11+AD12 -> 4348355 | AE9: =AA9+AD9 -> 54301625 | AG9: =AC9+AF9 -> 0 | AH9: =+AH10+AH11+AH12 -> 5343486 | AI9: =AE9+AH9 -> 59645111 | AK9: =AG9+AJ9 -> 0 | AL9: =+AL10+AL11+AL12 -> 5206920 | AM9: =AI9+AL9 -> 64852031 | AO9: =AK9+AN9 -> 0 | AP9: =+AP10+AP11+AP12 -> 4539945 | AQ9: =AM9+AP9 -> 69391976 | AS9: =AO9+AR9 -> 0 | AT9: =+AT10+AT11+AT12 -> 5671900 | AU9: =AQ9+AT9 -> 75063876
A10: 415520 | B10: Alquiler IVA | C10: 0 | D10: 9455741 | E10: =+D10 -> 9455741 | G10: 0 | H10: 8079667 | I10: =E10+H10 -> 17535408 | J10: 0 | K10: 10928082 | L10: =I10+K10 -> 28463490 | N10: 0 | O10: 84000 | P10: =L10+O10 -> 28547490 | R10: 0 | S10: 0 | T10: =+P10+S10 -> 28547490 | V10: 0 | W10: 13738340 | X10: =T10+W10 -> 42285830 | Y10: 0 | Z10: 4717405 | AA10: =+X10+Z10 -> 47003235 | AC10: 0 | AD10: 4228355 | AE10: =AA10+AD10 -> 51231590 | AG10: 0 | AH10: 5253486 | AI10: =AE10+AH10 -> 56485076 | AL10: 5206920 | AM10: =AI10+AL10 -> 61691996 | AO10: 0 | AP10: 4539945 | AQ10: =AM10+AP10 -> 66231941 | AS10: 0 | AT10: 5531900 | AU10: =AQ10+AT10 -> 71763841
A11: 415525 | B11: VENTA EQUIPO | D11: 0 | E11: =+D11 -> 0 | G11: 0 | H11: 0 | I11: =E11+H11 -> 0 | K11: 0 | L11: =I11+K11 -> 0 | O11: 0 | P11: =L11+O11 -> 0 | S11: 0 | T11: =+P11+S11 -> 0 | V11: 0 | W11: 0 | X11: =T11+W11 -> 0 | Y11: 0 | Z11: 0 | AA11: =+X11+Z11 -> 0 | AC11: 0 | AD11: 0 | AE11: =AA11+AD11 -> 0 | AG11: 0 | AI11: =AE11+AH11 -> 0 | AK11: 0 | AL11: 0 | AM11: =AI11+AL11 -> 0 | AO11: 0 | AP11: 0 | AQ11: =AM11+AP11 -> 0 | AS11: 0 | AT11: 0 | AU11: =AQ11+AT11 -> 0
A12: 415515 | B12: Transporte | C12: 0 | D12: 317000 | E12: =+D12 -> 317000 | G12: 0 | H12: 582600 | I12: =E12+H12 -> 899600 | J12: 0 | K12: 285000 | L12: =I12+K12 -> 1184600 | N12: 0 | O12: 25000 | P12: =L12+O12 -> 1209600 | R12: 0 | S12: 0 | T12: =+P12+S12 -> 1209600 | V12: 0 | W12: 1350435 | X12: =T12+W12 -> 2560035 | Y12: 0 | Z12: 390000 | AA12: =+X12+Z12 -> 2950035 | AC12: 0 | AD12: 120000 | AE12: =AA12+AD12 -> 3070035 | AG12: 0 | AH12: 90000 | AI12: =AE12+AH12 -> 3160035 | AK12: 0 | AL12: 0 | AM12: =AI12+AL12 -> 3160035 | AO12: 0 | AP12: 0 | AQ12: =AM12+AP12 -> 3160035 | AS12: 0 | AT12: 140000 | AU12: =AQ12+AT12 -> 3300035
L13: =I13+K13 -> 0 | AA13: =+X13+Z13 -> 0
A14: 42 | B14: No operacionales | C14: 0 | D14: =D15+D19+D22+D24 -> 6544936 | E14: =+D14 -> 6544936 | G14: 0 | H14: =H15+H19+H22+H24 -> 9693229 | I14: =E14+H14 -> 16238165 | J14: 0 | K14: =K15+K19+K22+K24 -> 7789105 | L14: =I14+K14 -> 24027270 | N14: 0 | O14: =O15+O19+O22+O24 -> 2009814 | P14: =L14+O14 -> 26037084 | R14: 0 | S14: =S15+S19+S22+S24 -> 3692905 | T14: =+P14+S14 -> 29729989 | V14: 0 | W14: =W15+W19+W22+W24 -> 7566200 | X14: =+T14+W14 -> 37296189 | Y14: 0 | Z14: =Z15+Z19+Z22+Z24 -> 10752281 | AA14: =X14+Z14 -> 48048470 | AC14: 0 | AD14: =AD15+AD19+AD22+AD24 -> 8798817 | AE14: =AA14+AD14 -> 56847287 | AG14: 0 | AH14: =AH15+AH19+AH22+AH24 -> 10970171 | AI14: =AE14+AH14 -> 67817458 | AK14: 0 | AL14: =AL15+AL19+AL22+AL24 -> 13872710 | AM14: =AI14+AL14 -> 81690168 | AO14: 0 | AP14: =AP15+AP19+AP22+AP24 -> 11364233 | AQ14: =AM14+AP14 -> 93054401 | AS14: 0 | AT14: =AT15+AT19+AT22+AT24 -> 13090325 | AU14: =AQ14+AT14 -> 1.0614473e+08
A15: 4210 | B15: Financieros | C15: 0 | D15: =+D16+D17 -> 98461 | E15: =+D15 -> 98461 | G15: 0 | H15: =+H16+H17 -> 119593 | I15: =E15+H15 -> 218054 | J15: 0 | K15: =+K16+K17 -> 116227 | L15: =I15+K15 -> 334281 | N15: 0 | O15: =+O16+O17 -> 120723 | P15: =L15+O15 -> 455004 | R15: 0 | S15: =+S16 -> 7961 | T15: =+P15+S15 -> 462965 | V15: 0 | W15: =+W16+W17 -> 9258 | X15: =+T15+W15 -> 472223 | Y15: 0 | Z15: =+Z16+Z17 -> 5860 | AA15: =+X15+Z15 -> 478083 | AC15: 0 | AD15: =+AD16+AD17 -> 6465 | AE15: =AA15+AD15 -> 484548 | AG15: 0 | AH15: =+AH16+AH17 -> 6863 | AI15: =AE15+AH15 -> 491411 | AK15: 0 | AL15: =+AL16+AL17 -> 7468 | AM15: =AI15+AL15 -> 498879 | AO15: 0 | AP15: =+AP16+AP17 -> 3771 | AQ15: =AM15+AP15 -> 502650 | AS15: 0 | AT15: =+AT16+AT17 -> 3436 | AU15: =AQ15+AT15 -> 506086
A16: 421005 | B16: Intereses | C16: 0 | D16: 389 | E16: =+D16 -> 389 | G16: 0 | H16: 8163 | I16: =E16+H16 -> 8552 | J16: 0 | K16: 4797 | L16: =I16+K16 -> 13349 | N16: 0 | O16: 9293 | P16: =L16+O16 -> 22642 | R16: 0 | S16: 7961 | T16: =+P16+S16 -> 30603 | V16: 0 | W16: 9258 | X16: =+T16+W16 -> 39861 | Y16: 0 | Z16: 5860 | AA16: =+X16+Z16 -> 45721 | AC16: 0 | AD16: 6465 | AE16: =AA16+AD16 -> 52186 | AG16: 0 | AH16: 6863 | AI16: =AE16+AH16 -> 59049 | AK16: 0 | AL16: 7468 | AM16: =AI16+AL16 -> 66517 | AO16: 0 | AP16: 3771 | AQ16: =AM16+AP16 -> 70288 | AS16: 0 | AT16: 3436 | AU16: =AQ16+AT16 -> 73724
A17: 421095 | B17: intereses prestamos socios | D17: 98072 | E17: =+D17 -> 98072 | H17: 111430 | I17: =E17+H17 -> 209502 | K17: 111430 | L17: =I17+K17 -> 320932 | O17: 111430 | P17: =L17+O17 -> 432362 | X17: =+T17+W17 -> 0 | Z17: 0 | AA17: =+X17+Z17 -> 0 | AD17: 0 | AE17: =AA17+AD17 -> 0 | AI17: =AE17+AH17 -> 0 | AL17: 0 | AM17: =AI17+AL17 -> 0 | AQ17: =AM17+AP17 -> 0 | AU17: =AQ17+AT17 -> 0
L18: =I18+K18 -> 0 | T18: =+P18+S18 -> 0 | X18: =+T18+W18 -> 0 | AA18: =+X18+Z18 -> 0 | AE18: =AA18+AD18 -> 0 | AI18: =AE18+AH18 -> 0 | AM18: =AI18+AL18 -> 0 | AQ18: =AM18+AP18 -> 0 | AU18: =AQ18+AT18 -> 0
A19: 4220 | B19: ARRENDAMIENTOS APARTAMENTOS | C19: 0 | D19: =D20 -> 1888800 | E19: =+D19 -> 1888800 | G19: 0 | H19: =+H20 -> 1888800 | I19: =E19+H19 -> 3777600 | J19: 0 | K19: 1888800 | L19: =I19+K19 -> 5666400 | N19: 0 | O19: =O20 -> 1888800 | P19: =L19+O19 -> 7555200 | R19: 0 | S19: =+S20 -> 1888800 | T19: =+P19+S19 -> 9444000 | V19: 0 | W19: =+W20 -> 1682900 | X19: =+T19+W19 -> 11126900 | Y19: 0 | Z19: =+Z20 -> 1682900 | AA19: =+X19+Z19 -> 12809800 | AC19: 0 | AD19: =+AD20 -> 1936100 | AE19: =AA19+AD19 -> 14745900 | AG19: 0 | AH19: =+AH20 -> 1855700 | AI19: =AE19+AH19 -> 16601600 | AK19: 0 | AL19: =+AL20 -> 1960600 | AM19: =AI19+AL19 -> 18562200 | AO19: 0 | AP19: =+AP20 -> 1960600 | AQ19: =AM19+AP19 -> 20522800 | AS19: 0 | AT19: =+AT20 -> 1960600 | AU19: =AQ19+AT19 -> 22483400
A20: 422010 | B20: Apartamentos Arrendados | C20: 0 | D20: 1888800 | E20: =+D20 -> 1888800 | G20: 0 | H20: =+K20 -> 1888800 | I20: =E20+H20 -> 3777600 | J20: 0 | K20: =+K19 -> 1888800 | L20: =I20+K20 -> 5666400 | N20: 0 | O20: 1888800 | P20: =L20+O20 -> 7555200 | R20: 0 | S20: 1888800 | T20: =+P20+S20 -> 9444000 | V20: 0 | W20: 1682900 | X20: =+T20+W20 -> 11126900 | Y20: 0 | Z20: 1682900 | AA20: =+X20+Z20 -> 12809800 | AC20: 0 | AD20: 1936100 | AE20: =AA20+AD20 -> 14745900 | AG20: 0 | AH20: 1855700 | AI20: =AE20+AH20 -> 16601600 | AK20: 0 | AL20: 1960600 | AM20: =AI20+AL20 -> 18562200 | AO20: 0 | AP20: 1960600 | AQ20: =AM20+AP20 -> 20522800 | AS20: 0 | AT20: 1960600 | AU20: =AQ20+AT20 -> 22483400
L21: =I21+K21 -> 0 | T21: =+P21+S21 -> 0 | X21: =+T21+W21 -> 0 | AA21: =+X21+Z21 -> 0
A22: 4235 | B22: Servicios | C22: 0 | D22: =D23 -> 4555634 | E22: =+D22 -> 4555634 | G22: 0 | H22: =H23 -> 7684835 | I22: =E22+H22 -> 12240469 | J22: 0 | K22: =K23 -> 5784014 | L22: =I22+K22 -> 18024483 | N22: 0 | O22: =O23 -> 0 | P22: =L22+O22 -> 18024483 | R22: 0 | S22: =S23 -> 1735600 | T22: =+P22+S22 -> 19760083 | V22: 0 | W22: =+W23 -> 5171840 | X22: =+T22+W22 -> 24931923 | Y22: 0 | Z22: =+Z23 -> 8361192 | AA22: =+X22+Z22 -> 33293115 | AC22: 0 | AD22: =AD23 -> 6855832 | AE22: =AA22+AD22 -> 40148947 | AG22: 0 | AH22: =AH23 -> 9106991 | AI22: =AE22+AH22 -> 49255938 | AK22: 0 | AL22: =AL23 -> 11904424 | AM22: =AI22+AL22 -> 61160362 | AO22: 0 | AP22: =AP23 -> 9399435 | AQ22: =AM22+AP22 -> 70559797 | AS22: 0 | AT22: =AT23 -> 11126088 | AU22: =AQ22+AT22 -> 81685885
A23: 423510 | B23: VENTAS SIN IVA | C23: 0 | D23: 4555634 | E23: =+D23 -> 4555634 | G23: 0 | H23: 7684835 | I23: =E23+H23 -> 12240469 | J23: 0 | K23: 5784014 | L23: =I23+K23 -> 18024483 | N23: 0 | O23: 0 | P23: =L23+O23 -> 18024483 | R23: 0 | S23: 1735600 | T23: =+P23+S23 -> 19760083 | V23: 0 | W23: 5171840 | X23: =+T23+W23 -> 24931923 | Y23: 0 | Z23: 8361192 | AA23: =+X23+Z23 -> 33293115 | AC23: 0 | AD23: 6855832 | AE23: =AA23+AD23 -> 40148947 | AG23: 0 | AH23: 9106991 | AI23: =AE23+AH23 -> 49255938 | AK23: 0 | AL23: 11904424 | AM23: =AI23+AL23 -> 61160362 | AO23: 0 | AP23: 9399435 | AQ23: =AM23+AP23 -> 70559797 | AS23: 0 | AT23: 11126088 | AU23: =AQ23+AT23 -> 81685885
A24: 4295 | B24: DIVERSOS | C24: 0 | D24: =+D25 -> 2041 | E24: =+D24 -> 2041 | G24: 0 | H24: =+H25 -> 1 | I24: =E24+H24 -> 2042 | J24: 0 | K24: =+K25 -> 64 | L24: =I24+K24 -> 2106 | N24: 0 | O24: =+O25 -> 291 | P24: =L24+O24 -> 2397 | R24: 0 | S24: =+S25 -> 60544 | T24: =+P24+S24 -> 62941 | V24: 0 | W24: =+W25 -> 702202 | X24: =+T24+W24 -> 765143 | Y24: 0 | Z24: =+Z25 -> 702329 | AA24: =+X24+Z24 -> 1467472 | AC24: 0 | AD24: =+AD25 -> 420 | AE24: =AA24+AD24 -> 1467892 | AG24: 0 | AH24: =+AH25 -> 617 | AI24: =AE24+AH24 -> 1468509 | AK24: 0 | AL24: =+AL25 -> 217.83 | AM24: =AI24+AL24 -> 1468726.8 | AO24: 0 | AP24: =+AP25 -> 427 | AQ24: =AM24+AP24 -> 1469153.8 | AS24: 0 | AT24: 201 | AU24: =AQ24+AT24 -> 1469354.8
A25: 429581 | B25: Ajuste al peso | C25: 0 | D25: 2041 | E25: =+D25 -> 2041 | G25: 0 | H25: 1 | I25: =E25+H25 -> 2042 | J25: 0 | K25: 64 | L25: =I25+K25 -> 2106 | N25: 0 | O25: 291 | P25: =L25+O25 -> 2397 | R25: 0 | S25: 60544 | T25: =+P25+S25 -> 62941 | V25: 0 | W25: 702202 | X25: =+T25+W25 -> 765143 | Y25: 0 | Z25: 702329 | AA25: =+X25+Z25 -> 1467472 | AC25: 0 | AD25: 420 | AE25: =AA25+AD25 -> 1467892 | AG25: 0 | AH25: 617 | AI25: =AE25+AH25 -> 1468509 | AK25: 0 | AL25: 217.83 | AM25: =AI25+AL25 -> 1468726.8 | AO25: 0 | AP25: 427 | AQ25: =AM25+AP25 -> 1469153.8 | AS25: 0 | AT25: 201 | AU25: =AQ25+AT25 -> 1469354.8
A27: 5 | B27: GASTOS | C27: =C28+C140+C118 -> 11744572 | D27: 0 | E27: =+C27 -> 11744572 | G27: =G28+G140+G118 -> 13567384 | H27: 0 | I27: =E27+G27 -> 25311956 | J27: =J28+J140+J118 -> 11094912 | K27: 0 | L27: =I27+J27 -> 36406868 | N27: =N28+N140+N118 -> 8654656 | O27: 0 | P27: =L27+N27 -> 45061524 | R27: =R28+R140+R118 -> 11139699 | S27: 0 | T27: =+P27+R27 -> 56201223 | V27: =V28+V140+V118 -> 13198472 | W27: 0 | X27: =T27+V27 -> 69399695 | Y27: =Y28+Y140+Y118 -> 11738973 | Z27: 0 | AA27: =X27+Y27 -> 81138668 | AC27: =AC28+AC140+AC118 -> 11240136 | AD27: 0 | AE27: =AA27+AC27 -> 92378804 | AG27: =AG28+AG140+AG118 -> 11325056 | AH27: 0 | AI27: =AE27+AG27 -> 103703860 | AK27: =AK28+AK140+AK118 -> 14796625 | AL27: 0 | AM27: =AI27+AK27 -> 118500485 | AO27: =AO28+AO140+AO118 -> 15785972 | AP27: 0 | AQ27: =AM27+AO27 -> 134286457 | AS27: =AS28+AS140+AS118 -> 13034178 | AT27: 0 | AU27: =AQ27+AS27 -> 147320635
A28: 51 | B28: Operacionales de administración | C28: =C29+C45+C56+C50+C63+C66+C77+C83+C90+C104+C60+C96 -> 11085668 | D28: 0 | E28: =+C28 -> 11085668 | G28: =G29+G45+G56+G50+G63+G66+G77+G83+G90+G104+G60+G96 -> 13257332 | H28: 0 | I28: =E28+G28 -> 24343000 | J28: =J29+J45+J56+J50+J63+J66+J77+J83+J90+J104+J60+J96 -> 10689110 | K28: 0 | L28: =I28+J28 -> 35032110 | N28: =N29+N45+N56+N50+N63+N66+N77+N83+N90+N104+N60+N96 -> 8333942 | O28: 0 | P28: =L28+N28 -> 43366052 | R28: =R29+R45+R56+R50+R63+R66+R77+R83+R90+R104+R60+R96 -> 10779740 | S28: 0 | T28: =+P28+R28 -> 54145792 | V28: =V29+V45+V50+V56+V63+V66+V77+V83+V90+V104+V96 -> 12830518 | W28: 0 | X28: =T28+V28 -> 66976310 | Y28: =Y29+Y45+Y50+Y56+Y63+Y66+Y77+Y83+Y90+Y104+Y96 -> 11399718 | Z28: 0 | AA28: =X28+Y28 -> 78376028 | AC28: =AC29+AC45+AC50+AC56+AC63+AC66+AC77+AC83+AC90+AC104+AC96 -> 10811171 | AD28: 0 | AE28: =AA28+AC28 -> 89187199 | AG28: =AG29+AG45+AG50+AG56+AG63+AG66+AG77+AG83+AG90+AG104+AG96 -> 11022465 | AH28: 0 | AI28: =AE28+AG28 -> 100209664 | AK28: =AK29+AK45+AK50+AK56+AK63+AK66+AK77+AK83+AK90+AK104+AK96 -> 14479282 | AL28: 0 | AM28: =AI28+AK28 -> 114688946 | AO28: =AO29+AO45+AO50+AO56+AO63+AO66+AO77+AO83+AO90+AO104+AO96 -> 15438511 | AP28: 0 | AQ28: =AM28+AO28 -> 130127457 | AS28: =AS29+AS45+AS50+AS56+AS63+AS66+AS77+AS83+AS90+AS104+AS96 -> 12665615 | AT28: 0 | AU28: =AQ28+AS28 -> 142793072
A29: 5105 | B29: Gastos de personal | C29: =C30+C32+C33+C34+C35+C36+C37+C38+C39+C40+C41+C42 -> 2240070 | D29: 0 | E29: =+C29 -> 2240070 | G29: =SUM(G30:G42) -> 4589258 | H29: 0 | I29: =E29+G29 -> 6829328 | J29: =SUM(J30:J42) -> 3812340 | K29: 0 | L29: =I29+J29 -> 10641668 | N29: =N30+N32+N33+N34+N35+N36+N37+N38+N39+N40+N41+N42 -> 2438298 | O29: 0 | P29: =L29+N29 -> 13079966 | R29: =SUM(R30:R42) -> 4265577 | S29: 0 | T29: =+P29+R29 -> 17345543 | V29: =SUM(V30:V42) -> 4726603 | W29: 0 | X29: =T29+V29 -> 22072146 | Y29: =SUM(Y30:Y42) -> 4759971 | Z29: 0 | AA29: =X29+Y29 -> 26832117 | AC29: =AC30+AC32+AC33+AC34+AC35+AC36+AC37+AC38+AC39+AC40+AC41+AC42 -> 4463934 | AD29: 0 | AE29: =AA29+AC29 -> 31296051 | AG29: =AG30+AG32+AG33+AG34+AG35+AG36+AG37+AG38+AG39+AG40+AG41+AG42 -> 4682010 | AH29: 0 | AI29: =AE29+AG29 -> 35978061 | AK29: =AK30+AK32+AK33+AK34+AK35+AK36+AK37+AK38+AK39+AK40+AK41+AK42+AK43 -> 4764290 | AL29: 0 | AM29: =AI29+AK29 -> 40742351 | AO29: =AO30+AO32+AO33+AO34+AO35+AO36+AO37+AO38+AO39+AO40+AO41+AO42 -> 4766659 | AP29: 0 | AQ29: =AM29+AO29 -> 45509010 | AS29: =AS30+AS32+AS33+AS34+AS35+AS36+AS37+AS38+AS39+AS40+AS41+AS42 -> 4185647 | AT29: 0 | AU29: =AQ29+AS29 -> 49694657
A30: 510506 | B30: Sueldos | C30: 1266596 | D30: 0 | E30: =+C30 -> 1266596 | G30: 2860993 | H30: 0 | I30: =E30+G30 -> 4127589 | J30: 2308429 | K30: 0 | L30: =I30+J30 -> 6436018 | N30: 1806596 | O30: 0 | P30: =L30+N30 -> 8242614 | R30: 2890994 | S30: 0 | T30: =+P30+R30 -> 11133608 | V30: 2980994 | W30: 0 | X30: =T30+V30 -> 14114602 | Y30: 3010994 | Z30: 0 | AA30: =X30+Y30 -> 17125596 | AC30: 2810261 | AD30: 0 | AE30: =AA30+AC30 -> 19935857 | AG30: 3010994 | AH30: 0 | AI30: =AE30+AG30 -> 22946851 | AK30: 3010994 | AL30: 0 | AM30: =AI30+AK30 -> 25957845 | AO30: 3010994 | AP30: 0 | AQ30: =AM30+AO30 -> 28968839 | AS30: 2690261 | AT30: 0 | AU30: =AQ30+AS30 -> 31659100
A31: 5105 | B31: Horas extras | C31: 0 | D31: 0 | E31: 0 | G31: 0 | H31: 0 | I31: 0 | J31: 0 | K31: 0 | L31: 0 | N31: 0 | O31: 0 | P31: 0 | T31: =+P31+R31 -> 0 | V31: 0 | AU31: =AQ31+AS31 -> 0
A32: 510527 | B32: Auxilio de transporte | C32: 0 | D32: 0 | E32: =+C32 -> 0 | G32: 85712 | H32: 0 | I32: =E32+G32 -> 85712 | J32: 78855 | K32: 0 | L32: =I32+J32 -> 164567 | N32: 0 | O32: 0 | P32: =L32+N32 -> 164567 | R32: 89140 | S32: 0 | T32: =+P32+R32 -> 253707 | V32: 99426 | W32: 0 | X32: =T32+V32 -> 353133 | Y32: 102854 | Z32: 0 | AA32: =X32+Y32 -> 455987 | AC32: 95997 | AD32: 0 | AE32: =AA32+AC32 -> 551984 | AG32: 102854 | AH32: 0 | AI32: =AE32+AG32 -> 654838 | AK32: 102854 | AL32: 0 | AM32: =AI32+AK32 -> 757692 | AO32: 102854 | AP32: 0 | AQ32: =AM32+AO32 -> 860546 | AS32: 82283 | AT32: 0 | AU32: =AQ32+AS32 -> 942829
A33: 510530 | B33: Cesantías | C33: 105507 | D33: 0 | E33: =+C33 -> 105507 | G33: 298275 | H33: 0 | I33: =E33+G33 -> 403782 | J33: 298275 | K33: 0 | L33: =I33+J33 -> 702057 | N33: =150489-13022 -> 137467 | O33: 0 | P33: =L33+N33 -> 839524 | R33: 298275 | S33: 0 | T33: =+P33+R33 -> 1137799 | V33: 298275 | W33: 0 | X33: =T33+V33 -> 1436074 | Y33: 298275 | Z33: 0 | AA33: =X33+Y33 -> 1734349 | AC33: 259384 | AD33: 0 | AE33: =AA33+AC33 -> 1993733 | AG33: 259384 | AH33: 0 | AI33: =AE33+AG33 -> 2253117 | AK33: 259384 | AL33: 0 | AM33: =AI33+AK33 -> 2512501 | AO33: 259384 | AP33: 0 | AQ33: =AM33+AO33 -> 2771885 | AS33: 50063 | AT33: 0 | AU33: =AQ33+AS33 -> 2821948
A34: 510533 | B34: Intereses sobre cesantías | C34: 12666 | D34: 0 | E34: =+C34 -> 12666 | G34: 29467 | H34: 0 | I34: =E34+G34 -> 42133 | J34: 23872 | K34: 0 | L34: =I34+J34 -> 66005 | N34: 28218 | O34: 0 | P34: =L34+N34 -> 94223 | R34: 37981 | S34: 0 | T34: =+P34+R34 -> 132204 | V34: 28217 | W34: 0 | X34: =T34+V34 -> 160421 | Y34: 28217 | Z34: 0 | AA34: =X34+Y34 -> 188638 | AC34: 20823 | AD34: 0 | AE34: =AA34+AC34 -> 209461 | AG34: 28218 | AH34: 0 | AI34: =AE34+AG34 -> 237679 | AK34: 28218 | AL34: 0 | AM34: =AI34+AK34 -> 265897 | AO34: 28218 | AP34: 0 | AQ34: =AM34+AO34 -> 294115 | AS34: 14475 | AT34: 0 | AU34: =AQ34+AS34 -> 308590
A35: 510536 | B35: Prima de servicios | C35: 105507 | D35: 0 | E35: =+C35 -> 105507 | G35: 298275 | H35: 0 | I35: =E35+G35 -> 403782 | J35: 298275 | K35: 0 | L35: =I35+J35 -> 702057 | N35: =+N33 -> 137467 | O35: 0 | P35: =L35+N35 -> 839524 | R35: 298275 | S35: 0 | T35: =+P35+R35 -> 1137799 | V35: 298275 | W35: 0 | X35: =T35+V35 -> 1436074 | Y35: 298275 | Z35: 0 | AA35: =X35+Y35 -> 1734349 | AC35: =+AC33 -> 259384 | AD35: 0 | AE35: =AA35+AC35 -> 1993733 | AG35: =+AG33 -> 259384 | AH35: 0 | AI35: =AE35+AG35 -> 2253117 | AK35: 259384 | AL35: 0 | AM35: =AI35+AK35 -> 2512501 | AO35: 259384 | AP35: 0 | AQ35: =AM35+AO35 -> 2771885 | AS35: =+AS33 -> 50063 | AT35: 0 | AU35: =AQ35+AS35 -> 2821948
A36: 510539 | B36: Vacaciones | C36: 52817 | D36: 0 | E36: =+C36 -> 52817 | G36: 126868 | H36: 0 | I36: =E36+G36 -> 179685 | J36: 126868 | K36: 0 | L36: =I36+J36 -> 306553 | N36: 75335 | O36: 0 | P36: =L36+N36 -> 381888 | R36: 126868 | S36: 0 | T36: =+P36+R36 -> 508756 | V36: 126868 | W36: 0 | X36: =T36+V36 -> 635624 | Y36: 126868 | Z36: 0 | AA36: =X36+Y36 -> 762492 | AC36: 126868 | AD36: 0 | AE36: =AA36+AC36 -> 889360 | AG36: 126868 | AH36: 0 | AI36: =AE36+AG36 -> 1016228 | AK36: 126868 | AL36: 0 | AM36: =AI36+AK36 -> 1143096 | AO36: 126868 | AP36: 0 | AQ36: =AM36+AO36 -> 1269964 | AS36: 141010 | AT36: 0 | AU36: =AQ36+AS36 -> 1410974
A37: 510545 | B37: Auxilios | C37: 203405 | D37: 0 | E37: =+C37 -> 203405 | G37: 339008 | H37: 0 | I37: =E37+G37 -> 542413 | J37: 259906 | K37: 0 | L37: =I37+J37 -> 802319 | N37: 0 | O37: 0 | P37: =L37+N37 -> 802319 | R37: 169504 | S37: 0 | T37: =+P37+R37 -> 971823 | V37: 339008 | W37: 0 | X37: =T37+V37 -> 1310831 | Y37: 339008 | Z37: 0 | AA37: =X37+Y37 -> 1649839 | AC37: 327708 | AD37: 0 | AE37: =AA37+AC37 -> 1977547 | AG37: 339008 | AH37: 0 | AI37: =AE37+AG37 -> 2316555 | AK37: 339008 | AL37: 0 | AM37: =AI37+AK37 -> 2655563 | AO37: 339008 | AP37: 0 | AQ37: =AM37+AO37 -> 2994571 | AS37: 316407 | AT37: 0 | AU37: =AQ37+AS37 -> 3310978
A38: 510551 | B38: Dotación y elementos seguridad trabajadores | C38: 103000 | D38: 0 | E38: =+C38 -> 103000 | H38: 0 | I38: =E38+G38 -> 103000 | J38: 0 | K38: 0 | L38: =I38+J38 -> 103000 | N38: 22269 | O38: 0 | P38: =L38+N38 -> 125269 | R38: 0 | S38: 0 | T38: =+P38+R38 -> 125269 | V38: 0 | W38: 0 | X38: =T38+V38 -> 125269 | Y38: 0 | Z38: 0 | AA38: =X38+Y38 -> 125269 | AC38: 0 | AD38: 0 | AE38: =AA38+AC38 -> 125269 | AG38: 0 | AH38: 0 | AI38: =AE38+AG38 -> 125269 | AK38: 24000 | AL38: 0 | AM38: =AI38+AK38 -> 149269 | AO38: 8403 | AP38: 0 | AQ38: =AM38+AO38 -> 157672 | AT38: 0 | AU38: =AQ38+AS38 -> 157672
A39: 510568 | B39: Aportes a administradoras de riesgos profesionales arp | C39: 29400 | D39: 0 | E39: =+C39 -> 29400 | G39: 71900 | H39: 0 | I39: =E39+G39 -> 101300 | J39: 56400 | K39: 0 | L39: =I39+J39 -> 157700 | N39: 44100 | O39: 0 | P39: =L39+N39 -> 201800 | R39: 73500 | S39: 0 | T39: =+P39+R39 -> 275300 | V39: 73500 | W39: 0 | X39: =T39+V39 -> 348800 | Y39: 73500 | Z39: 0 | AA39: =X39+Y39 -> 422300 | AC39: 73500 | AD39: 0 | AE39: =AA39+AC39 -> 495800 | AG39: 73500 | AH39: 0 | AI39: =AE39+AG39 -> 569300 | AK39: 73500 | AL39: 0 | AM39: =AI39+AK39 -> 642800 | AO39: 73500 | AP39: 0 | AQ39: =AM39+AO39 -> 716300 | AS39: 63300 | AT39: 0 | AU39: =AQ39+AS39 -> 779600
A40: 510569 | B40: Aportes a entidades promotoras de salud eps | C40: 32336 | D40: 0 | E40: =+C40 -> 32336 | G40: 3600 | H40: 0 | I40: =E40+G40 -> 35936 | J40: 0 | K40: 0 | L40: =I40+J40 -> 35936 | N40: 48206 | O40: 0 | P40: =L40+N40 -> 84142 | R40: 5060 | S40: 0 | T40: =+P40+R40 -> 89202 | V40: 0 | W40: 0 | X40: =T40+V40 -> 89202 | Y40: 0 | Z40: 0 | AA40: =X40+Y40 -> 89202 | AC40: 0 | AD40: 0 | AE40: =AA40+AC40 -> 89202 | AG40: 0 | AH40: 0 | AI40: =AE40+AG40 -> 89202 | AL40: 0 | AM40: =AI40+AK40 -> 89202 | AP40: 0 | AQ40: =AM40+AO40 -> 89202 | AT40: 0 | AU40: =AQ40+AS40 -> 89202
A41: 510570 | B41: Aportes a fondos de pensiones y/o cesantías | C41: 280636 | D41: 0 | E41: =+C41 -> 280636 | G41: 357160 | H41: 0 | I41: =E41+G41 -> 637796 | J41: 361460 | K41: 0 | L41: =I41+J41 -> 999256 | N41: 18140 | O41: 0 | P41: =L41+N41 -> 1017396 | R41: 34980 | S41: 0 | T41: =+P41+R41 -> 1052376 | V41: 361540 | W41: 0 | X41: =T41+V41 -> 1413916 | Y41: 361540 | Z41: 0 | AA41: =X41+Y41 -> 1775456 | AC41: 369569 | AD41: 0 | AE41: =AA41+AC41 -> 2145025 | AG41: 361360 | AH41: 0 | AI41: =AE41+AG41 -> 2506385 | AK41: 361360 | AL41: 0 | AM41: =AI41+AK41 -> 2867745 | AO41: 437606 | AP41: 0 | AQ41: =AM41+AO41 -> 3305351 | AS41: 618285 | AT41: 0 | AU41: =AQ41+AS41 -> 3923636
A42: 510572 | B42: Aportes cajas de compensación familiar | C42: 48200 | D42: 0 | E42: =+C42 -> 48200 | G42: 118000 | H42: 0 | I42: =E42+G42 -> 166200 | K42: 0 | L42: =I42+J42 -> 166200 | N42: 120500 | O42: 0 | P42: =L42+N42 -> 286700 | R42: 241000 | S42: 0 | T42: =+P42+R42 -> 527700 | V42: 120500 | W42: 0 | X42: =T42+V42 -> 648200 | Y42: 120440 | Z42: 0 | AA42: =X42+Y42 -> 768640 | AC42: 120440 | AD42: 0 | AE42: =AA42+AC42 -> 889080 | AG42: 120440 | AH42: 0 | AI42: =AE42+AG42 -> 1009520 | AK42: 120440 | AL42: 0 | AM42: =AI42+AK42 -> 1129960 | AO42: 120440 | AP42: 0 | AQ42: =AM42+AO42 -> 1250400 | AS42: 159500 | AT42: 0 | AU42: =AQ42+AS42 -> 1409900
...

Sheet GRAFICAS PYG
B5: MES | C5: VENTAS FISCALES 2020 | D5: VENTAS FISCALES 2019 | E5: VENTAS FISCALES 2018 | F5: VENTAS FISCALES 2017 | G5: VENTAS SIN IVA 2020 | H5: VENTAS SIN IVA 2019 | I5: VENTAS SIN IVA 2018 | J5: VENTAS SIN IVA 2017 | K5: GASTOS 2020 | L5: GASTOS 2019 | M5: GASTOS 2018 | N5: GASTOS 2017 | O5: UTILIDAD 2020 | P5: UTILIDAD 2019 | Q5: UTILIDAD 2018 | R5: UTILIDAD 2017
B6: ENERO | C6: 9772741 | D6: 5232922 | E6: 20519674 | F6: =522963+299991+2769114+199640+276690 -> 4068398 | G6: =+'PYG '!D14-'PYG '!D19 -> 4656136 | H6: =7998115 -> 7998115 | I6: 5489862 | J6: 3111549 | K6: =+'PYG '!C153 -> 11183760 | L6: 8192569 | M6: 7055307 | N6: 10452832 | O6: =+C6+G6-K6 -> 3245117 | P6: =+D6+H6-L6 -> 5038468 | Q6: 18954229 | R6: -3272885
B7: FEBRERO | C7: 8662267 | D7: 6735984 | E7: 347610 | F7: =34155+356641+30000+185495+199640+2769114+52440+124200+30000 -> 3781685 | G7: =+'PYG '!H14-'PYG '!H19 -> 7804429 | H7: =4974356-1 -> 4974355 | I7: 7374328 | J7: 8157506 | K7: =+'PYG '!G153 -> 13337610 | L7: 8084721 | M7: 8975623 | N7: 8843670 | O7: =+C7+G7-K7 -> 3129086 | P7: =+D7+H7-L7 -> 3625618 | Q7: -1253685 | R7: 3095521
B8: MARZO | C8: 11213082 | D8: 4072345 | E8: =245268+260 -> 245528 | F8: =2501135+199640+393580+80730+29750+34510+25000 -> 3264345 | G8: =+'PYG '!K14-'PYG '!K19 -> 5900305 | H8: =7130394+43 -> 7130437 | I8: 5439456 | J8: 5780617 | K8: =+'PYG '!J153 -> 10865138 | L8: 8025783 | M8: 9788704 | N8: 8621927 | O8: =+C8+G8-K8 -> 6248249 | P8: =+D8+H8-L8 -> 3176999 | Q8: -4103720 | R8: 423035
B9: ABRIL | C9: 109000 | D9: 8902568 | E9: =44268+102185+80587+29750+50000+4998 -> 311788 | F9: =2769114+199640+549053+161460+430560+90000+267950+437283+714714+17250+40000+37500 -> 5714524 | G9: =+'PYG '!O14-'PYG '!O19 -> 121014 | H9: =6000929+75 -> 6001004 | I9: 7142915 | J9: 5636163 | K9: =+'PYG '!N154 -> 8424882 | L9: 11161681 | M9: 9211395 | N9: 6162384 | O9: =+C9+G9-K9 -> -8194868 | P9: =+D9+H9-L9 -> 3741891 | Q9: -1756692 | R9: 5188303
B10: MAYO | D10: 4831245 | E10: 2070588 | F10: 1563099 | G10: =+'PYG '!S14-'PYG '!S19 -> 1804105 | H10: 7419178 | I10: 5721041 | J10: 13796936 | K10: =+'PYG '!R154 -> 10909925 | L10: 10164486 | M10: 8014528 | N10: 10155182 | O10: =+C10+G10-K10 -> -9105820 | P10: =+D10+H10-L10 -> 2085937 | Q10: -222899 | R10: 5204853
B11: JUNIO | C11: 15088775 | D11: 2541098 | E11: 4186225 | F11: 2504537 | G11: =+'PYG '!W14-'PYG '!W19 -> 5883300 | H11: =6384494+91 -> 6384585 | I11: 4021740 | J11: 6565667 | K11: =+'PYG '!V154 -> 12990071 | L11: 8433671 | M11: 7385244 | N11: 14240736 | O11: =+C11+G11-K11 -> 7982004 | P11: =+D11+H11-L11 -> 492012 | Q11: 822721 | R11: -5170532
B12: JULIO | C12: 5107405 | D12: 2060928 | E12: 3502320 | F12: 14376812 | G12: =+'PYG '!Z14-'PYG '!Z19 -> 9069381 | H12: 4374077 | I12: 1959742 | J12: 6138041 | K12: =+'PYG '!Y154 -> 11530572 | L12: 8752682 | M12: 7676064 | N12: 10531315 | O12: =+C12+G12-K12 -> 2646214 | P12: =+D12+H12-L12 -> -2317677 | Q12: -2214002 | R12: 9983538
B13: AGOSTO | C13: 4348355 | D13: 722060 | E13: 13456626 | F13: 9843168 | G13: =+'PYG '!AD14-'PYG '!AD19 -> 6862717 | H13: =8088407+176 -> 8088583 | I13: 4820282 | J13: 5449400 | K13: =+'PYG '!AC154 -> 11013798 | L13: 10250005 | M13: 9472439 | N13: 10083753 | O13: =+C13+G13-K13 -> 197274 | P13: =+D13+H13-L13 -> -1439362 | Q13: 8804469 | R13: 5208815
B14: SEPTIEMBRE | C14: 5343486 | D14: 1921510 | E14: 0 | F14: 6807513 | G14: =+'PYG '!AH14-'PYG '!AH19 -> 9114471 | H14: 5761435 | I14: 6035931 | J14: 6941815 | K14: =+'PYG '!AG154 -> 11098718 | L14: 12341541 | M14: 16476675 | N14: 13656658 | O14: =+C14+G14-K14 -> 3359239 | P14: =+D14+H14-L14 -> -4658595.8 | Q14: -10440744 | R14: 92670
B15: OCTUBRE | C15: 5206920 | D15: 1940050 | E15: =+'[1]PYG '!AP8 -> 53036592 | F15: 3921439 | G15: =+'PYG '!AL14-'PYG '!AL19 -> 11912110 | H15: 5903667 | I15: 10697305 | J15: 5541550 | K15: =+'PYG '!AK154 -> 14559398 | L15: 13788361 | M15: 10699836 | N15: 12463405 | O15: =+C15+G15-K15 -> 2559631.8 | P15: =+D15+H15-L15 -> -5944643.8 | Q15: 4755101 | R15: -3000416
B16: NOVIEMBRE | C16: 4539945 | D16: 6096979 | E16: =+'[1]PYG '!AT8 -> 58092377 | F16: 2545390 | G16: =+'PYG '!AP22+'PYG '!AP24+'PYG '!AP15 -> 9403633 | H16: 6953987 | I16: 7259988 | J16: 6901480 | K16: =+'PYG '!AO154 -> 15548745 | L16: 12146151 | M16: 12696365 | N16: 13179987 | O16: =+C16+G16-K16 -> -1605167 | P16: =+D16+H16-L16 -> 904815.25 | Q16: -380592 | R16: -3733117
B17: DICIEMBRE | C17: 5671900 | D17: 10802895 | E17: =+'[1]PYG '!AX8 -> 63938027 | F17: 68513641 | G17: =+'PYG '!AT22+'PYG '!AT15+'PYG '!AT24 -> 11129725 | H17: 3580427 | I17: 8230584 | J17: 7106144 | K17: =+'PYG '!AS154 -> 12796951 | L17: 9554095.8 | M17: 8852048 | N17: 27294325 | O17: =+C17+G17-K17 -> 4004674 | P17: =+D17+H17-L17 -> 4829226.2 | Q17: 5224186 | R17: 48325460
B19: TOTAL | C19: =SUM(C6:C18) -> 75063876 | D19: =SUM(D6:D18) -> 55860584 | E19: =SUM(E6:E18) -> 219707355 | F19: =SUM(F6:F18) -> 126904551 | G19: =SUM(G6:G18) -> 83661326 | H19: =SUM(H6:H18) -> 74569850 | I19: =SUM(I6:I18) -> 74193174 | J19: =SUM(J6:J18) -> 81126868 | ... R19: =SUM(R6:R18) -> 62345245
B44: MES | C44: VENTAS FISCALES 2020 | D44: VENTAS FISCALES 2019 | E44: VENTAS FISCALES 2018 | F44: VENTAS FISCALES 2017
B45: ENERO | C45: 9772741 | D45: 5232922 | E45: 20519674 | F45: =522963+299991+2769114+199640+276690 -> 4068398
B46: FEBRERO | C46: 8662267 | D46: 6735984 | E46: 347610 | F46: =34155+356641+30000+185495+199640+2769114+52440+124200+30000 -> 3781685
B47: MARZO | C47: 11213082 | D47: 4072345 | E47: =245268+260 -> 245528 | F47: =2501135+199640+393580+80730+29750+34510+25000 -> 3264345
B48: ABRIL | C48: 109000 | D48: 8902568 | E48: =44268+102185+80587+29750+50000+4998 -> 311788 | F48: =2769114+199640+549053+161460+430560+90000+267950+437283+714714+17250+40000+37500 -> 5714524
B49: MAYO | D49: 4831245 | E49: 2070588 | F49: 1563099
B50: JUNIO | C50: 15088775 | D50: 2541098 | E50: 4186225 | F50: 2504537
B51: JULIO | C51: 5107405 | D51: 2060928 | E51: 3502320 | F51: 14376812
B52: AGOSTO | C52: 4348355 | D52: 722060 | E52: 13456626 | F52: 9843168
B53: SEPTIEMBRE | C53: 5343486 | D53: 1921510 | E53: 0 | F53: 6807513
B54: OCTUBRE | C54: 5206920 | D54: 1940050 | E54: =+'[1]PYG '!AP47 -> 11000000 | F54: 3921439
B55: NOVIEMBRE | C55: 4539945 | D55: 6096979 | E55: =+'[1]PYG '!AT47 -> 12000000 | F55: 2545390
B56: DICIEMBRE | C56: 5671900 | D56: 10802895 | E56: =+'[1]PYG '!AX47 -> 13000000 | F56: 68513641
B58: TOTAL | C58: =SUM(C45:C57) -> 75063876 | D58: =SUM(D45:D57) -> 55860584 | E58: =SUM(E45:E57) -> 80640359 | F58: =SUM(F45:F57) -> 126904551
B70: MES | C70: VENTAS SIN IVA 2020 | D70: VENTAS SIN IVA 2019 | E70: VENTAS SIN IVA 2018 | F70: VENTAS SIN IVA 2017
B71: ENERO | C71: 4656136 | D71: 7998115 | E71: 5489862 | F71: 3111549
B72: FEBRERO | C72: 7804429 | D72: 4974355 | E72: 7374328 | F72: 8157506
B73: MARZO | C73: 5900305 | D73: 7130437 | E73: 5439456 | F73: 5780617
B74: ABRIL | C74: 121014 | D74: 6001004 | E74: 7142915 | F74: 5636163
B75: MAYO | C75: 1804105 | D75: 7419178 | E75: 5721041 | F75: 13796936
B76: JUNIO | C76: 5883300 | D76: 6384585 | E76: 4021740 | F76: 6565667
B77: JULIO | C77: 9069381 | D77: 4374077 | E77: 1959742 | F77: 6138041
B78: AGOSTO | C78: 6862717 | D78: 8088583 | E78: 4820282 | F78: 5449400
B79: SEPTIEMBRE | C79: 9114471 | D79: 5761435 | E79: 6035931 | F79: 6941815
B80: OCTUBRE | C80: 11912110 | D80: 5903667 | E80: 10697305 | F80: 5541550
B81: NOVIEMBRE | C81: 9403633 | D81: 6953987 | E81: 7259988 | F81: 6901480
...

Sheet INDICADORES
A1: Razones Financieras
A2: Liquidez
A4: Liquidez | B4: Activos Circulantes | C4: =+DICIEMBRE!E60 -> 6.2305987e+08 | D4: =+C4/C5 -> 99.020234 | E4: La empresa cuenta con el 99% de respaldo de los activos
B5: Pasivos Circulantes | C5: =+DICIEMBRE!E97 -> 6292248
A7: Prueba Acida | B7: Activos Circulantes - Inventarios | C7: =+DICIEMBRE!E60-DICIEMBRE!E34 -> 4.5982442e+08 | D7: =+C7/C8 -> 73.077924 | E7: con el activo que tenemos hay el 73,07% para pagar el pasivo
B8: Pasivos Circulantes | C8: =+C5 -> 6292248
A10: Administración de Activos
A12: Rotación Activos Fijos | B12: Ventas | C12: 136687592 | D12: =+C12/C13 -> 0.36613025 | E12: la empresa roto su activo el 0,36
B13: Activos Fijos Netos | C13: =+DICIEMBRE!E38 -> 373330511
A15: Rotación Activos Totales | B15: Ventas | C15: =+C12 -> 136687592 | D15: =+C15/C16 -> 0.21938115 | E15: la empresa roto su activo totales el 0,21
B16: Activos Totales | C16: =+C4 -> 6.2305987e+08
A18: Administración de Deudas
A20: Razón de Endeudamiento | B20: Deudas Totales | C20: =+DICIEMBRE!E97 -> 6292248 | D20: =+C20/C21 -> 0.010098946 | E20: la empresa de los activos debe el 0,010
B21: Activos totales | C21: =+DICIEMBRE!E60 -> 6.2305987e+08
A23: Rentabilidad
A25: Margen de utilidad | B25: Utilidad Neta | C25: =+'PYG '!AU154 -> 14465634 | D25: =+C25/C26*100 -> 9.1987892 | E25: el margen de utilidad es del 9,19%
B26: Ventas | C26: =+'PYG '!AU8+'PYG '!AU15+'PYG '!AU22 -> 157255847
A28: Rendimiento sobre los activos totales (RAT) | B28: Utilidad Neta | C28: =+C25 -> 14465634 | D28: =+C28/C29*100 -> 2.3217085 | E28: la empresa puede utilizarr el 2,32% de sus activos para generar ventas
B29: Activos totales | C29: =+C16 -> 6.2305987e+08
