Workbook

Sheet AGOSTO
A1: EQUIORIENTE LTDA
A2: SITUACION FINANCIERA
A3: FECHA: 30 AGOSTO DE 2021
A6: 1 | C6: ACTIVO
A8: 11 | C8: Efectivo y equivalentes al efectivo
A9: 1105 | C9: Caja | E9: =+D10 -> 31272301
A10: 110505 | C10: Caja general | D10: 31272301
A11: 1120 | C11: Cuentas de ahorro
A12: 112005 | C12: Bancos | E12: =+D13 -> 5634973
A13: 11200501 | C13: BBVA | D13: 5634973
A14: 11200502 | C14: Davivienda
A16: 13 | C16: Cuentas por cobrar (instrumentos financieros)
A17: 1305 | C17: Clientes | E17: =SUM(D19:D21) -> 7483662
A18: 130505 | C18: Nacionales
C19: Fenix Constructores | D19: 5855549
C20: Construcasa | D20: 1386670
C21: gonzalez bohorque | D21: 241443
A24: 130515 | C24: Deudores facturacion sin iva | E24: =+D25+D26 -> 6005402
C25: Miriam Serrano | D25: 4577126
C26: Clientes varios | D26: 1428276
A28: 1355 | C28: Anticipo de impuestos y contribuciones o saldos a favor | E28: =SUM(D29:D33) -> 2836193
A29: 135505 | C29: Anticipo de impuestos de renta y complementarios | D29: 1762000
A30: 135518 | C30: Reteica | D30: 51861
A31: 135515 | C31: Retención en la fuente | D31: 771332
A32: 135517 | C32: Impuesto a las ventas retenido | D32: 0
A33: 13559006 | C33: Autorretencion de renta | D33: 251000
A35: 14 | C35: Inventarios | E35: =+D36 -> 166485896
A36: 1435 | C36: Mercancías no fabricadas por la empresa | D36: 166485896
A39: 15 | C39: Propiedades planta y equipo | E39: =+D40+D42+D45+D47+D49+D51 -> 354443971
A40: 1512 | C40: Maquinaria y equipos en montaje | D40: =+D41 -> 10126196
A41: 151210 | C41: Equipo de oficina | D41: 10126196
A42: 1516 | C42: Construcciones y edificaciones | D42: =+D43+D44 -> 381000000
A43: 151605 | C43: Apto sion | D43: 91000000
A44: 151610 | C44: Apto tamara | D44: 290000000
A45: 1524 | C45: Equipo de oficina | D45: =+D46 -> 1070000
A46: 152410 | C46: Equipos | D46: 1070000
A47: 1528 | C47: Equipo de computación y comunicación | D47: =+D48 -> 3109000
A48: 152805 | C48: Equipo de procesamiento de datos | D48: 3109000
A49: 1540 | C49: Flota y equipo de transporte | D49: 34596000
A50: 154008 | C50: Camiones, volquetas y furgones | D50: 34596000
...

Sheet PYG 
A1: EQUIORIENTE LTDA
A2: INFORMES AÑO 2021
C4: 44197 | G4: 44228 | J4: 44256 | N4: 44287 | R4: 44317 | V4: 44348 | Z4: 44378 | AD4: 44409
A5: Cuenta | C5: Mov. 02/01/2021 a 31/01/2021 | E5: Saldos a 31/01/1 | G5: Mov. 01/02/2021 a 28/02/2021 | I5: Saldos a 28/02/2021 | J5: Mov. 01/03/2021 a 31/03/2021 | L5: Saldos a 31/03/2021 | N5: Mov. 01/04/2021 a 30/04/2021 | P5: Saldos a 30/04/2021 | R5: Mov. 01/04/2021 a 30/04/2021 | T5: Saldos a 30/04/2021 | V5: Mov. 01/04/2021 a 30/04/2021 | X5: Saldos a 30/04/2021 | Z5: Mov. 01/04/2021 a 30/04/2021 | AB5: Saldos a 30/04/2021 | AD5: Mov. 01/04/2021 a 30/04/2021 | AF5: c vvvvvv
A6: Cód. | B6: Nombre | C6: Débitos | D6: Créditos | E6: Saldo actual | G6: Débitos | H6: Créditos | I6: Saldo actual | J6: Débitos | K6: Créditos | L6: Saldo actual | N6: Débitos | O6: Créditos | P6: Saldo actual | R6: Débitos | S6: Créditos | T6: Saldo actual | V6: Débitos | W6: Créditos | X6: Saldo actual | Z6: Débitos | AA6: Créditos | AB6: Saldo actual | AD6: Débitos | AE6: Créditos | AF6: Saldo actual
A7: 4 | B7: INGRESOS | C7: 0 | D7: =D8+D14 -> 11344635 | E7: =E8+E14 -> 11344635 | G7: 0 | H7: =H8+H14 -> 12286773 | I7: =E7+H7 -> 23631408 | J7: 0 | K7: =K8+K14 -> 14156650 | L7: =I7+K7 -> 37788058 | N7: 0 | O7: =O8+O14 -> 15531100 | P7: =L7+O7 -> 53319158 | R7: 0 | S7: =S8+S14 -> 14472469 | T7: =P7+S7 -> 67791627 | V7: 0 | W7: =W8+W14 -> 19253718 | X7: =T7+W7 -> 87045345 | Z7: 0 | AA7: =AA8+AA14 -> 12791478 | AB7: =X7+AA7 -> 99836823 | AD7: 0 | AE7: =AE8+AE14 -> 14702304 | AF7: =AB7+AE7 -> 114539127
A8: 41 | B8: Operacionales | C8: 0 | D8: =D9 -> 4088450 | E8: =E9 -> 4088450 | G8: 0 | H8: =H9 -> 3444630 | I8: =E8+H8 -> 7533080 | J8: 0 | K8: =K9 -> 4294490 | L8: =I8+K8 -> 11827570 | N8: 0 | O8: =O9 -> 3094715 | P8: =L8+O8 -> 14922285 | R8: 0 | S8: =S9 -> 3036250 | T8: =P8+S8 -> 17958535 | V8: 0 | W8: =W9 -> 3220640 | X8: =T8+W8 -> 21179175 | Z8: 0 | AA8: =AA9 -> 2982171 | AB8: =X8+AA8 -> 24161346 | AD8: 0 | AE8: =AE9 -> 2259634 | AF8: =AB8+AE8 -> 26420980
A9: 4155 | B9: Actividades inmobiliarias, empresariales y de alquiler | C9: 0 | D9: =+D10+D11+D12 -> 4088450 | E9: =D9 -> 4088450 | G9: 0 | H9: =H10+H11+H12 -> 3444630 | I9: =E9+H9 -> 7533080 | J9: 0 | K9: =K10+K11+K12 -> 4294490 | L9: =I9+K9 -> 11827570 | N9: 0 | O9: =O10+O11+O12 -> 3094715 | P9: =L9+O9 -> 14922285 | R9: 0 | S9: =S10+S11+S12 -> 3036250 | T9: =P9+S9 -> 17958535 | V9: 0 | W9: =W10+W11+W12 -> 3220640 | X9: =T9+W9 -> 21179175 | Z9: 0 | AA9: =AA10+AA11+AA12 -> 2982171 | AB9: =X9+AA9 -> 24161346 | AD9: 0 | AE9: =AE10+AE11+AE12 -> 2259634 | AF9: =AB9+AE9 -> 26420980
A10: 415520 | B10: Alquiler IVA | C10: 0 | D10: 4058450 | E10: =+D10 -> 4058450 | G10: 0 | H10: 3409630 | I10: =E10+H10 -> 7468080 | J10: 0 | K10: 4294490 | L10: =I10+K10 -> 11762570 | N10: 0 | O10: 3019715 | P10: =L10+O10 -> 14782285 | R10: 0 | S10: 3036250 | T10: =P10+S10 -> 17818535 | V10: 0 | W10: 3175640 | X10: =T10+W10 -> 20994175 | Z10: 0 | AA10: 2982171 | AB10: =X10+AA10 -> 23976346 | AD10: 0 | AE10: 2259634 | AF10: =AB10+AE10 -> 26235980
A11: 415525 | B11: VENTA EQUIPO | D11: 0 | E11: =+D11 -> 0 | G11: 0 | H11: 0 | I11: =E11+H11 -> 0 | K11: 0 | L11: =I11+K11 -> 0 | O11: 0 | P11: =L11+O11 -> 0 | S11: 0 | T11: =P11+S11 -> 0 | W11: 0 | X11: =T11+W11 -> 0 | AA11: 0 | AB11: =X11+AA11 -> 0 | AE11: 0 | AF11: =AB11+AE11 -> 0
A12: 415515 | B12: Transporte | C12: 0 | D12: 30000 | E12: =+D12 -> 30000 | G12: 0 | H12: 35000 | I12: =E12+H12 -> 65000 | J12: 0 | K12: 0 | L12: =I12+K12 -> 65000 | N12: 0 | O12: 75000 | P12: =L12+O12 -> 140000 | R12: 0 | S12: 0 | T12: =P12+S12 -> 140000 | V12: 0 | W12: 45000 | X12: =T12+W12 -> 185000 | Z12: 0 | AA12: 0 | AB12: =X12+AA12 -> 185000 | AD12: 0 | AE12: 0 | AF12: =AB12+AE12 -> 185000
L13: =I13+K13 -> 0
A14: 42 | B14: No operacionales | C14: 0 | D14: =D15+D19+D22+D24 -> 7256185 | E14: =+D14 -> 7256185 | G14: 0 | H14: =H15+H19+H22+H24 -> 8842143 | I14: =E14+H14 -> 16098328 | J14: 0 | K14: =K15+K19+K22+K24 -> 9862160 | L14: =I14+K14 -> 25960488 | N14: 0 | O14: =O15+O19+O22+O24 -> 12436385 | P14: =L14+O14 -> 38396873 | R14: 0 | S14: =S15+S19+S22+S24 -> 11436219 | T14: =P14+S14 -> 49833092 | V14: 0 | W14: =W15+W19+W22+W24 -> 16033078 | X14: =T14+W14 -> 65866170 | Z14: 0 | AA14: =AA15+AA19+AA22+AA24 -> 9809307 | AB14: =X14+AA14 -> 75675477 | AD14: 0 | AE14: =AE15+AE19+AE22+AE24 -> 12442670 | AF14: =AB14+AE14 -> 88118147
A15: 4210 | B15: Financieros | C15: 0 | D15: =+D16+D17 -> 3538 | E15: =+D15 -> 3538 | G15: 0 | H15: =+H16 -> 3553 | I15: =E15+H15 -> 7091 | J15: 0 | K15: =+K16+K17 -> 1206 | L15: =I15+K15 -> 8297 | N15: 0 | O15: =+O16+O17 -> 112 | P15: =L15+O15 -> 8409 | R15: 0 | S15: =+S16+S17 -> 444 | T15: =P15+S15 -> 8853 | V15: 0 | W15: =+W16+W17 -> 681 | X15: =T15+W15 -> 9534 | Z15: 0 | AA15: =+AA16+AA17 -> 570 | AB15: =X15+AA15 -> 10104 | AD15: 0 | AE15: =+AE16+AE17 -> 644 | AF15: =AB15+AE15 -> 10748
A16: 421005 | B16: Intereses | C16: 0 | D16: 3538 | E16: =+D16 -> 3538 | G16: 0 | H16: 3553 | I16: =E16+H16 -> 7091 | J16: 0 | K16: 1206 | L16: =I16+K16 -> 8297 | N16: 0 | O16: 112 | P16: =L16+O16 -> 8409 | R16: 0 | S16: 444 | T16: =P16+S16 -> 8853 | V16: 0 | W16: 681 | X16: =T16+W16 -> 9534 | Z16: 0 | AA16: 570 | AB16: =X16+AA16 -> 10104 | AD16: 0 | AE16: 644 | AF16: =AB16+AE16 -> 10748
A17: 421095 | B17: intereses prestamos socios | E17: =+D17 -> 0 | H17: 0 | I17: =E17+H17 -> 0 | K17: 0 | L17: =I17+K17 -> 0 | N17: 0 | O17: 0 | P17: =L17+O17 -> 0 | R17: 0 | S17: 0 | T17: =P17+S17 -> 0 | V17: 0 | W17: 0 | X17: =T17+W17 -> 0 | Z17: 0 | AA17: 0 | AB17: =X17+AA17 -> 0 | AD17: 0 | AE17: 0 | AF17: =AB17+AE17 -> 0
L18: =I18+K18 -> 0
A19: 4220 | B19: ARRENDAMIENTOS APARTAMENTOS | C19: 0 | D19: =D20 -> 1960600 | E19: =+D19 -> 1960600 | G19: 0 | H19: =+H20 -> 1960600 | I19: =E19+H19 -> 3921200 | J19: 0 | K19: =+K20 -> 1960600 | L19: =I19+K19 -> 5881800 | N19: 0 | O19: =O20 -> 1960600 | P19: =L19+O19 -> 7842400 | R19: 0 | S19: =S20 -> 1960600 | T19: =P19+S19 -> 9803000 | V19: 0 | W19: =W20 -> 1960600 | X19: =T19+W19 -> 11763600 | Z19: 0 | AA19: =AA20 -> 1960600 | AB19: =X19+AA19 -> 13724200 | AD19: 0 | AE19: =AE20 -> 1960600 | AF19: =AB19+AE19 -> 15684800
A20: 422010 | B20: Apartamentos Arrendados | C20: 0 | D20: 1960600 | E20: =+D20 -> 1960600 | G20: 0 | H20: =+K20 -> 1960600 | I20: =E20+H20 -> 3921200 | J20: 0 | K20: 1960600 | L20: =I20+K20 -> 5881800 | N20: 0 | O20: 1960600 | P20: =L20+O20 -> 7842400 | R20: 0 | S20: 1960600 | T20: =P20+S20 -> 9803000 | V20: 0 | W20: 1960600 | X20: =T20+W20 -> 11763600 | Z20: 0 | AA20: 1960600 | AB20: =X20+AA20 -> 13724200 | AD20: 0 | AE20: 1960600 | AF20: =AB20+AE20 -> 15684800
L21: =I21+K21 -> 0
A22: 4235 | B22: Servicios | C22: 0 | D22: =D23 -> 5292010 | E22: =+D22 -> 5292010 | G22: 0 | H22: =H23 -> 6877990 | I22: =E22+H22 -> 12170000 | J22: 0 | K22: =K23 -> 7900354 | L22: =I22+K22 -> 20070354 | N22: 0 | O22: =O23 -> 10475673 | P22: =L22+O22 -> 30546027 | R22: 0 | S22: =S23 -> 9475175 | T22: =P22+S22 -> 40021202 | V22: 0 | W22: =W23 -> 14071797 | X22: =T22+W22 -> 54092999 | Z22: 0 | AA22: =AA23 -> 7846784 | AB22: =X22+AA22 -> 61939783 | AD22: 0 | AE22: =AE23 -> 10481424 | AF22: =AB22+AE22 -> 72421207
A23: 423510 | B23: VENTAS SIN IVA | C23: 0 | D23: 5292010 | E23: =+D23 -> 5292010 | G23: 0 | H23: 6877990 | I23: =E23+H23 -> 12170000 | J23: 0 | K23: 7900354 | L23: =I23+K23 -> 20070354 | N23: 0 | O23: 10475673 | P23: =L23+O23 -> 30546027 | R23: 0 | S23: 9475175 | T23: =P23+S23 -> 40021202 | V23: 0 | W23: 14071797 | X23: =T23+W23 -> 54092999 | Z23: 0 | AA23: 7846784 | AB23: =X23+AA23 -> 61939783 | AD23: 0 | AE23: 10481424 | AF23: =AB23+AE23 -> 72421207
A24: 4295 | B24: DIVERSOS | C24: 0 | D24: =+D25 -> 37 | E24: =+D24 -> 37 | G24: 0 | H24: =+H25 -> 0 | I24: =E24+H24 -> 37 | J24: 0 | K24: =+K25 -> 0 | L24: =I24+K24 -> 37 | N24: 0 | O24: =+O25 -> 0 | P24: =L24+O24 -> 37 | R24: 0 | S24: =+S25 -> 0 | T24: =P24+S24 -> 37 | V24: 0 | W24: =+W25 -> 0 | X24: =T24+W24 -> 37 | Z24: 0 | AA24: =+AA25 -> 1353 | AB24: =X24+AA24 -> 1390 | AD24: 0 | AE24: =+AE25 -> 2 | AF24: =AB24+AE24 -> 1392 | AG24: 3
A25: 429581 | B25: Ajuste al peso | C25: 0 | D25: 37 | E25: =+D25 -> 37 | G25: 0 | I25: =E25+H25 -> 37 | J25: 0 | L25: =I25+K25 -> 37 | N25: 0 | O25: 0 | P25: =L25+O25 -> 37 | R25: 0 | S25: 0 | T25: =P25+S25 -> 37 | V25: 0 | W25: 0 | X25: =T25+W25 -> 37 | Z25: 0 | AA25: =1360-7 -> 1353 | AB25: =X25+AA25 -> 1390 | AD25: 0 | AE25: 2 | AF25: =AB25+AE25 -> 1392
A27: 5 | B27: GASTOS | C27: =C28+C140+C118 -> 9031235 | D27: 0 | E27: =+C27 -> 9031235 | G27: =G28+G140+G118 -> 12657564 | H27: 0 | I27: =E27+G27 -> 21688799 | J27: =J28+J140+J118 -> 14106743 | K27: 0 | L27: =I27+J27 -> 35795542 | N27: =N28+N140+N118 -> 17975576 | O27: 0 | P27: =L27+N27 -> 53771118 | R27: =R28+R140+R118 -> 12421885 | S27: 0 | T27: =P27+R27 -> 66193003 | V27: =V28+V140+V118 -> 13474748 | W27: 0 | X27: =T27+V27 -> 79667751 | Z27: =Z28+Z140+Z118 -> 14035260 | AA27: 0 | AB27: =X27+Z27 -> 93703011 | AD27: =AD28+AD140+AD118 -> 13118813 | AE27: 0 | AF27: =AB27+AD27 -> 1.0682182e+08
A28: 51 | B28: Operacionales de administración | C28: =C29+C45+C56+C50+C63+C66+C77+C83+C90+C104+C60+C96 -> 8946851 | D28: 0 | E28: =+C28 -> 8946851 | G28: =G29+G45+G56+G50+G63+G66+G77+G83+G90+G104+G60+G96 -> 12329940 | H28: 0 | I28: =E28+G28 -> 21276791 | J28: =J29+J45+J56+J50+J63+J66+J77+J83+J90+J104+J60+J96 -> 13307958 | K28: 0 | L28: =I28+J28 -> 34584749 | N28: =N29+N45+N56+N50+N63+N66+N77+N83+N90+N104+N60+N96 -> 16977646 | O28: 0 | P28: =L28+N28 -> 51562395 | R28: =R29+R45+R56+R50+R63+R66+R77+R83+R90+R104+R60+R96 -> 11666774 | S28: 0 | T28: =P28+R28 -> 63229169 | V28: =V29+V45+V56+V50+V63+V66+V77+V83+V90+V104+V60+V96 -> 12699979 | W28: 0 | X28: =T28+V28 -> 75929148 | Z28: =Z29+Z45+Z56+Z50+Z63+Z66+Z77+Z83+Z90+Z104+Z60+Z96 -> 13275217 | AA28: 0 | AB28: =X28+Z28 -> 89204365 | AD28: =AD29+AD45+AD56+AD50+AD63+AD66+AD77+AD83+AD90+AD104+AD60+AD96 -> 12322820 | AE28: 0 | AF28: =AB28+AD28 -> 1.0152718e+08
A29: 5105 | B29: Gastos de personal | C29: =+C38 -> 30000 | D29: 0 | E29: =+C29 -> 30000 | G29: =SUM(G30:G42) -> 4888998 | H29: 0 | I29: =E29+G29 -> 4918998 | J29: =SUM(J30:J42) -> 4803581 | K29: 0 | L29: =I29+J29 -> 9722579 | N29: =N30+N32+N33+N34+N35+N36+N37+N38+N39+N40+N41+N42 -> 4803967 | O29: 0 | P29: =L29+N29 -> 14526546 | R29: =R30+R32+R33+R34+R35+R36+R37+R38+R39+R40+R41+R42 -> 4902866 | S29: 0 | T29: =P29+R29 -> 19429412 | V29: =V30+V32+V33+V34+V35+V36+V37+V38+V39+V40+V41+V42 -> 4792542 | W29: 0 | X29: =T29+V29 -> 24221954 | Z29: =Z30+Z32+Z33+Z34+Z35+Z36+Z37+Z38+Z39+Z40+Z41+Z42 -> 4916046 | AA29: 0 | AB29: =X29+Z29 -> 29138000 | AD29: =AD30+AD32+AD33+AD34+AD35+AD36+AD37+AD38+AD39+AD40+AD41+AD42+AD31 -> 4800542 | AE29: 0 | AF29: =AB29+AD29 -> 33938542
A30: 510506 | B30: Sueldos | C30: 0 | D30: 0 | E30: =+C30 -> 0 | G30: 2908453 | H30: 0 | I30: =E30+G30 -> 2908453 | J30: 3116200 | K30: 0 | L30: =I30+J30 -> 6024653 | N30: 3116200 | O30: 0 | P30: =L30+N30 -> 9140853 | R30: 3116200 | S30: 0 | T30: =P30+R30 -> 12257053 | V30: 3116200 | W30: 0 | X30: =T30+V30 -> 15373253 | Z30: 3116200 | AA30: 0 | AB30: =X30+Z30 -> 18489453 | AD30: 3116200 | AE30: 0 | AF30: =AB30+AD30 -> 21605653
A31: 5105 | B31: Horas extras | C31: 0 | D31: 0 | E31: 0 | G31: 0 | H31: 0 | I31: 0 | J31: 0 | K31: 0 | L31: 0 | N31: 0 | O31: 0 | P31: 0 | R31: 0 | S31: 0 | T31: 0 | V31: 0 | W31: 0 | X31: 0 | Z31: 0 | AA31: 0 | AB31: 0 | AD31: 25000 | AE31: 0 | AF31: =+AD31 -> 25000
A32: 510527 | B32: Auxilio de transporte | C32: 0 | D32: 0 | E32: =+C32 -> 0 | G32: 99357 | H32: 0 | I32: =E32+G32 -> 99357 | J32: 106454 | K32: 0 | L32: =I32+J32 -> 205811 | N32: 106454 | O32: 0 | P32: =L32+N32 -> 312265 | R32: 106454 | S32: 0 | T32: =P32+R32 -> 418719 | V32: 106454 | W32: 0 | X32: =T32+V32 -> 525173 | Z32: 106454 | AA32: 0 | AB32: =X32+Z32 -> 631627 | AD32: 106454 | AE32: 0 | AF32: =AB32+AD32 -> 738081
A33: 510530 | B33: Cesantías | C33: 0 | D33: 0 | E33: =+C33 -> 0 | G33: 250550 | H33: 0 | I33: =E33+G33 -> 250550 | J33: 268448 | K33: 0 | L33: =I33+J33 -> 518998 | N33: 268448 | O33: 0 | P33: =L33+N33 -> 787446 | R33: 268448 | S33: 0 | T33: =P33+R33 -> 1055894 | V33: 268448 | W33: 0 | X33: =T33+V33 -> 1324342 | Z33: 268448 | AA33: 0 | AB33: =X33+Z33 -> 1592790 | AD33: 268448 | AE33: 0 | AF33: =AB33+AD33 -> 1861238
A34: 510533 | B34: Intereses sobre cesantías | C34: 0 | D34: 0 | E34: =+C34 -> 0 | G34: 20879 | H34: 0 | I34: =E34+G34 -> 20879 | J34: 32213 | K34: 0 | L34: =I34+J34 -> 53092 | N34: 32226 | O34: 0 | P34: =L34+N34 -> 85318 | R34: 32214 | S34: 0 | T34: =P34+R34 -> 117532 | V34: 32214 | W34: 0 | X34: =T34+V34 -> 149746 | Z34: 32214 | AA34: 0 | AB34: =X34+Z34 -> 181960 | AD34: 32214 | AE34: 0 | AF34: =AB34+AD34 -> 214174
A35: 510536 | B35: Prima de servicios | C35: 0 | D35: 0 | E35: =+C35 -> 0 | G35: 250550 | H35: 0 | I35: =E35+G35 -> 250550 | J35: 268448 | K35: 0 | L35: =I35+J35 -> 518998 | N35: 268448 | O35: 0 | P35: =L35+N35 -> 787446 | R35: 268448 | S35: 0 | T35: =P35+R35 -> 1055894 | V35: 268448 | W35: 0 | X35: =T35+V35 -> 1324342 | Z35: 268448 | AA35: 0 | AB35: =X35+Z35 -> 1592790 | AD35: 268448 | AE35: 0 | AF35: =AB35+AD35 -> 1861238
A36: 510539 | B36: Vacaciones | C36: 0 | D36: 0 | E36: =+C36 -> 0 | G36: 121282 | H36: 0 | I36: =E36+G36 -> 121282 | J36: 129946 | K36: 0 | L36: =I36+J36 -> 251228 | N36: 129946 | O36: 0 | P36: =L36+N36 -> 381174 | R36: 129946 | S36: 0 | T36: =P36+R36 -> 511120 | V36: 134384 | W36: 0 | X36: =T36+V36 -> 645504 | Z36: 134384 | AA36: 0 | AB36: =X36+Z36 -> 779888 | AD36: 134384 | AE36: 0 | AF36: =AB36+AD36 -> 914272
A37: 510545 | B37: Auxilios | C37: 0 | D37: 0 | E37: =+C37 -> 0 | G37: 350872 | H37: 0 | I37: =E37+G37 -> 350872 | J37: 350872 | K37: 0 | L37: =I37+J37 -> 701744 | N37: 350872 | O37: 0 | P37: =L37+N37 -> 1052616 | R37: 350872 | S37: 0 | T37: =P37+R37 -> 1403488 | V37: 350872 | W37: 0 | X37: =T37+V37 -> 1754360 | Z37: 350872 | AA37: 0 | AB37: =X37+Z37 -> 2105232 | AD37: 350872 | AE37: 0 | AF37: =AB37+AD37 -> 2456104
A38: 510551 | B38: Dotación y elementos seguridad trabajadores | C38: 30000 | D38: 0 | E38: =+C38 -> 30000 | G38: 391093 | H38: 0 | I38: =E38+G38 -> 421093 | J38: 0 | K38: 0 | L38: =I38+J38 -> 421093 | N38: 0 | O38: 0 | P38: =L38+N38 -> 421093 | R38: 73950 | S38: 0 | T38: =P38+R38 -> 495043 | V38: 17000 | W38: 0 | X38: =T38+V38 -> 512043 | Z38: 140504 | AA38: 0 | AB38: =X38+Z38 -> 652547 | AD38: 0 | AE38: 0 | AF38: =AB38+AD38 -> 652547
A39: 510568 | B39: Aportes a administradoras de riesgos profesionales arp | C39: 0 | D39: 0 | E39: =+C39 -> 0 | G39: 30400 | H39: 0 | I39: =E39+G39 -> 30400 | J39: 32408 | K39: 0 | L39: =I39+J39 -> 62808 | N39: 32700 | O39: 0 | P39: =L39+N39 -> 95508 | R39: 32678 | S39: 0 | T39: =P39+R39 -> 128186 | V39: 32532 | W39: 0 | X39: =T39+V39 -> 160718 | Z39: 32532 | AA39: 0 | AB39: =X39+Z39 -> 193250 | AD39: 32532 | AE39: 0 | AF39: =AB39+AD39 -> 225782
A40: 510569 | B40: Aportes a entidades promotoras de salud eps | C40: 0 | D40: 0 | E40: =+C40 -> 0 | G40: 0 | H40: 0 | I40: =E40+G40 -> 0 | J40: 0 | K40: 0 | L40: =I40+J40 -> 0 | N40: 0 | O40: 0 | P40: =L40+N40 -> 0 | R40: 0 | S40: 0 | T40: =P40+R40 -> 0 | V40: 0 | W40: 0 | X40: =T40+V40 -> 0 | Z40: 0 | AA40: 0 | AB40: =X40+Z40 -> 0 | AD40: 0 | AE40: 0 | AF40: =AB40+AD40 -> 0
A41: 510570 | B41: Aportes a fondos de pensiones y/o cesantías | C41: 0 | D41: 0 | E41: =+C41 -> 0 | G41: 349162 | H41: 0 | I41: =E41+G41 -> 349162 | J41: 373944 | K41: 0 | L41: =I41+J41 -> 723106 | N41: 374025 | O41: 0 | P41: =L41+N41 -> 1097131 | R41: 373944 | S41: 0 | T41: =P41+R41 -> 1471075 | V41: 341342 | W41: 0 | X41: =T41+V41 -> 1812417 | Z41: 341342 | AA41: 0 | AB41: =X41+Z41 -> 2153759 | AD41: 341342 | AE41: 0 | AF41: =AB41+AD41 -> 2495101
A42: 510572 | B42: Aportes cajas de compensación familiar | C42: 0 | D42: 0 | E42: =+C42 -> 0 | G42: 116400 | H42: 0 | I42: =E42+G42 -> 116400 | J42: 124648 | K42: 0 | L42: =I42+J42 -> 241048 | N42: =124700-52 -> 124648 | O42: 0 | P42: =L42+N42 -> 365696 | R42: 149712 | S42: 0 | T42: =P42+R42 -> 515408 | V42: 124648 | W42: 0 | X42: =T42+V42 -> 640056 | Z42: 124648 | AA42: 0 | AB42: =X42+Z42 -> 764704 | AD42: 124648 | AE42: 0 | AF42: =AB42+AD42 -> 889352
...

Sheet GRAFICAS PYG
B5: MES | C5: VENTAS FISCALES 2021 | D5: VENTAS FISCALES 2020 | E5: VENTAS FISCALES 2019 | F5: VENTAS FISCALES 2018 | G5: VENTAS FISCALES 2017 | H5: VENTAS SIN IVA 2021 | I5: VENTAS SIN IVA 2020 | J5: VENTAS SIN IVA 2019 | K5: VENTAS SIN IVA 2018 | L5: VENTAS SIN IVA 2017 | M5: GASTOS 2021 | N5: GASTOS 2020 | O5: GASTOS 2019 | P5: GASTOS 2018 | Q5: GASTOS 2017 | R5: UTILIDAD 2021 | S5: UTILIDAD 2020 | T5: UTILIDAD 2019 | U5: UTILIDAD 2018 | V5: UTILIDAD 2017
B6: ENERO | C6: 4088450 | D6: 9772741 | E6: 5232922 | F6: 20519674 | G6: 4068398 | H6: 5295548 | I6: 4656136 | J6: 7998115 | K6: 5489862 | L6: 3111549 | M6: =+'PYG '!C153 -> 9031235 | N6: 11183760 | O6: 8192569 | P6: 7055307 | Q6: 10452832 | R6: 352800 | S6: 3245117 | T6: 5038468 | U6: 18954229 | V6: -3272885
B7: FEBRERO | C7: 3444630 | D7: 8662267 | E7: 6735984 | F7: 347610 | G7: 3781685 | H7: 6881543 | I7: 7804429 | J7: 4974355 | K7: 7374328 | L7: 8157506 | M7: =+'PYG '!G153 -> 12420337 | N7: 13337610 | O7: 8084721 | P7: 8975623 | Q7: 8843670 | R7: =+C7+H7-M7 -> -2094164 | S7: 3129086 | T7: 3625618 | U7: -1253685 | V7: 3095521
B8: MARZO | C8: 4294490 | D8: 11213082 | E8: 4072345 | F8: 245528 | G8: 3264345 | H8: 7901560 | I8: 5900305 | J8: 7130437 | K8: 5439456 | L8: 5780617 | M8: =+'PYG '!J153 -> 13591375 | N8: 10865138 | O8: 8025783 | P8: 9788704 | Q8: 8621927 | R8: =+C8+H8-M8 -> -1395325 | S8: 6248249 | T8: 3176999 | U8: -4103720 | V8: 423035
B9: ABRIL | C9: 3094715 | D9: 109000 | E9: 8902568 | F9: 311788 | G9: 5714524 | H9: 10475785 | I9: 121014 | J9: 6001004 | K9: 7142915 | L9: 5636163 | M9: =+'PYG '!N153 -> 17060981 | N9: 8424882 | O9: 11161681 | P9: 9211395 | Q9: 6162384 | R9: =+C9+H9-M9 -> -3490481 | S9: -8194868 | T9: 3741891 | U9: -1756692 | V9: 5188303
B10: MAYO | C10: =+'PYG '!S9 -> 3036250 | E10: 4831245 | F10: 2070588 | G10: 1563099 | H10: 9475619 | I10: 1804105 | J10: 7419178 | K10: 5721041 | L10: 13796936 | M10: =+'PYG '!R153 -> 11744517 | N10: 10909925 | O10: 10164486 | P10: 8014528 | Q10: 10155182 | R10: =+C10+H10-M10 -> 767352.37 | S10: -9105820 | T10: 2085937 | U10: -222899 | V10: 5204853
B11: JUNIO | C11: =+'PYG '!W9 -> 3220640 | D11: 15088775 | E11: 2541098 | F11: 4186225 | G11: 2504537 | H11: 14072478 | I11: 5883300 | J11: 6384585 | K11: 4021740 | L11: 6565667 | M11: =+'PYG '!V154 -> 12797380 | N11: 12990071 | O11: 8433671 | P11: 7385244 | Q11: 14240736 | R11: =+C11+H11-M11 -> 4495738 | S11: 7982004 | T11: 492012 | U11: 822721 | V11: -5170532
B12: JULIO | C12: =+'PYG '!AA9 -> 2982171 | D12: 5107405 | E12: 2060928 | F12: 3502320 | G12: 14376812 | H12: 7847354 | I12: 9069381 | J12: 4374077 | K12: 1959742 | L12: 6138041 | M12: =+'PYG '!Z154 -> 13357892 | N12: 11530572 | O12: 8752682 | P12: 7676064 | Q12: 10531315 | R12: -2527014 | S12: 2646214 | T12: -2317677 | U12: -2214002 | V12: 9983538
B13: AGOSTO | C13: =+'PYG '!AE9 -> 2259634 | D13: 4348355 | E13: 722060 | F13: 13456626 | G13: 9843168 | H13: 10482068 | I13: 6862717 | J13: 8088583 | K13: 4820282 | L13: 5449400 | M13: =+'PYG '!AD154 -> 12441445 | N13: 11013798 | O13: 10250005 | P13: 9472439 | Q13: 10083753 | R13: =+C13+H13-M13 -> 300257 | S13: 197274 | T13: -1439362 | U13: 8804469 | V13: 5208815
B19: TOTAL | C19: =SUM(C6:C18) -> 26420980 | D19: =SUM(D6:D18) -> 54301625 | E19: =SUM(E6:E18) -> 35099150 | F19: =SUM(F6:F18) -> 44640359 | G19: =SUM(G6:G18) -> 45116568 | H19: =SUM(H6:H18) -> 72431955 | I19: =SUM(I6:I18) -> 42101387 | J19: =SUM(J6:J18) -> 52370334 | ... V19: =SUM(V6:V18) -> 20660648
B44: MES | C44: VENTAS FISCALES 2021 | D44: VENTAS FISCALES 2020 | E44: VENTAS FISCALES 2019 | F44: VENTAS FISCALES 2018 | G44: VENTAS FISCALES 2017
B45: ENERO | C45: 4088450 | D45: 9772741 | E45: 5232922 | F45: 20519674 | G45: =522963+299991+2769114+199640+276690 -> 4068398
B46: FEBRERO | C46: 3444630 | D46: 8662267 | E46: 6735984 | F46: 347610 | G46: =34155+356641+30000+185495+199640+2769114+52440+124200+30000 -> 3781685
B47: MARZO | C47: 4294490 | D47: 11213082 | E47: 4072345 | F47: =245268+260 -> 245528 | G47: =2501135+199640+393580+80730+29750+34510+25000 -> 3264345
B48: ABRIL | C48: 3094715 | D48: 109000 | E48: 8902568 | F48: =44268+102185+80587+29750+50000+4998 -> 311788 | G48: =2769114+199640+549053+161460+430560+90000+267950+437283+714714+17250+40000+37500 -> 5714524
B49: MAYO | C49: 3036250 | E49: 4831245 | F49: 2070588 | G49: 1563099
B50: JUNIO | C50: 3220640 | D50: 15088775 | E50: 2541098 | F50: 4186225 | G50: 2504537
B51: JULIO | C51: 2982171 | D51: 5107405 | E51: 2060928 | F51: 3502320 | G51: 14376812
B52: AGOSTO | C52: 2259634 | D52: 4348355 | E52: 722060 | F52: 13456626 | G52: 9843168
B53: SEPTIEMBRE | D53: 5343486 | E53: 1921510 | F53: 0 | G53: 6807513
B54: OCTUBRE | D54: 5206920 | E54: 1940050 | F54: =+'[1]PYG '!AP47 -> 11000000 | G54: 3921439
B55: NOVIEMBRE | D55: 4539945 | E55: 6096979 | F55: =+'[1]PYG '!AT47 -> 12000000 | G55: 2545390
B56: DICIEMBRE | D56: 5671900 | E56: 10802895 | F56: =+'[1]PYG '!AX47 -> 13000000 | G56: 68513641
B58: TOTAL | C58: =SUM(C45:C57) -> 26420980 | D58: =SUM(D45:D57) -> 75063876 | E58: =SUM(E45:E57) -> 55860584 | F58: =SUM(F45:F57) -> 80640359 | G58: =SUM(G45:G57) -> 126904551
C61: =SUM(C45:C48) -> 14922285 | F61: =SUM(F45:F48) -> 21424600
B70: MES | C70: VENTAS SIN IVA 2021 | D70: VENTAS SIN IVA 2020 | E70: VENTAS SIN IVA 2019 | F70: VENTAS SIN IVA 2018 | G70: VENTAS SIN IVA 2017
B71: ENERO | C71: 5295548 | D71: 4656136 | E71: 7998115 | F71: 5489862 | G71: 3111549
B72: FEBRERO | C72: 6881543 | D72: 7804429 | E72: 4974355 | F72: 7374328 | G72: 8157506
B73: MARZO | C73: 7901560 | D73: 5900305 | E73: 7130437 | F73: 5439456 | G73: 5780617
B74: ABRIL | C74: 10475785 | D74: 121014 | E74: 6001004 | F74: 7142915 | G74: 5636163
B75: MAYO | C75: 9475619 | D75: 1804105 | E75: 7419178 | F75: 5721041 | G75: 13796936
B76: JUNIO | C76: 14072478 | D76: 5883300 | E76: 6384585 | F76: 4021740 | G76: 6565667
B77: JULIO | C77: 7847354 | D77: 9069381 | E77: 4374077 | F77: 1959742 | G77: 6138041
B78: AGOSTO | C78: 10482068 | D78: 6862717 | E78: 8088583 | F78: 4820282 | G78: 5449400
B79: SEPTIEMBRE | D79: 9114471 | E79: 5761435 | F79: 6035931 | G79: 6941815
B80: OCTUBRE | D80: 11912110 | E80: 5903667 | F80: 10697305 | G80: 5541550
B81: NOVIEMBRE | D81: 9403633 | E81: 6953987 | F81: 7259988 | G81: 6901480
B82: DICIEMBRE | D82: 11129725 | E82: 3580427 | F82: 8230584 | G82: 7106144
B83: TOTAL | C83: =SUM(C71:C82) -> 72431955 | D83: =SUM(D71:D82) -> 83661326 | E83: =SUM(E71:E82) -> 74569850 | F83: =SUM(F71:F82) -> 74193174 | G83: =SUM(G71:G82) -> 81126868
C86: =SUM(C71:C74) -> 30554436 | F86: =SUM(F71:F74) -> 25446561
...

Sheet INDICADORES
A1: Razones Financieras
A2: Liquidez
A4: Liquidez | B4: Activos Circulantes | C4: =+AGOSTO!E56 -> 576711378 | D4: =+C4/C5 -> 96.114991 | E4: La empresa cuenta con el 96,11% de respaldo de los activos
B5: Pasivos Circulantes | C5: =+AGOSTO!E93 -> 6000223
A7: Prueba Acida | B7: Activos Circulantes - Inventarios | C7: =+AGOSTO!E56-AGOSTO!E35 -> 410225482 | D7: =+C7/C8 -> 68.368373 | E7: con el activo que tenemos hay el 68,36% para pagar el pasivo
B8: Pasivos Circulantes | C8: =+C5 -> 6000223
A10: Administración de Activos
A12: Rotación Activos Fijos | B12: Ventas | C12: 136687592 | D12: =+C12/C13 -> 0.38563949 | E12: la empresa roto su activo el 0,38
B13: Activos Fijos Netos | C13: =+AGOSTO!E39 -> 354443971
A15: Rotación Activos Totales | B15: Ventas | C15: =+C12 -> 136687592 | D15: =+C15/C16 -> 0.23701213 | E15: la empresa roto su activo totales el 0,23
B16: Activos Totales | C16: =+C4 -> 576711378
A18: Administración de Deudas
A20: Razón de Endeudamiento | B20: Deudas Totales | C20: =+AGOSTO!E93 -> 6000223 | D20: =+C20/C21 -> 0.010404204 | E20: la empresa de los activos debe el 0,010
B21: Activos totales | C21: =+AGOSTO!E56 -> 576711378

Sheet Hoja1
D2: DEPRECIACION ANUAL
B3: Maquinaria y equipos en montaje | C3: =+C4 -> 10126196
B4: Equipo de oficina | C4: 10126196 | D4: =+C4/10 -> 1012619.6 | E4: =+D4/12 -> 84384.967
B5: Construcciones y edificaciones | C5: =+C6+C7 -> 381000000 | E5: =+D5/12 -> 0
B6: Apto sion | C6: 91000000 | D6: =+C6/30 -> 3033333.3 | E6: =+D6/12 -> 252777.78 | F6: =+E6+E7 -> 1058333.3
B7: Apto tamara | C7: 290000000 | D7: =+C7/30 -> 9666666.7 | E7: =+D7/12 -> 805555.56
B8: Equipo de oficina | C8: =+C9 -> 1070000 | E8: =+D8/12 -> 0
B9: Equipos | C9: 1070000 | D9: =+C9/10 -> 107000 | E9: =+D9/12 -> 8916.6667
B10: Equipo de computación y comunicación | C10: =+C11 -> 3109000 | E10: =+D10/12 -> 0
B11: Equipo de procesamiento de datos | C11: 3109000 | D11: =+C11/5 -> 621800 | E11: =+D11/12 -> 51816.667
B12: Flota y equipo de transporte | C12: 34596000 | E12: =+D12/12 -> 0
B13: Camiones, volquetas y furgones | C13: 34596000 | D13: =+C13/5 -> 6919200 | E13: =+D13/12 -> 576600
D14: =SUM(D3:D13) -> 21360620 | E14: =SUM(E3:E13) -> 1780051.6

Sheet TABLAS
B8: MES | C8: VENTAS FISCALES 2021 | D8: VENTAS FISCALES 2020 | E8: VENTAS FISCALES 2019 | F8: VENTAS FISCALES 2018 | G8: VENTAS FISCALES 2017
B9: MAYO | C9: =+'PYG '!S8 -> 3036250 | E9: 4831245 | F9: 2070588 | G9: 1563099
B10: JUNIO | C10: =+'PYG '!W8 -> 3220640 | D10: 15088775 | E10: 2541098 | F10: 4186225 | G10: 2504537
B11: JULIO | C11: =+'PYG '!AA8 -> 2982171 | D11: 5107405 | E11: 2060928 | F11: 3502320 | G11: 14376812
B12: AGOSTO | C12: =+'PYG '!AE8 -> 2259634 | D12: 4348355 | E12: 722060 | F12: 13456626 | G12: 9843168
B13: TOTAL | C13: =SUM(C9:C12) -> 11498695 | D13: =SUM(D9:D12) -> 24544535 | E13: =SUM(E9:E12) -> 10155331 | F13: =SUM(F9:F12) -> 23215759 | G13: =SUM(G9:G12) -> 28287616
B19: MES | C19: VENTAS SIN IVA 2021 | D19: VENTAS SIN IVA 2020 | E19: VENTAS SIN IVA 2019 | F19: VENTAS SIN IVA 2018 | G19: VENTAS SIN IVA 2017 | K19: MES | L19: VENTA ACUMULADA 2021 | M19: VENTA ACUMULADA 2020 | N19: VENTA ACUMULADA 2019 | O19: VENTA ACUMULADA 2018 | P19: VENTA ACUMULADA 2017
B20: MAYO | C20: 9475619 | D20: 1804105 | E20: 7419178 | F20: 5721041 | G20: 13796936 | K20: MAYO | L20: =+C9+C20 -> 12511869 | M20: =+D9+D20 -> 1804105 | N20: =+E9+E20 -> 12250423 | O20: =+F9+F20 -> 7791629 | P20: =+G9+G20 -> 15360035
B21: JUNIO | C21: 14072478 | D21: 5883300 | E21: 6384585 | F21: 4021740 | G21: 6565667 | K21: JUNIO | L21: =+C10+C21 -> 17293118 | M21: =+D10+D21 -> 20972075 | N21: =+E10+E21 -> 8925683 | O21: =+F10+F21 -> 8207965 | P21: =+G10+G21 -> 9070204
B22: JULIO | C22: 7847354 | D22: 9069381 | E22: 4374077 | F22: 1959742 | G22: 6138041 | K22: JULIO | L22: =+C11+C22 -> 10829525 | M22: =+D11+D22 -> 14176786 | N22: =+E11+E22 -> 6435005 | O22: =+F11+F22 -> 5462062 | P22: =+G11+G22 -> 20514853
B23: AGOSTO | C23: 10482068 | D23: 6862717 | E23: 8088583 | F23: 4820282 | G23: 5449400 | K23: AGOSTO | L23: =+C12+C23 -> 12741702 | M23: =+D12+D23 -> 11211072 | N23: =+E12+E23 -> 8810643 | O23: =+F12+F23 -> 18276908 | P23: =+G12+G23 -> 15292568
B24: TOTAL | C24: =SUM(C20:C23) -> 41877519 | D24: =SUM(D20:D23) -> 23619503 | E24: =SUM(E20:E23) -> 26266423 | F24: =SUM(F20:F23) -> 16522805 | G24: =SUM(G20:G23) -> 31950044 | K24: TOTAL | L24: =+C13+C24 -> 53376214 | M24: =SUM(M20:M23) -> 48164038 | N24: =SUM(N20:N23) -> 36421754 | O24: =SUM(O20:O23) -> 39738564 | P24: =SUM(P20:P23) -> 60237660
C25: =+C13+C24 -> 53376214 | D25: =+D13+D24 -> 48164038 | E25: =+E13+E24 -> 36421754 | F25: =+F13+F24 -> 39738564 | G25: =+G13+G24 -> 60237660
B27: MES | C27: GASTOS 2021 | D27: GASTOS 2020 | E27: GASTOS 2019 | F27: GASTOS 2018 | G27: GASTOS 2017
B28: MAYO | C28: 11744517 | D28: 10909925 | E28: 10164486 | F28: 8014528 | G28: 10155182
B29: JUNIO | C29: 12797380 | D29: 12990071 | E29: 8433671 | F29: 7385244 | G29: 14240736
B30: JULIO | C30: 13357892 | D30: 11530572 | E30: 8752682 | F30: 7676064 | G30: 10531315
B31: AGOSTO | C31: 12441445 | D31: 11013798 | E31: 10250005 | F31: 9472439 | G31: 10083753
B32: TOTAL | C32: =SUM(C28:C31) -> 50341234 | D32: =SUM(D28:D31) -> 46444366 | E32: =SUM(E28:E31) -> 37600844 | F32: =SUM(F28:F31) -> 32548275 | G32: =SUM(G28:G31) -> 45010986
C33: 0.08
B35: MES | C35: UTILIDAD 2021 | D35: UTILIDAD 2020 | E35: UTILIDAD 2019 | F35: UTILIDAD 2018 | G35: UTILIDAD 2017
B36: MAYO | C36: 767352.37 | D36: -9105820 | E36: 2085937 | F36: -222899 | G36: 5204853
B37: JUNIO | C37: 4495738 | D37: 7982004 | E37: 492012 | F37: 822721 | G37: -5170532
B38: JULIO | C38: -2527014 | D38: 2646214 | E38: -2317677 | F38: -2214002 | G38: 9983538
B39: AGOSTO | C39: 300257 | D39: 197274 | E39: -1439362 | F39: 8804469 | G39: 5208815
B40: TOTAL | C40: =SUM(C36:C39) -> 3036333.4 | D40: =SUM(D36:D39) -> 1719672 | E40: =SUM(E36:E39) -> -1179090 | F40: =SUM(F36:F39) -> 7190289 | G40: =SUM(G36:G39) -> 15226674
