Workbook

Sheet BALANCE DICIEMBRE
A1: EQUIORIENTE LTDA
A2: SITUACION FINANCIERA
A3: FECHA: 31 de Diciembre DE 2025
A6: 1 | C6: ACTIVO
A8: 11 | C8: Efectivo y equivalentes al efectivo
A9: 1105 | C9: Caja | E9: =+D10 -> 9204613
A10: 110505 | C10: Caja general | D10: 9204613
A12: 1120 | C12: Cuentas de ahorro
A13: 112005 | C13: Bancos | E13: =+D14 -> 6165540.4
A14: 11200501 | C14: BBVA | D14: 6165540.4
A16: 1220 | C16: CDT | E16: =+D17+D19 -> 110901494
C17: CDT BBVA 19/12/2025 | D17: 88137296 | H17: venci 19/03/2026 | I17: TRIMESTRE
C18: CDT COMULTRASAN20/02/2025 | D18: =7474000+J18 -> 7810240 | H18: VENC 20/08/2025 | I18: TRIMESTRE | J18: 336240
C19: CDT COOMULTRASAN 18/07/2025 | D19: =22337500+J19 -> 22764198 | H19: VENC 18/10/2025 | I19: TRIMESTRE | J19: =444477-17779 -> 426698
A21: 13 | C21: Cuentas por cobrar (instrumentos financieros)
A22: 1305 | C22: Clientes | E22: =+D23 -> 5426583 | H22: INMUEBLE | I22: 91000000
A23: 130505 | C23: Nacionales | D23: =+CARTERA!D28 -> 5426583 | H23: DEPREC | I23: =+D17-I22 -> -2862704
I24: =+I22+I23 -> 88137296
A25: 130515 | C25: Deudores facturacion sin iva | E25: =+D26 -> 30240
C26: Varios | D26: =+CARTERA!D17 -> 30240
A28: 1330 | C28: ANTICIPO PUERTA DE ORO | E28: =+D29 -> 50879370
C29: Puerta de Oro etapa 3 | D29: =+ANTICIPOS!E40 -> 50879370
A31: 1355 | C31: Anticipo de impuestos y contribuciones o saldos a favor | E31: =SUM(D32:D35) -> 4551523.4
A32: 135505 | C32: Anticipo de impuestos de renta y complementarios | D32: 3476000
A33: 135518 | C33: Reteica | D33: 50487
A34: 135515 | C34: Retención en la fuente | D34: =+Hoja1!H20 -> 570036.4
A35: 13559006 | C35: Autorretencion de renta | D35: 455000
A37: 15 | C37: Propiedades planta y equipo | E37: =SUM(D38:D46) -> 222134229
A38: 1516 | C38: Construcciones y edificaciones
A39: 151605 | C39: Apto sion | D39: 0
A40: 1520 | C40: MAQUINARIA Y EQUIPO | D40: 192065553
A41: 152005 | C41: Formaleta
A42: 1528 | C42: Equipo de computación y comunicación
A43: 152805 | C43: Equipo de procesamiento de datos | D43: 3718000
A44: 1540 | C44: Flota y equipo de transporte | D44: 0
A45: 154008 | C45: Camiones, volquetas y furgones | D45: 34596000
A46: 1592 | C46: Depreciación acumulada | D46: =-11108028+2862704 -> -8245324
A48: 16 | C48: Intangibles | E48: =+D49 -> 2548980
A49: 1635 | C49: Licencias | D49: 2548980
A51: TOTAL ACTIVO | E51: =SUM(E9:E49) -> 4.1184257e+08
...

Sheet VALOR EMPRESA 2025
A3: MATERIAL DE FORMALETA
B4: 2018 | C4: DEPRE | D4: VR FORMALETA
A5: EQUIPO DE CONSTRUCCION | B5: 381000000 | C5: 152400000 | D5: =+B5-C5-6250000 -> 222350000
A6: APTO ANTICIPOS PUERTA ORO | D6: 192665553
A7: CDT BBVA 19/12/2025 | D7: 88137296
A8: CDT COMULTRASAN20/02/2025 | D8: =7474000+H8 -> 7474000
A9: CDT COOMULTRASAN 18/07/2025 | D9: =22337500+H9 -> 22337500
A10: CAJA | D10: 9204613
D13: =SUM(D5:D9) -> 532964349
A14: PASIVOS | D14: =+'BALANCE DICIEMBRE'!E80 -> 6891940
D15: =+D13-D14 -> 526072409

Sheet pyg2025
A1: EQUIORIENTE LTDA
A2: INFORMES AÑO 2025
S3: 45809
C4: 45658 | G4: 45689 | J4: 45717 | M4: 45748 | P4: 45778 | W4: 45839 | AA4: 45870 | AE4: 45901 | AI4: 45931 | AM4: 45962 | AQ4: 45992
A5: Cuenta | E5: Saldos a 31/01/23 | G5: 4 | I5: Saldos a 28/02/2023 | J5: Mov. 01/03/2023 a 31/03/2023 | L5: Saldos a 31/03/2023 | M5: Mov. 01/04/2023 a 30/04/2023 | O5: Saldos a 30/04/2023 | P5: Mov. 01/05/2023 a 31/05/2023 | R5: Saldos a 31/05/2023 | S5: Mov. 01/06/2023 a 30/06/202 | U5: Saldos a 30/06/2023 | W5: Mov. 01/07/2023 a 31/07/2023 | Y5: Saldos a 31/07/2022 | AA5: Mov. 01/08/2023 a 31/08/2023 | AC5: Saldos a 30/08/2022 | AE5: Mov. 01/09/2022 a 30/09/2022 | AG5: Saldos a 30/09/2022 | AI5: Mov. 01/10/2022 a 31/10/2022 | AK5: Saldos a 31/10/2022 | AM5: Mov. 01/11/2022 a 30/11/2022 | AO5: Saldos a 30/11/2022 | AQ5: Mov. 01/12/2022 a 31/12/2022 | AS5: Saldos a 30/12/2022
A6: Cód. | B6: Nombre | C6: Débitos | D6: Créditos | E6: Saldo actual | G6: Débitos | H6: Créditos | I6: Saldo actual | J6: Débitos | K6: Créditos | L6: Saldo actual | M6: Débitos | N6: Créditos | O6: Saldo actual | P6: Débitos | Q6: Créditos | R6: Saldo actual | S6: Débitos | T6: Créditos | U6: Saldo actual | W6: Débitos | X6: Créditos | Y6: Saldo actual | AA6: Débitos | AB6: Créditos | AC6: Saldo actual | AE6: Débitos | AF6: Créditos | AG6: Saldo actual | AI6: Débitos | AJ6: Créditos | AK6: Saldo actual | AM6: Débitos | AN6: Créditos | AO6: Saldo actual | AQ6: Débitos | AR6: Créditos | AS6: Saldo actual
A7: 4 | B7: INGRESOS | C7: 0 | D7: =D8+D16 -> 3650160 | E7: =E8+E16 -> 3650160 | G7: =G14 -> 0 | H7: =H8+H16 -> 8194444 | I7: =+E7+H7 -> 11844604 | J7: =+J8 -> 0 | K7: =K16+K8 -> 15949913 | L7: =+I7+J7+K7 -> 27794517 | M7: =+M14 -> 0 | N7: =N8+N16 -> 8100964 | O7: =+L7-M7+N7 -> 35895481 | P7: =+P8 -> 0 | Q7: =Q8+Q16 -> 18412486 | R7: =R8+R16 -> 54307967 | S7: =+S14 -> 1071520 | T7: =T8+T16 -> 13297291 | U7: =+R7-S7+T7 -> 66533738 | W7: =+W15 -> 0 | X7: =+X8+X16 -> 14522346 | Y7: =U7+X7 -> 81056084 | AA7: =+AA14 -> 0 | AB7: =+AB8+AB16 -> 19706466 | AC7: =+Y7+AB7-AA7 -> 100762550 | AE7: =+AE14 -> 0 | AF7: =+AF8+AF16 -> 12601267 | AG7: =AC7+AF7 -> 113363817 | AI7: =+AI14 -> 0 | AJ7: =+AJ8+AJ16 -> 13432176 | AK7: =AG7+AJ7 -> 126795993 | AM7: =+AM14 -> 0 | AN7: =+AN8+AN16 -> 11210209 | AO7: =AK7+AN7 -> 138006202 | AQ7: =+AQ14 -> 7800 | AR7: =+AR8+AR16 -> 24004695 | AS7: =AO7+AR7-AQ7 -> 162003097
A8: 41 | B8: Operacionales | C8: 0 | D8: =+D9 -> 496100 | E8: =+E9+E14 -> 496100 | G8: =G15 -> 0 | H8: =H9 -> 24370 | I8: =+E8+H8 -> 520470 | J8: =+J14 -> 0 | K8: =+K9+K13 -> 100949 | L8: =+I8-J8+K8 -> 621419 | M8: 0 | N8: =N9 -> 55000 | O8: =+L8+N8 -> 676419 | Q8: =+Q9 -> 4552322 | R8: =+O8-P8+Q8 -> 5228741 | S8: 0 | T8: =+T9+T10+T11+T12+T13+T14+T15 -> 5319930 | U8: =+R8-S8+T8 -> 10548671 | W8: 0 | X8: =+X9 -> 5508975 | Y8: =+U8-W8+X8 -> 16057646 | AA8: =+AA14 -> 0 | AB8: =+AB9 -> 1143000 | AC8: =+Y8+AB8-AA8 -> 17200646 | AE8: =+AE14 -> 0 | AF8: =+AF9 -> 1275896 | AG8: =+AG9+AG14 -> 14228132 | AI8: =+AI14 -> 0 | AJ8: =AJ9 -> 914530 | AK8: =+AK9+AK14 -> 15142662 | AM8: =+AM14 -> 0 | AN8: =AN9 -> 1555310 | AO8: =+AO9+AO14 -> 16697972 | AQ8: =+AQ14 -> 7800 | AR8: =AR9 -> 14222015 | AS8: =+AO8-AQ8+AR8 -> 30912187
A9: 4155 | B9: Actividades inmobiliarias, empresariales y de alquiler | C9: 0 | D9: =846100-350000 -> 496100 | E9: =D9 -> 496100 | G9: 0 | H9: =H10+H11+H12 -> 24370 | I9: =+E9+H9 -> 520470 | J9: 0 | K9: =K10+K12 -> 100949 | L9: =+I9-J9+K9 -> 621419 | M9: 0 | N9: =+N10+N12 -> 55000 | O9: =+L9+N9 -> 676419 | P9: 0 | Q9: =+Q10+Q12 -> 4552322 | R9: =+O9-P9+Q9 -> 5228741 | S9: 0 | U9: =+R9-S9+T9 -> 5228741 | W9: 0 | X9: =+X10+X11+X12+X13 -> 5508975 | Y9: =+U9-W9+X9 -> 10737716 | AA9: 0 | AB9: =+AB10+AB12 -> 1143000 | AC9: =Y9+AB9 -> 11880716 | AE9: 0 | AF9: =+AF10+AF11+AF12+AF13 -> 1275896 | AG9: =AC9+AF9 -> 13156612 | AI9: 0 | AJ9: =+AJ10+AJ11+AJ12+AJ13 -> 914530 | AK9: =AG9+AJ9 -> 14071142 | AM9: 0 | AN9: =+AN10+AN11+AN12+AN13 -> 1555310 | AO9: =AK9+AN9 -> 15626452 | AQ9: 0 | AR9: =+AR10+AR11+AR12+AR13 -> 14222015 | AS9: =+AS10+AS11+AS12 -> 34672297
A10: 415520 | B10: Alquiler IVA | C10: 0 | E10: =+D10 -> 0 | G10: 0 | H10: 24370 | I10: =+E10+H10 -> 24370 | J10: 0 | K10: 75949 | L10: =+I10-J10+K10 -> 100319 | M10: 0 | N10: 55000 | O10: =+L10+N10 -> 155319 | P10: 0 | Q10: 4027322 | R10: =+O10-P10+Q10 -> 4182641 | S10: 0 | T10: 4522430 | U10: =+R10-S10+T10 -> 8705071 | W10: 0 | X10: 5168975 | Y10: =+U10-W10+X10 -> 13874046 | AA10: 0 | AB10: 973000 | AC10: =+Y10+AB10 -> 14847046 | AE10: 0 | AF10: 1235896 | AG10: =+AC10+AF10 -> 16082942 | AI10: 0 | AJ10: 779530 | AK10: =+AG10+AJ10 -> 16862472 | AM10: 0 | AN10: 1335310 | AO10: =AK10+AN10 -> 18197782 | AQ10: 0 | AR10: 13202015 | AS10: =AO10+AR10 -> 31399797
A11: 415525 | B11: VENTA EQUIPO | D11: 0 | E11: =+D11 -> 0 | G11: 0 | H11: 0 | I11: =+G11+H11+E11 -> 0 | K11: 0 | L11: =+I11-J11+K11 -> 0 | M11: 0 | N11: 0 | O11: =+L11+N11 -> 0 | P11: 0 | Q11: 0 | R11: =+O11-P11+Q11 -> 0 | U11: =+R11-S11+T11 -> 0 | Y11: =+U11-W11+X11 -> 0 | AC11: =Y11+AB11 -> 0 | AG11: =AC11+AF11 -> 0 | AK11: =AG11+AJ11 -> 0 | AO11: =AK11+AN11 -> 0 | AS11: =AO11+AR11 -> 0
A12: 415515 | B12: Transporte | C12: 0 | E12: =+D12 -> 0 | G12: 0 | H12: 0 | I12: =+E12+H12 -> 0 | J12: 0 | K12: 25000 | L12: =+I12-J12+K12 -> 25000 | M12: 0 | N12: 0 | O12: =+L12+N12 -> 25000 | P12: 0 | Q12: 525000 | R12: =+O12-P12+Q12 -> 550000 | S12: 0 | T12: 797500 | U12: =+R12-S12+T12 -> 1347500 | W12: 0 | X12: 340000 | Y12: =+U12-W12+X12 -> 1687500 | AA12: 0 | AB12: 170000 | AC12: =Y12+AB12 -> 1857500 | AE12: 0 | AF12: 40000 | AG12: =AC12+AF12 -> 1897500 | AI12: 0 | AJ12: 135000 | AK12: =AG12+AJ12 -> 2032500 | AM12: 0 | AN12: 220000 | AO12: =AK12+AN12 -> 2252500 | AQ12: 0 | AR12: 1020000 | AS12: =AO12+AR12 -> 3272500
A13: 415595 | E13: =+D13 -> 0 | L13: =+I13-J13+K13 -> 0 | M13: 0 | N13: 0 | P13: 0 | R13: =+O13-P13+Q13 -> 0 | U13: =+R13-S13+T13 -> 0 | Y13: =+U13-W13+X13 -> 0 | AS13: =AO13+AR13 -> 0
A14: 4175 | B14: Devoluciones en ventas (db) | E14: =+D14 -> 0 | G14: =G15 -> 0 | H14: =H15 -> 0 | I14: =+G14+H14+E14 -> 0 | J14: 0 | K14: =+K15 -> 0 | L14: =+I14-J14+K14 -> 0 | M14: 0 | N14: 0 | O14: =+L14+N14 -> 0 | R14: =+O14-P14+Q14 -> 0 | S14: 1071520 | U14: =+S14 -> 1071520 | Y14: =+U14+X14 -> 1071520 | AC14: =+Y14-AA14 -> 1071520 | AE14: =+AE15 -> 0 | AG14: =+AC14+AE14 -> 1071520 | AI14: =+AI15 -> 0 | AK14: =+AG14+AI14 -> 1071520 | AM14: 0 | AO14: =+AK14+AM14 -> 1071520 | AQ14: =+AQ15 -> 7800 | AS14: =+AO14+AQ14 -> 1079320
A15: 417501 | B15: Devoluciones en ventas (db) | I15: =+G15+H15+E15 -> 0 | J15: =+J14 -> 0 | L15: =+I15-J15+K15 -> 0 | M15: 0 | N15: 0 | O15: =+L15+N15 -> 0 | R15: =+O15-P15+Q15 -> 0 | U15: =R15+T15 -> 0 | Y15: =+U15+X15 -> 0 | AA15: 0 | AC15: =+Y15+AA15 -> 0 | AG15: =+AC15+AE15 -> 0 | AK15: =+AG15+AI15 -> 0 | AM15: 0 | AO15: =+AK15+AM15 -> 0 | AQ15: 7800 | AS15: =AO15+AR15 -> 0
A16: 42 | B16: No operacionales | C16: 0 | D16: =D17+D21+D24+D26 -> 3154060 | E16: =+D16 -> 3154060 | G16: 0 | H16: =H17+H21+H24+H26 -> 8170074 | I16: =+G16+H16+E16 -> 11324134 | J16: 0 | K16: =K17+K21+K24 -> 15848964 | L16: =I16+K16 -> 27173098 | M16: 0 | N16: =N17+N21+N24+N26 -> 8045964 | O16: =+L16+N16 -> 35219062 | P16: 0 | Q16: =Q17+Q21+Q24+Q26 -> 13860164 | R16: =+O16+Q16 -> 49079226 | S16: 0 | T16: =T17+T21+T24+T26 -> 7977361 | U16: =R16+T16 -> 57056587 | W16: 0 | X16: =X17+X21+X24+X26 -> 9013371 | Y16: =U16+X16 -> 66069958 | AA16: =AA17+AA21+AA24 -> 0 | AB16: =AB17+AB21+AB24+AB26 -> 18563466 | AC16: =Y16+AB16 -> 84633424 | AE16: =AE17+AE21+AE24 -> 0 | AF16: =AF17+AF21+AF24+AF26 -> 11325371 | AG16: =AC16+AF16 -> 95958795 | AI16: =AI17+AI21+AI24 -> 0 | AJ16: =AJ17+AJ21+AJ24+AJ26 -> 12517646 | AK16: =AG16+AJ16 -> 108476441 | AM16: =AM17+AM21+AM24 -> 0 | AN16: =AN17+AN21+AN24+AN26 -> 9654899 | AO16: =AK16+AN16 -> 118131340 | AQ16: =AQ17+AQ21+AQ24 -> 0 | AR16: =AR17+AR21+AR24+AR26 -> 9782680 | AS16: =AO16+AR16 -> 127914020
A17: 4210 | B17: Financieros | C17: 0 | D17: =D18 -> 110 | E17: =+D17 -> 110 | G17: 0 | H17: =+H18 -> 54 | I17: =+G17+H17+E17 -> 164 | J17: 0 | K17: =K18+K19+K20 -> 4 | L17: =I17+K17 -> 168 | M17: 0 | N17: =+N18+N19 -> 34 | O17: =+L17+N17 -> 202 | P17: 0 | Q17: =Q18+Q19+Q20 -> 524 | R17: =+O17+Q17 -> 726 | S17: 0 | T17: =T18+T19 -> 1101 | U17: =R17+T17 -> 1827 | W17: 0 | X17: =+X18+X19 -> 1633 | Y17: =U17+X17 -> 3460 | AA17: =AA18+AA19+AA20 -> 0 | AB17: =+AB20 -> 0 | AC17: =Y17+AB17 -> 3460 | AE17: =AE18+AE19+AE20 -> 0 | AF17: =+AF18+AF19 -> 211 | AG17: =AC17+AF17 -> 3671 | AI17: =AI18+AI19+AI20 -> 0 | AJ17: =+AJ18+AJ19 -> 426712 | AK17: =AG17+AJ17 -> 430383 | AM17: =AM18+AM19+AM20 -> 0 | AN17: =+AN18+AN19 -> 999 | AO17: =AK17+AN17 -> 431382 | AQ17: =AQ18+AQ19+AQ20 -> 0 | AR17: =+AR18+AR19 -> 1722552 | AS17: =AO17+AR17 -> 2153934
A18: 421005 | B18: Intereses | C18: 0 | D18: 110 | E18: =+D18 -> 110 | G18: 0 | H18: 54 | I18: =+G18+H18+E18 -> 164 | J18: 0 | K18: 4 | L18: =I18+K18 -> 168 | M18: 0 | N18: 34 | O18: =+L18+N18 -> 202 | P18: 0 | Q18: 524 | R18: =+O18+Q18 -> 726 | S18: 0 | T18: 34 | U18: =R18+T18 -> 760 | W18: 0 | X18: 36 | Y18: =U18+X18 -> 796 | AA18: 0 | AB18: 336240 | AC18: =Y18+AB18 -> 337036 | AE18: 0 | AF18: 211 | AG18: =AC18+AF18 -> 337247 | AI18: 0 | AJ18: =14+'BALANCE DICIEMBRE'!J19 -> 426712 | AK18: =AG18+AJ18 -> 763959 | AM18: 0 | AN18: 999 | AO18: =AK18+AN18 -> 764958 | AQ18: 0 | AR18: =43+1722509 -> 1722552 | AS18: =AO18+AR18 -> 2487510
A19: 421095 | B19: intereses prestamos socios | E19: =+D19 -> 0 | H19: 0 | I19: =+G19+H19+E19 -> 0 | K19: 0 | L19: =I19+K19 -> 0 | M19: 0 | N19: 0 | O19: =+L19+N19 -> 0 | P19: 0 | Q19: 0 | R19: =+O19+Q19 -> 0 | S19: 0 | T19: 1067 | U19: =R19+T19 -> 1067 | W19: 0 | X19: 1597 | Y19: =U19+X19 -> 2664 | AA19: 0 | AB19: 0 | AC19: =Y19+AB19 -> 2664 | AE19: 0 | AF19: 0 | AG19: =AC19+AF19 -> 2664 | AI19: 0 | AK19: =AG19+AJ19 -> 2664 | AM19: 0 | AN19: 0 | AO19: =AK19+AN19 -> 2664 | AQ19: 0 | AR19: 0 | AS19: =AO19+AR19 -> 2664
A20: 421040 | B20: Descuentos comerciales condicionados | I20: =+G20+H20+E20 -> 0 | L20: =I20+K20 -> 0 | O20: =+L20+N20 -> 0 | R20: =+O20+Q20 -> 0 | U20: =R20+T20 -> 0 | AB20: 0
A21: 4220 | B21: ARRENDAMIENTOS APARTAMENTOS | C21: 0 | D21: =D22 -> 0 | E21: =+D21 -> 0 | G21: 0 | H21: =+H22 -> 0 | I21: =+G21+H21+E21 -> 0 | J21: 0 | K21: =+K22 -> 0 | L21: =I21+K21 -> 0 | M21: 0 | N21: =N22 -> 0 | O21: =+L21+N21 -> 0 | P21: 0 | Q21: =+Q22 -> 0 | R21: =+O21+Q21 -> 0 | S21: 0 | T21: =+T22 -> 0 | U21: =R21+T21 -> 0 | W21: 0 | X21: =X22 -> 955998 | Y21: =U21+X21 -> 955998 | AA21: 0 | AB21: =AB22 -> 0 | AC21: =Y21+AB21 -> 955998 | AE21: 0 | AF21: =AF22 -> 11325160 | AG21: =AC21+AF21 -> 12281158 | AI21: 0 | AJ21: =AJ22 -> 0 | AK21: =AG21+AJ21 -> 12281158 | AM21: 0 | AN21: =AN22 -> 0 | AO21: =AK21+AN21 -> 12281158 | AQ21: 0 | AR21: =AR22 -> 0 | AS21: =AO21+AR21 -> 12281158
A22: 422010 | B22: Apartamentos Arrendados | C22: 0 | E22: =+D22 -> 0 | G22: 0 | I22: =+G22+H22+E22 -> 0 | J22: 0 | L22: =I22+K22 -> 0 | M22: 0 | O22: =+L22+N22 -> 0 | P22: 0 | R22: =+O22+Q22 -> 0 | S22: 0 | U22: =R22+T22 -> 0 | W22: 0 | X22: 955998 | Y22: =U22+X22 -> 955998 | AA22: 0 | AC22: =Y22+AB22 -> 955998 | AE22: 0 | AF22: 11325160 | AG22: =AC22+AF22 -> 12281158 | AI22: 0 | AK22: =AG22+AJ22 -> 12281158 | AM22: 0 | AO22: =AK22+AN22 -> 12281158 | AQ22: 0 | AS22: =AO22+AR22 -> 12281158
I23: =+G23+H23+E23 -> 0 | L23: =I23+K23 -> 0 | O23: =+L23+N23 -> 0 | R23: =+O23+Q23 -> 0 | U23: =R23+T23 -> 0
A24: 4235 | B24: Servicios | C24: 0 | D24: =D25 -> 3153950 | E24: =+D24 -> 3153950 | G24: 0 | H24: =H25 -> 8170020 | I24: =+G24+H24+E24 -> 11323970 | J24: 0 | K24: =K25 -> 15848960 | L24: =I24+K24 -> 27172930 | M24: 0 | N24: =N25 -> 8045930 | O24: =+L24+N24 -> 35218860 | P24: 0 | Q24: =+Q25 -> 13859640 | R24: =+O24+Q24 -> 49078500 | S24: 0 | T24: =T25 -> 7976260 | U24: =R24+T24 -> 57054760 | W24: 0 | X24: =X25 -> 8055740 | Y24: =U24+X24 -> 65110500 | AA24: 0 | AB24: =AB25 -> 18562760 | AC24: =Y24+AB24 -> 83673260 | AE24: 0 | AF24: =AF25 -> 0 | AG24: =AC24+AF24 -> 83673260 | AI24: 0 | AJ24: =AJ25 -> 12090934 | AK24: =AG24+AJ24 -> 95764194 | AM24: 0 | AN24: =AN25 -> 9653900 | AO24: =AK24+AN24 -> 105418094 | AQ24: 0 | AR24: =AR25 -> 8060128 | AS24: =AO24+AR24 -> 113478222
A25: 423510 | B25: VENTAS SIN IVA | C25: 0 | D25: 3153950 | E25: =+D25 -> 3153950 | G25: 0 | H25: 8170020 | I25: =+G25+H25+E25 -> 11323970 | J25: 0 | K25: 15848960 | L25: =I25+K25 -> 27172930 | N25: 8045930 | O25: =+L25+N25 -> 35218860 | Q25: 13859640 | R25: =+O25+Q25 -> 49078500 | S25: 0 | T25: 7976260 | U25: =R25+T25 -> 57054760 | W25: 0 | X25: 8055740 | Y25: =U25+X25 -> 65110500 | AA25: 0 | AB25: 18562760 | AC25: =Y25+AB25 -> 83673260 | AE25: 0 | AG25: =AC25+AF25 -> 83673260 | AI25: 0 | AJ25: 12090934 | AK25: =AG25+AJ25 -> 95764194 | AM25: 0 | AN25: 9653900 | AO25: =AK25+AN25 -> 105418094 | AQ25: 0 | AR25: 8060128 | AS25: =AO25+AR25 -> 113478222
A26: 4295 | B26: DIVERSOS | C26: 0 | D26: =+D27 -> 0 | E26: =+D26 -> 0 | G26: 0 | H26: =+H27 -> 0 | I26: =+G26+H26+E26 -> 0 | J26: 0 | K26: =+K27 -> 0 | L26: =I26+K26 -> 0 | M26: =M27 -> 0 | N26: =+N27 -> 0 | O26: =+L26+N26 -> 0 | P26: =P27 -> 0 | Q26: =+Q27 -> 0 | R26: =+O26+Q26 -> 0 | S26: =S27 -> 0 | T26: =+T27 -> 0 | U26: =R26+T26 -> 0 | W26: =W27 -> 0 | Y26: =U26+X26 -> 0 | AA26: 0 | AB26: =+AB27 -> 706 | AC26: =Y26+AB26 -> 706 | AE26: 0 | AF26: =+AF27 -> 0 | AG26: =AC26+AF26 -> 706 | AI26: 0 | AK26: =AG26+AJ26 -> 706 | AM26: 0 | AN26: =+AN27 -> 0 | AO26: =AK26+AN26 -> 706 | AQ26: 0 | AR26: =+AR27 -> 0 | AS26: =AO26+AR26 -> 706
A27: 429581 | B27: Ajuste al peso | C27: 0 | E27: =+D27 -> 0 | G27: 0 | I27: =+G27+H27+E27 -> 0 | J27: 0 | L27: =I27+K27 -> 0 | O27: =+L27+N27 -> 0 | R27: =+O27+Q27 -> 0 | U27: =R27+T27 -> 0 | Y27: =U27+X27 -> 0 | AA27: 0 | AB27: =36+670 -> 706 | AC27: =Y27+AB27 -> 706 | AE27: 0 | AG27: =AC27+AF27 -> 706 | AI27: 0 | AK27: =AG27+AJ27 -> 706 | AM27: 0 | AO27: =AK27+AN27 -> 706 | AQ27: 0 | AS27: =AO27+AR27 -> 706
I28: =+G28+H28+E28 -> 0 | L28: =I28+K28 -> 0
A29: 5 | B29: GASTOS | C29: =C30+C146+C124 -> 10157985 | D29: 0 | E29: =+C29 -> 10157985 | G29: =G30+G146+G124 -> 12636419 | H29: 0 | I29: =+G29+H29+E29 -> 22794404 | J29: =J30+J146+J124 -> 15699505 | K29: 0 | L29: =+I29+J29 -> 38493909 | M29: =M30+M146+M124 -> 13845188 | N29: 0 | O29: =+L29+M29 -> 52339097 | P29: =P30+P146+P124 -> 16159541 | Q29: 0 | R29: =+O29+P29 -> 68498638 | S29: =S30+S146+S124 -> 13183791 | T29: 0 | U29: =+R29+S29 -> 81682429 | W29: =W30+W146+W124 -> 13164418 | X29: 0 | Y29: =U29+W29 -> 94846847 | AA29: =AA30+AA146+AA124 -> 12998509 | AB29: 0 | AC29: =Y29+AA29 -> 107845356 | AE29: =AE30+AE146+AE124 -> 15385036 | AF29: 0 | AG29: =AC29+AE29 -> 123230392 | AI29: =AI30+AI146+AI124 -> 15449005 | AJ29: 0 | AK29: =AG29+AI29 -> 138679397 | AM29: =AM30+AM146+AM124 -> 16781585 | AN29: 0 | AO29: =AK29+AM29 -> 155460982 | AQ29: =AQ30+AQ146+AQ124 -> 13073986 | AR29: 0 | AS29: =AO29+AQ29 -> 168534968
A30: 51 | B30: Operacionales de administración | C30: =+C31+C47+C52+C58+C62+C65+C70+C82+C88+C95+C101+C109 -> 10021333 | D30: 0 | E30: =+C30 -> 10021333 | G30: =+G31+G47+G52+G58+G62+G65+G70+G82+G88+G95+G101+G109 -> 12566177 | H30: 0 | I30: =+G30+H30+E30 -> 22587510 | J30: =+J31+J47+J52+J58+J62+J65+J70+J82+J88+J95+J101+J109 -> 15435906 | K30: 0 | L30: =I30+J30 -> 38023416 | M30: =+M31+M47+M52+M58+M62+M65+M70+M82+M88+M95+M101+M109 -> 13681519 | N30: =N31+N47+N58+N52+N65+N70+N82+N88+N95+N109+N62+N101 -> 0 | O30: =+L30+M30 -> 51704935 | P30: =+P31+P47+P52+P58+P62+P65+P70+P82+P88+P95+P101+P109 -> 16015883 | Q30: =Q31+Q47+Q58+Q52+Q65+Q70+Q82+Q88+Q95+Q109+Q62+Q101 -> 0 | R30: =+O30+P30 -> 67720818 | S30: =+S31+S47+S52+S58+S62+S65+S70+S82+S88+S95+S101+S109 -> 13043546 | T30: 0 | U30: =+R30+S30 -> 80764364 | W30: =+W31+W47+W52+W58+W62+W65+W70+W82+W88+W95+W101+W109 -> 12988921 | X30: 0 | Y30: =U30+W30 -> 93753285 | AA30: =+AA31+AA47+AA52+AA58+AA62+AA65+AA70+AA82+AA88+AA95+AA101+AA109 -> 12780064 | AB30: 0 | AC30: =Y30+AA30 -> 106533349 | AE30: =+AE31+AE47+AE52+AE58+AE62+AE65+AE70+AE82+AE88+AE95+AE101+AE109 -> 15214228 | AF30: 0 | AG30: =AC30+AE30 -> 121747577 | AI30: =+AI31+AI47+AI52+AI58+AI62+AI65+AI70+AI82+AI88+AI95+AI101+AI109 -> 15297669 | AJ30: 0 | AK30: =AG30+AI30 -> 137045246 | AM30: =+AM31+AM47+AM52+AM58+AM62+AM65+AM70+AM82+AM88+AM95+AM101+AM109 -> 16601670 | AN30: 0 | AO30: =AK30+AM30 -> 153646916 | AQ30: =+AQ31+AQ47+AQ52+AQ58+AQ62+AQ65+AQ70+AQ82+AQ88+AQ95+AQ101+AQ109 -> 12860497 | AR30: 0 | AS30: =AO30+AQ30 -> 166507413
A31: 5105 | B31: Gastos de personal | C31: =C32+C33+C34+C35+C36+C37+C38+C39+C40+C41+C42+C43+C44+C45 -> 2236775 | D31: 0 | E31: =+C31 -> 2236775 | G31: =SUM(G32:G44) -> 7001974 | H31: 0 | I31: =+G31+H31+E31 -> 9238749 | J31: =SUM(J32:J44) -> 7235201 | K31: 0 | L31: =I31+J31 -> 16473950 | M31: =SUM(M32:M44) -> 6661974 | N31: 0 | O31: =+L31+M31 -> 23135924 | P31: =+P32+P33+P34+P35+P36+P37+P38+P39+P40+P41+P42+P43+P44+P45 -> 5433676 | Q31: 0 | R31: =+O31+P31 -> 28569600 | S31: =SUM(S32:S44) -> 5483676 | T31: 0 | U31: =+R31+S31 -> 34053276 | W31: =W32+W33+W34+W35+W36+W37+W38+W39+W40+W41+W42+W43+W44+W45 -> 6955221 | X31: 0 | Y31: =U31+W31 -> 41008497 | AA31: =AA32+AA33+AA34+AA35+AA36+AA37+AA38+AA39+AA40+AA41+AA42+AA43+AA44+AA45 -> 6656666 | AB31: 0 | AC31: =Y31+AA31 -> 47665163 | AE31: =SUM(AE32:AE44) -> 6540919 | AF31: 0 | AG31: =AC31+AE31 -> 54206082 | AI31: =SUM(AI32:AI45) -> 6766017 | AJ31: 0 | AK31: =AG31+AI31 -> 60972099 | AM31: =SUM(AM32:AM45) -> 6389516 | AN31: 0 | AO31: =AK31+AM31 -> 67361615 | AQ31: =SUM(AQ32:AQ45) -> 4551236 | AR31: 0 | AS31: =AO31+AQ31 -> 71912851
A32: 510506 | B32: Sueldos | C32: 1603500 | D32: 0 | E32: =+C32 -> 1603500 | G32: 4637000 | I32: =+G32+H32+E32 -> 6240500 | J32: 4637000 | L32: =I32+J32 -> 10877500 | M32: 4637000 | O32: =+L32+M32 -> 15514500 | P32: 3918750 | R32: =+O32+P32 -> 19433250 | S32: 3918750 | U32: =+R32+S32 -> 23352000 | W32: 4630500 | Y32: =U32+W32 -> 27982500 | AA32: 4630500 | AC32: =Y32+AA32 -> 32613000 | AE32: 4583050 | AG32: =AC32+AE32 -> 37196050 | AI32: 4535600 | AK32: =AG32+AI32 -> 41731650 | AM32: 4630500 | AO32: =AK32+AM32 -> 46362150 | AQ32: 3241350 | AS32: =AO32+AQ32 -> 49603500
A33: 510515 | B33: Horas extras | D33: 0 | E33: 0 | I33: =+G33+H33+E33 -> 0 | L33: =I33+J33 -> 0 | M33: 0 | O33: =+L33+M33 -> 0 | R33: =+O33+P33 -> 0 | U33: =+R33+S33 -> 0 | Y33: =U33+W33 -> 0 | AC33: =Y33+AA33 -> 0 | AE33: 0 | AG33: =AC33+AE33 -> 0 | AI33: 0 | AK33: =AG33+AI33 -> 0 | AM33: 0 | AO33: =AK33+AM33 -> 0 | AQ33: 0 | AS33: =AO33+AQ33 -> 0
A34: 510527 | B34: Auxilio de transporte | D34: 0 | E34: =+C34 -> 0 | G34: 200000 | I34: =+G34+H34+E34 -> 200000 | J34: 200000 | L34: =I34+J34 -> 400000 | M34: 200000 | O34: =+L34+M34 -> 600000 | P34: 100000 | R34: =+O34+P34 -> 700000 | S34: 100000 | U34: =+R34+S34 -> 800000 | W34: 200000 | Y34: =U34+W34 -> 1000000 | AA34: 200000 | AC34: =Y34+AA34 -> 1200000 | AE34: 193334 | AG34: =AC34+AE34 -> 1393334 | AI34: 186667 | AK34: =AG34+AI34 -> 1580001 | AM34: 106666 | AO34: =AK34+AM34 -> 1686667 | AQ34: 140000 | AS34: =AO34+AQ34 -> 1826667
A35: 510530 | B35: Cesantías | C35: 133572 | D35: 0 | E35: =+C35 -> 133572 | G35: 402922 | I35: =+G35+H35+E35 -> 536494 | J35: 402922 | L35: =I35+J35 -> 939416 | M35: 402922 | O35: =+L35+M35 -> 1342338 | P35: 334762 | R35: =+O35+P35 -> 1677100 | S35: 334762 | U35: =+R35+S35 -> 2011862 | W35: 402381 | Y35: =U35+W35 -> 2414243 | AA35: 402381 | AC35: =Y35+AA35 -> 2816624 | AE35: 397873 | AG35: =AC35+AE35 -> 3214497 | AI35: 393365 | AK35: =AG35+AI35 -> 3607862 | AM35: 393365 | AO35: =AK35+AM35 -> 4001227 | AQ35: 281666 | AS35: =AO35+AQ35 -> 4282893
A36: 510533 | B36: Intereses sobre cesantías | C36: 16029 | D36: 0 | E36: =+C36 -> 16029 | G36: 4029 | I36: =+G36+H36+E36 -> 20058 | J36: 4029 | L36: =I36+J36 -> 24087 | M36: 4029 | O36: =+L36+M36 -> 28116 | P36: 3347 | R36: =+O36+P36 -> 31463 | S36: 3347 | U36: =+R36+S36 -> 34810 | W36: 4023 | Y36: =U36+W36 -> 38833 | AA36: 4023 | AC36: =Y36+AA36 -> 42856 | AE36: 3978 | AG36: =AC36+AE36 -> 46834 | AI36: 3933 | AK36: =AG36+AI36 -> 50767 | AM36: 3933 | AO36: =AK36+AM36 -> 54700 | AQ36: 33800 | AS36: =AO36+AQ36 -> 88500
A37: 510536 | B37: Prima de servicios | C37: 133572 | D37: 0 | E37: =+C37 -> 133572 | G37: 402922 | I37: =+G37+H37+E37 -> 536494 | J37: 402922 | L37: =I37+J37 -> 939416 | M37: 402922 | O37: =+L37+M37 -> 1342338 | P37: 334762 | R37: =+O37+P37 -> 1677100 | S37: 334762 | U37: =+R37+S37 -> 2011862 | W37: 402381 | Y37: =U37+W37 -> 2414243 | AA37: 402381 | AC37: =Y37+AA37 -> 2816624 | AE37: 397873 | AG37: =AC37+AE37 -> 3214497 | AI37: 393365 | AK37: =AG37+AI37 -> 3607862 | AM37: 393365 | AO37: =AK37+AM37 -> 4001227 | AQ37: 281666 | AS37: =AO37+AQ37 -> 4282893
A38: 510539 | B38: Vacaciones | C38: 66866 | D38: 0 | E38: =+C38 -> 66866 | G38: 193363 | I38: =+G38+H38+E38 -> 260229 | J38: 193363 | L38: =I38+J38 -> 453592 | M38: 193363 | O38: =+L38+M38 -> 646955 | P38: 163412 | R38: =+O38+P38 -> 810367 | S38: 163412 | U38: =+R38+S38 -> 973779 | W38: 193092 | Y38: =U38+W38 -> 1166871 | AA38: 193092 | AC38: =Y38+AA38 -> 1359963 | AE38: 191113 | AG38: =AC38+AE38 -> 1551076 | AI38: 189135 | AK38: =AG38+AI38 -> 1740211 | AM38: 189135 | AO38: =AK38+AM38 -> 1929346 | AQ38: 135164 | AS38: =AO38+AQ38 -> 2064510
A39: 510548 | B39: Bonificaciones | D39: 0 | E39: =+C39 -> 0 | H39: 0 | I39: =+G39+H39+E39 -> 0 | L39: =I39+J39 -> 0 | O39: =+L39+M39 -> 0 | R39: =+O39+P39 -> 0 | S39: =+P39+Q39 -> 0 | U39: =+R39+S39 -> 0 | W39: 160000 | Y39: =U39+W39 -> 160000 | AA39: 150000 | AC39: =Y39+AA39 -> 310000 | AE39: 150000 | AG39: =AC39+AE39 -> 460000 | AI39: 300000 | AK39: =AG39+AI39 -> 760000 | AO39: =AK39+AM39 -> 760000 | AS39: =AO39+AQ39 -> 760000
A40: 510551 | B40: Dotación y elementos seguridad trabajadores | C40: 10000 | D40: 0 | E40: =+C40 -> 10000 | G40: 355000 | H40: 0 | I40: =+G40+H40+E40 -> 365000 | J40: 588227 | L40: =I40+J40 -> 953227 | M40: 15000 | O40: =+L40+M40 -> 968227 | R40: =+O40+P40 -> 968227 | S40: 50000 | U40: =+R40+S40 -> 1018227 | W40: 352000 | Y40: =U40+W40 -> 1370227 | AA40: 63445 | AC40: =Y40+AA40 -> 1433672 | AE40: 15000 | AG40: =AC40+AE40 -> 1448672 | AI40: 140000 | AK40: =AG40+AI40 -> 1588672 | AO40: =AK40+AM40 -> 1588672 | AQ40: 10000 | AS40: =AO40+AQ40 -> 1598672
...

Sheet GRAFICAS PYG
B5: MES | C5: VENTAS FISCALES 2025 | D5: VENTAS FISCALES 2024 | E5: VENTAS FISCALES 2023 | F5: VENTAS FISCALES 2022 | G5: VENTAS FISCALES 2021 | H5: VENTAS FISCALES 2020 | I5: VENTAS SIN IVA 2025 | J5: VENTAS SIN IVA 2024 | K5: VENTAS SIN IVA 2023 | L5: VENTAS SIN IVA 2022 | M5: VENTAS SIN IVA 2021 | N5: VENTAS SIN IVA 2020 | O5: GASTOS 2025 | P5: GASTOS 2024 | Q5: GASTOS 2023 | R5: GASTOS 2022 | S5: GASTOS 2021 | T5: GASTOS 2020 | U5: UTILIDAD 2025 | V5: UTILIDAD 2024 | W5: UTILIDAD 2023 | X5: UTILIDAD 2022 | Y5: UTILIDAD 2021 | Z5: UTILIDAD 2020
B6: ENERO | C6: =+[1]pyg2025!D9 -> 496100 | D6: 2319055 | E6: 0 | F6: 6308768 | G6: 4088450 | H6: 9772741 | I6: =+[2]pyg2025!D16 -> 3154060 | J6: 5070435 | K6: 4878660 | L6: 3100823 | M6: 5295548 | N6: 4656136 | O6: =+'pyg2025'!C166 -> 10157985 | P6: 9947041 | Q6: 10152266 | R6: 8340075.4 | S6: 9031235 | T6: 11183760 | U6: =+C6+I6-O6 -> -6507825 | V6: =+D6+J6-P6 -> -2557551 | W6: -5273606 | X6: -1150802.4 | Y6: 352800 | Z6: 3245117
B7: FEBRERO | C7: =+[1]pyg2025!H9 -> 24370 | D7: 2198885 | E7: 4332104 | F7: 3904163 | G7: 3444630 | H7: 8662267 | I7: =+[2]pyg2025!H16 -> 8170074 | J7: 6521782 | K7: 4693673 | L7: 7094524 | M7: 6881543 | N7: 7804429 | O7: =+'pyg2025'!G166 -> 12636419 | P7: 13136716 | Q7: 13410419 | R7: 9969598 | S7: 12420337 | T7: 13337610 | U7: =+C7+I7-O7 -> -4441975 | V7: =+D7+J7-P7 -> -4416049 | W7: -4384642 | X7: 569556 | Y7: -2094164 | Z7: 3129086
B8: MARZO | C8: =+[1]pyg2025!K9 -> 100949 | D8: 5345924 | E8: 11179580 | F8: 6104727 | G8: 4294490 | H8: 11213082 | I8: 15848964 | J8: 6934538 | K8: 12062967 | L8: 11156171 | M8: 7901560 | N8: 5900305 | O8: =+'pyg2025'!J166 -> 15699505 | P8: 11222288 | Q8: 16907266 | R8: 11403558 | S8: 13591375 | T8: 10865138 | U8: =+C8+I8-O8 -> 250408 | V8: =+D8+J8-P8 -> 1058174.2 | W8: 6335281 | X8: 4047103 | Y8: -1395325 | Z8: 6248249
B9: ABRIL | C9: =+[1]pyg2025!N9 -> 55000 | D9: 5705085 | E9: 6476561 | F9: 4771392 | G9: 3094715 | H9: 109000 | I9: 8045964 | J9: 11902051 | K9: 13101458 | L9: 11179990 | M9: 10475785 | N9: 121014 | O9: =+'pyg2025'!M166 -> 13845188 | P9: 13880419 | Q9: 12557124 | R9: 11689725 | S9: 17060981 | T9: 8424882 | U9: =+C9+I9-O9 -> -5744224 | V9: =+D9+J9-P9 -> 3726717 | W9: 7020895 | X9: 2584980 | Y9: -3490481 | Z9: -8194868
B10: MAYO | C10: 4552322 | D10: 6312190 | E10: 2948466 | F10: 3195437 | G10: 3036250 | H10: 0 | I10: 13860164 | J10: 5781805 | K10: 11011958 | L10: 9141636 | M10: 9475619 | N10: 1804105 | O10: =+'pyg2025'!P165 -> 16159541 | P10: 12971414 | Q10: 15171959 | R10: 11286631 | S10: 11744517 | T10: 10909925 | U10: =+C10+I10-O10 -> 2252945 | V10: =+D10+J10-P10 -> -877419 | W10: -1211535 | X10: 891255 | Y10: 767352.37 | Z10: -9105820
B11: JUNIO | C11: 4248410 | D11: 5308821 | E11: 5460313 | F11: 3587643 | G11: 3220640 | H11: 15088775 | I11: 7977361 | J11: 3102603 | K11: 9771991 | L11: 6890613 | M11: 14072478 | N11: 5883300 | O11: =+'pyg2025'!S165 -> 13183791 | P11: 10918657 | Q11: 10729339 | R11: 12304971 | S11: 12797380 | T11: 12990071 | U11: =+C11+I11-O11 -> -958020 | V11: =+D11+J11-P11 -> -2507233 | W11: 4502965 | X11: -2193718 | Y11: 4495738 | Z11: 7982004
B12: JULIO | C12: 5508975 | D12: 1368000 | E12: 5032261 | F12: 5002298 | G12: 2982171 | H12: 5107405 | I12: 9013371 | J12: 4934884 | K12: 5870486 | L12: 8564817 | M12: 7847354 | N12: 9069381 | O12: =+'pyg2025'!W166 -> 13164418 | P12: 11152404 | Q12: 10792468 | R12: 12624706 | S12: 13357892 | T12: 11530572 | U12: =+C12+I12-O12 -> 1357928 | V12: =+D12+J12-P12 -> -4849520 | W12: 110279 | X12: -1077718 | Y12: -2527014 | Z12: 2646214
B13: AGOSTO | C13: 1143000 | D13: 1818800 | E13: 7904377 | F13: 6292782 | G13: 2259634 | H13: 4348355 | I13: 18563466 | J13: 13355048 | K13: 7730780 | L13: 12002561 | M13: 10482068 | N13: 6862717 | O13: =+'pyg2025'!AA166 -> 12998509 | P13: 11530628 | Q13: 10381456 | R13: 0 | S13: 12441445 | T13: 11013798 | U13: =+C13+I13-O13 -> 6707957 | V13: =+D13+J13-P13 -> 3643220 | W13: 5253701 | X13: 14262195 | Y13: 299710 | Z13: 197274
B14: SEPTIEMBRE | C14: =+'pyg2025'!AF8 -> 1275896 | D14: 2263580 | E14: 11362855 | F14: 9534674 | G14: 4199993 | H14: 5343486 | I14: =+'pyg2025'!AF16 -> 11325371 | J14: 12223256 | K14: 12500720 | L14: 8694467 | M14: 12769758 | N14: 9114471 | O14: =+'pyg2025'!AE29 -> 15385036 | P14: 14014468 | Q14: 14685440 | R14: 10423141 | S14: 14262071 | T14: 11098718 | U14: =+C14+I14-O14 -> -2783769 | V14: =+D14+J14-P14 -> 472368 | W14: 9178135 | X14: 2471319 | Y14: 2707680 | Z14: 3359239
B15: OCTUBRE | C15: =+'pyg2025'!AJ8 -> 914530 | D15: 3401625 | E15: 9491748 | F15: 8627180 | G15: 5953903 | H15: 5206920 | I15: =+'pyg2025'!AJ16 -> 12517646 | J15: 12732697 | K15: 7560400 | L15: 6596990 | M15: 11490263 | N15: 11912110 | O15: =+'pyg2025'!AI29 -> 15449005 | P15: 14110605 | Q15: 22974686 | R15: 10630364 | S15: 11384483 | T15: 14559398 | U15: =+C15+I15-O15 -> -2016829 | V15: =+D15+J15-P15 -> 2023717 | W15: -5922538 | X15: 1920529 | Y15: 6059683 | Z15: 2559631.8
B16: NOVIEMBRE | C16: =+'pyg2025'!AN8 -> 1555310 | D16: 2974890 | E16: 6387715 | F16: 9834611 | G16: 3450527 | H16: 4539945 | I16: =+'pyg2025'!AN16 -> 9654899 | J16: 10221753 | K16: 7355430 | L16: 10351450 | M16: 13482352 | N16: 9403633 | O16: =+'pyg2025'!AM29 -> 16781585 | P16: 12084858 | Q16: 13205069 | R16: 13793441 | S16: 9460840 | T16: 15548745 | U16: =+C16+I16-O16 -> -5571376 | V16: =+D16+J16-P16 -> 1111784.9 | W16: 538076 | X16: 8536 | Y16: 7472128 | Z16: -1605167
B17: DICIEMBRE | C17: =+'pyg2025'!AR8-'pyg2025'!AQ7 -> 14214215 | D17: 3456110 | E17: 8960923 | F17: 6687564 | G17: 3437926 | H17: 5671900 | I17: =+'pyg2025'!AR16 -> 9782680 | J17: 10979454 | K17: 8377765 | L17: 10009636 | M17: 8072834 | N17: 11129725 | O17: =+'pyg2025'!AQ29 -> 13073986 | P17: 14343828 | Q17: 19716602 | R17: 14685347 | S17: 10271878 | T17: 12796951 | U17: =+C17+I17-O17 -> 10922909 | V17: =+D17+J17-P17 -> 91736 | W17: -2377914 | X17: -1237785 | Y17: 1238971 | Z17: 4004674
B19: TOTAL | C19: =SUM(C6:C18) -> 34089077 | D19: =SUM(D6:D18) -> 42472965 | E19: =SUM(E6:E18) -> 79536903 | F19: =SUM(F6:F18) -> 73851239 | G19: =SUM(G6:G18) -> 43463329 | H19: =SUM(H6:H18) -> 75063876 | I19: =SUM(I6:I18) -> 127914020 | J19: =SUM(J6:J18) -> 103760306 | ... Z19: =SUM(Z6:Z18) -> 14465634
B44: MES | C44: VENTAS FISCALES 2025 | D44: VENTAS FISCALES 2024 | E44: VENTAS FISCALES 2023 | F44: VENTAS FISCALES 2022 | G44: VENTAS FISCALES 2021 | H44: VENTAS FISCALES 2020
B45: ENERO | C45: 496100 | D45: 2319055 | E45: 0 | F45: 6308768 | G45: 4088450 | H45: 9772741
B46: FEBRERO | C46: 24370 | D46: 2198885 | E46: 4332104 | F46: 3904163 | G46: 3444630 | H46: 8662267
B47: MARZO | C47: 100949 | D47: 5345924 | E47: 11179580 | F47: 6104727 | G47: 4294490 | H47: 11213082
B48: ABRIL | C48: 55000 | D48: 5705085 | E48: 6476561 | F48: 4771392 | G48: 3094715 | H48: 109000
B49: MAYO | C49: 4552322 | D49: 6312190 | E49: 2948466 | F49: 3195437 | G49: 3036250 | H49: 0
B50: JUNIO | C50: 4248410 | D50: 5308821 | E50: 5460313 | F50: 3587643 | G50: 3220640 | H50: 15088775
B51: JULIO | C51: 5508975 | D51: 1368000 | E51: 5032261 | F51: 5002298 | G51: 2982171 | H51: 5107405
B52: AGOSTO | C52: 1143000 | D52: 1818800 | E52: 7904377 | F52: 6292782 | G52: 2259634 | H52: 4348355
B53: SEPTIEMBRE | C53: 1275896 | D53: 2263580 | E53: 11362855 | F53: 9534674 | G53: 4199993 | H53: 5343486
B54: OCTUBRE | C54: 914530 | D54: 3401625 | E54: 9491748 | F54: 8627180 | G54: 5953903 | H54: 5206920
B55: NOVIEMBRE | C55: 1555310 | D55: 2974890 | E55: 6387715 | F55: 9834611 | G55: 3450527 | H55: 4539945
B56: DICIEMBRE | C56: 14214215 | D56: 3456110 | E56: 8960923 | F56: 6687564 | G56: 3437926 | H56: 5671900
B57: TOTAL | C57: =SUM(C45:C56) -> 34089077 | D57: =SUM(D45:D56) -> 42472965 | E57: =SUM(E45:E56) -> 79536903 | F57: =SUM(F45:F56) -> 73851239 | G57: =SUM(G45:G56) -> 43463329 | H57: =SUM(H45:H56) -> 75063876
B64: MES | C64: VENTAS SIN IVA 2025 | D64: VENTAS SIN IVA 2024 | E64: VENTAS SIN IVA 2023 | F64: VENTAS SIN IVA 2022 | G64: VENTAS SIN IVA 2021 | H64: VENTAS SIN IVA 2020
B65: ENERO | C65: 3154060 | D65: 5070435 | E65: 4878660 | F65: 3100823 | G65: 5295548 | H65: 4656136
B66: FEBRERO | C66: 8170074 | D66: 6521782 | E66: 4693673 | F66: 7094524 | G66: 6881543 | H66: 7804429
B67: MARZO | C67: 15848964 | D67: 6934538 | E67: 12062967 | F67: 11156171 | G67: 7901560 | H67: 5900305
B68: ABRIL | C68: 8045964 | D68: 11902051 | E68: 13101458 | F68: 11179990 | G68: 10475785 | H68: 121014
B69: MAYO | C69: 13860164 | D69: 5781805 | E69: 11011958 | F69: 9141636 | G69: 9475619 | H69: 1804105
B70: JUNIO | C70: 7977361 | D70: 3102603 | E70: 9771991 | F70: 6890613 | G70: 14072478 | H70: 5883300
B71: JULIO | C71: 9013371 | D71: 4934884 | E71: 5870486 | F71: 8564817 | G71: 7847354 | H71: 9069381
B72: AGOSTO | C72: 18563466 | D72: 13355048 | E72: 7730780 | F72: 12002561 | G72: 10482068 | H72: 6862717
B73: SEPTIEMBRE | C73: 11325371 | D73: 12223256 | E73: 12500720 | F73: 8694467 | G73: 12769758 | H73: 9114471
B74: OCTUBRE | C74: 12517646 | D74: 12732697 | E74: 7560400 | F74: 6596990 | G74: 11490263 | H74: 11912110
B75: NOVIEMBRE | C75: 9654899 | D75: 10221753 | E75: 7355430 | F75: 10351450 | G75: 13482352 | H75: 9403633
...

Sheet CARTERA
C4: CARTERA NO FISCAL
C5: NILSON RUEDA | D5: 0
C6: PABLO JAIMES | D6: 0
C7: MAURICIO | D7: 0
C8: JUAN PABLO SARMIENTO | D8: 0
C9: CARLOS RIVERA | D9: 0
C10: GERARDO CONTRERAS | D10: 0
C11: REYNALDO ARDILA | D11: 0
C12: EDWIN
C13: polymis | D13: 30240
C17: TOTAL | D17: =SUM(D5:D16) -> 30240
C20: CARTERA FISCAL
C21: geison amaya | D21: 60000
C22: geison amaya | D22: =1663620-309019-9282 -> 1345319
C23: copower | D23: 40000 | E23: enr27
C24: copower | D24: 1572704 | E24: enr27
C25: nestor lopez | D25: 2408560
C28: TOTAL | D28: =SUM(D21:D25) -> 5426583

Sheet ANTICIPOS
D3: PUERTA DE ORO
D6: |
C8: 1 | D8: JUNIO | E8: 5087939
C9: 2 | D9: JULIO | E9: 1526381
C10: 3 | D10: AGOSTO | E10: 1526381
C11: 4 | D11: SEPT | E11: 1526381
C12: 5 | D12: OCTUBRE | E12: 1526381
C13: 6 | D13: NOVIEMBRE | E13: 1526381
C14: 7 | D14: DIC | E14: 1526381
C15: 8 | D15: ENERO | E15: 1526381
C16: 9 | D16: FEBRERO | E16: 1526381
C17: 10 | D17: MARZO | E17: 1526381
C18: 11 | D18: ABRIL | E18: 1526381
C19: 12 | D19: MAYO | E19: 1526381
... C26: 19 | D26: DIC | E26: 1526381
C27: 20 | D27: 45292 | E27: 1526381
C28: 21 | D28: 45323 | E28: 1526381
C29: 22 | D29: 45352 | E29: 1526381
C30: 23 | D30: 45383 | E30: 1526381
C31: 24 | D31: 45413 | E31: 1526381
C32: 25 | D32: 45444 | E32: 1526381
C33: 26 | D33: 45474 | E33: 1526381
C34: 27 | D34: 45505 | E34: 1526381
C35: 28 | D35: 45536 | E35: 1526381
C36: 29 | D36: 45566 | E36: 1526381
C37: 30 | D37: 45597 | E37: 1526381
C38: 31 | D38: 45627 | E38: 1526382
D40: TOTAL | E40: =SUM(E8:E39) -> 50879370

Sheet CUENTAS CDTS
A3: CDT BBVA 19/12/2025 | B3: 88137296
A4: CDT COMULTRASAN20/02/2025 | B4: 7810240
A5: CDT COOMULTRASAN 18/07/2025 | B5: 22764198
A10: VENTA ZION CDT | B10: 89642300
A11: MENOS OPERACIÓN | B11: 4857700
A12: TOTAL | B12: =+B10-B11 -> 84784600
A13: CDT 1 | B13: 7810240 | C13: NOTA ESTA INCLUIDO LOS INTERESES $ 336,240
A14: CDT 2 | B14: 22764198 | C14: NOTA ESTA INCLUIDO LOS INTERESES $ 426707
A15: TOTAL | B15: =SUM(B12:B14) -> 115359038 | C15: SALDO AGOSTO 31
A17: CDT 1 | B17: 7810240 | K17: VENTA ZION CDT | L17: 89642300
A18: CDT 2 | B18: 22764198 | K18: MENOS OPERACIÓN | L18: 4857700
A19: CDT 3 | B19: 88137296 | C19: NOTA : $ 89642300 MENOS ($4,857,700) MAS INTERESES $ 1722509 + SALDO $1,630,187 | K19: INTERESES SEPT A DIC | L19: 1722509
A20: TOTAL | B20: =SUM(B17:B19) -> 118711734 | K20: SALDO PEND JIMMY | L20: 1630187
L21: =+L17-L18+L19+L20 -> 88137296

Sheet ZION 
C4: DISTRIBUCION GASTOS ZION
C6: Valor Venta | D6: 170000000
C7: Comision Yamile | D7: 5100000
C8: Gastos paz y salvos Yamile | D8: 150000
C9: Boleta fiscal y registro | D9: 1342550
C10: Derechos notariales | D10: 421173
C12: Subtotal | D12: =+D6-D7-D8-D9-D10-277 -> 162986000
C13: Consignado en Equioriente | D13: 94500000 | E13: SE DESCUENTA SALDO PENDIENTE DE EQUIORIENTE | H13: =+D19-H26 -> 84784600 | I13: NUEVO CDT
C14: Efectivo | D14: =+D12-D13 -> 68486000
C16: Heidy | D16: =+D12*E16 -> 24447900 | E16: 0.15
C17: Jhon | D17: =+D12*E17 -> 24447900 | E17: 0.15
C18: Jimmy | D18: =+D12*E18 -> 24447900 | E18: 0.15
C19: Madre | D19: =+D12*E19 -> 89642300 | E19: 0.55 | F19: 4587800 | G19: =D19+F19 -> 94230100
D20: =SUM(D16:D19) -> 162986000
C22: Distribucion efectivo | G22: Saldo pendiente por Equioriente. | J22: zion
C23: Heidy | D23: =+D14/3 -> 22828667 | G23: Heidy | H23: =+D16-D23 -> 1619233.3 | I23: 0.15 | J23: 120000 | K23: =H23+J23 -> 1739233.3 | L23: se cruczo con cuenta davivienda
C24: Jhon | D24: =+D14/3 -> 22828667 | G24: Jhon | H24: =+D17-D24 -> 1619233.3 | I24: 0.15
C25: Jimmy | D25: =+D14/3 -> 22828667 | G25: Jimmy | H25: =+D18-D25 -> 1619233.3 | I25: 0.15
C26: TOTAL EFECTIVO | D26: =SUM(D23:D25) -> 68486000 | H26: =SUM(H23:H25) -> 4857700
F28: PUERTA DE ORO | G28: =D19-H26 -> 84784600 | H28: =D19-G28 -> 4857700
F29: CDT1 JULIO 18 | G29: 22337500
F30: CDT2 FEBRERO 20 | G30: 7474000
G31: =SUM(G28:G30) -> 114596100 | H31: 118718586 | I31: =+G31-H31 -> -4122486
C34: DE LO ENTREGADO EFECTIVO | G34: DE LO CONSIGNADO EQUIORIENTE
C35: TOTAL | D35: =+D14 -> 68486000 | G35: TOTAL | H35: 94500000
C36: SE ENTREGA DE LA SIGUIENTE MANERA
C38: Distribucion efectivo
C39: Heidy | D39: 22828667 | E39: 0.3333
C40: Jhon | D40: 22828667 | E40: 0.3333
C41: Jimmy | D41: 22828667 | E41: 0.3334

Sheet AUTO RRETENCIONES
A3: AUTORRETENCION
A4: ENERO | B4: 3456000 | C4: 38000
A5: FEBRERO | B5: 0 | C5: 0
A6: MARZO | B6: 125000 | C6: 1000
A7: ABRIL | B7: 55000 | C7: 1000
A8: MAYO | B8: 8801000 | C8: 97000
A9: JUNIO | B9: 4248000 | C9: 47000
A10: JULIO | B10: 5509000 | C10: 61000
A11: AGOSTO | B11: 1143000 | C11: 13000
A12: SEPTIEMBRE | B12: 1276000 | C12: 14000
A13: OCTUBRE | B13: 915000 | C13: 10000
A14: NOVIEMBRE | B14: 1555000 | C14: 17000
A15: DICIEMBRE | B15: 14214000 | C15: 156000
B16: =SUM(B4:B15) -> 41297000 | C16: =SUM(C4:C15) -> 455000

Sheet Hoja1
A1: Fecha documento | B1: Documento # | C1: Cuenta - Cód. | D1: Cuenta - Nombre de la cuenta NIIF | E1: Tercero - Cód. | F1: Tercero - Nombre-apellido | G1: CC imputado - Cód. | H1: Débito | I1: Crédito | J1: Saldo
A2: 45688 | B2: CI-000160 | C2: 13551504 | D2: Ret. por servicios en general | E2: 900133059 | F2: CUBYCO CONSTRUCTORES SA | H2: 17280 | I2: 0 | J2: 17280
A3: 45688 | B3: CI-000160 | C3: 13551504 | D3: Ret. por servicios en general | E3: 901765638 | F3: INVERSIONES G Y C23 S.A.S. | H3: 44031.9 | I3: 0 | J3: 44031.9
A4: 45688 | B4: CI-000160 | C4: 13551504 | D4: Ret. por servicios en general | E4: 901765638 | F4: INVERSIONES G Y C23 S.A.S. | H4: 2400 | I4: 0 | J4: 2400
A5: 45688 | B5: CI-000160 | C5: 13551504 | D5: Ret. por servicios en general | E5: 91540549 | F5: PERFOSANDER L | H5: 24960 | I5: 0 | J5: 24960
A6: 45688 | B6: CI-000160 | C6: 13551504 | D6: Ret. por servicios en general | E6: 91540549 | F6: PERFOSANDER L | H6: 1500 | I6: 0 | J6: 1500
A7: 45688 | B7: CI-000160 | C7: 13551504 | D7: Ret. por servicios en general | E7: 800029520 | F7: INVERSIONES ULLOA MONSALVE SAS | H7: 4992 | I7: 0 | J7: 4992
A8: 45688 | B8: CI-000160 | C8: 13551504 | D8: Ret. por servicios en general | E8: 800029520 | F8: INVERSIONES ULLOA MONSALVE SAS | H8: 250 | I8: 0 | J8: 250
A9: 45838 | B9: CI-000172 | C9: 13551504 | D9: Ret. por servicios en general | E9: 901906600 | F9: STERICARE PLUS SAS | H9: 23027 | I9: 0 | J9: 23027
A10: 45838 | B10: CI-000172 | C10: 13551504 | D10: Ret. por servicios en general | E10: 901906600 | F10: STERICARE PLUS SAS | H10: 1200 | I10: 0 | J10: 1200
A11: 45838 | B11: CI-000172 | C11: 13551504 | D11: Ret. por servicios en general | E11: 901906600 | F11: STERICARE PLUS SAS | H11: 59680 | I11: 0 | J11: 59680
A12: 45838 | B12: CI-000172 | C12: 13551504 | D12: Ret. por servicios en general | E12: 901906600 | F12: STERICARE PLUS SAS | H12: 1000 | I12: 0 | J12: 1000
A13: 45838 | B13: CI-000172 | C13: 13551504 | D13: Ret. por servicios en general | E13: 901906600 | F13: STERICARE PLUS SAS | H13: 8640 | I13: 0 | J13: 8640
... A19: 45900 | B19: NT-2508006 | C19: 13551503 | D19: Ret. por comisiones | E19: 900206797 | F19: INMOBILIARIA E INGENIERIA AJC LTDA | H19: 10096 | I19: 0 | J19: 10096
H20: =SUM(H2:H19) -> 570036.4

Sheet Hoja4
