Workbook

Sheet ENERO
B1: INGRESOS
B2: ENERO 1 AL 31 2026
B3: SALDO EN CAJA: | C3: 0
A4: FECHA | B4: DETALLE | C4: VALOR
A5: 46029 | B5: ADRIAN BRAVO | C5: 400000
B6: RONALD COLORADOS COLORADOS | C6: 208000
B7: TABLON | C7: 5000
B8: HERNAN TORRADO CANCELADO A ENERO 18 2025 | C8: 111500
B9: ABONO ALQUILER COLUMNAS YURANIS PABLON | C9: 400000 | D9: nequi
A10: 46036 | B10: ABONO ALQUILER ENERO 2026 CLAUDIA JEREZ | C10: 104250
B11: ABONOI MAESTRO GREGORIO ALQUILER ANDAMIOS 20 DIAS ENERO 14 A FEBRERO 3 | C11: 200000
B12: DEPOSITO PLACA RONALD | C12: 400000 | D12: NEQUI
A13: 46037 | B13: MAESTRO ROGELIO A ENERO 8 2025 | C13: 957000
B14: RETIRO NEQUI | C14: 300000 | D14: NEQUI
A15: 46039 | B15: SOPORTE ALQUILER POLEAS A PARTIR 20 ENERO 2026 | C15: 800000 | D15: BANCOLOMBIA
A16: 46041 | B16: PAGO YURANIS ALQUILER PLACA ENERO 20 A FEBRERO 3 | C16: 2745000 | D16: BBVA
B17: DEPOSITO JOSE HERNAN PARADA | C17: 72000 | D17: BANCOLOMBIA | E17: CUADRADO HASTA AQUÍ | F17: 200000
A18: 46042 | B18: DEPOSITOKETHERIN PALACIOS | C18: 200000 | D18: NEQUI
A19: 46043 | B19: ALQUILER DIEGO GUTIERREZ SALIDA 13282 A PARTIR 17 ENERO | C19: 300000
B20: MARICEL ABONO | C20: 50000
B21: ESCALERA CECILIA INFANTE | C21: 30000
A22: 46044 | B22: ADBONO YURANIS MATERIAL ADICICONAL | C22: 264500 | D22: BBVA
B23: HERNAN TORRADO ENERO 19 AL 25 | C23: 77000
A24: 46048 | B24: ALQUILER 26 ENERO A FEBRERO 6 DIEGO GUTIERREZ | C24: 330000
A25: 46049 | B25: ANDREA PAOLA ABONO A PLACA PRIMER PISO | C25: 1500000 | D25: BBVA JIMMY
A26: 46050 | B26: JUAN CARLOS BAUTISTA | C26: 84000
B27: ERNESTO ´PICOSN | C27: 36000
B28: DIEGO GUTIERREZ ENERO 27 AL 31 | C28: 6000
B29: ALQUILER ESCALERA GLASCOL POR 1 DIA | C29: 30000
B30: DIEGO GUTIERREZ ENERO 27 AL 31 | C30: 25760 | D30: NEQUI
A31: 46052 | B31: JORGE MANTILLA PAGO DE ALQUILER ENERO | C31: 170000 | D31: NEQUI
B32: POLIMYS ALQUILER DICIEMBRE | C32: 30240 | D32: BBVA JIMMY | E32: =1000000-630080 -> 369920 | F32: PENDIENTE FACTURAS
A33: 46053 | B33: PAGO ALQUILER LIBARDO REY A 2 FEBRERO 2026 | C33: 1000000
B34: PAGO ALQUILER FORMALETA MAESTRO ROGELIO A ENERO 23 2026 | C34: 909000
B35: CESAR AUGUSTO CACERES ABONO A ALQUILER | C35: 200000 | D35: NEQUI
C36: =SUM(C5:C35) -> 11945250
A38: EGRESOS
A39: FECHA | B39: ENERO 1 AL 31 2026
B40: DETALLE | C40: VALOR
A41: 46031 | B41: DIEGO ROJAS ENERO 7 AL 9 2026 | C41: 217500
...

Sheet FEBRERO
B1: INGRESOS
B2: FEBRERO 1 AL 28/ 2026
B3: SALDO EN CAJA: | C3: =ENERO!C112 -> -2874733
A4: FECHA | B4: DETALLE | C4: VALOR
A5: 46055 | B5: ANIBAL MEZA ALQUILERT AL 2 DEFBRERO | C5: 133000
B6: ABONO ENERO CLAUDIA GIL | C6: 300000 | D6: NEQUI
A7: 46057 | B7: ABONO ANTONIO GUTIERREZ | C7: 300000
B8: MARICEL | C8: 100000
A9: 46059 | B9: HERNAN TORRADO A FEBRERO 8 | C9: 196000
B10: ALQUILER ENERO ADRIAN BRAVO A FEBRERO 3 2026 | C10: 487840 | D10: NEQUI
B11: ABONO FEBRERO YURANIS PLACA | C11: 3403450 | D11: BBVA JIMMY
B12: OSWALDO GALVIS BOTERO ALQUIER 10 PARALES POR 8 DIAS FEBRERO | C12: 90000
A13: 46062 | B13: MARICEL | C13: 90000
B14: ALQUILER ANDAMIOS JORG E DIAZ FEBRERO | C14: 65000
B15: ABONO CUENTA ENERO25 A FEBRERO 9 2026 YURANIS | C15: 1500000
A16: 46065 | B16: ABONO ANDREA paola | C16: 1000000 | D16: BBVA JIMMY
B17: ENERO 2026 ALQUIOBRADS | C17: 253600 | D17: nequi
B18: ABONO ALQUILER JORGE | C18: 1000000
A19: 46066 | B19: SEMANA FEBRERO 9 AL 15 HERNAN TORRADO | C19: 91000
B20: Sacados de nequi | C20: 148000
B21: Diego Gutierrez abono ssalidas hasta FEBRERO 15 | C21: 402000
B22: ABONODIEGO GUTIERREZ SALIDA 13337 A PARTIR DEL 11 FEBRERO | C22: 100000
A23: 46067 | B23: ABONO ANDRREA CONKASA | C23: 500000 | D23: BBVA JIMMY
A24: 46069 | B24: ALQUILER SILVIA GOMEZ ENERO 31 A FEBRERO 15 | C24: 1500000
B25: ESCALERA ERACLITO 1 DIA | C25: 30000
B26: FEBRERO 6 AL 13 ANTONIO GUTIERREZ | C26: 200000
B27: CESAR CACERES FEBRERO 6 AL 14 | C27: 353000
A28: 46070 | B28: PAGO DIEGO GUTIERREZ SALDO SALIDA 133732 A PARTIR FEBRERO 11 | C28: 250000 | D28: NEQUI
A29: 46074 | B29: ABONO ALBA GARCIA | C29: 500000 | D29: NEQUI
A30: 46078 | B30: ALQUILER EDUARDO ARIZAFEBRERO SECCIONES ANDAMIO Y TABLONES | C30: 280000
B31: TRANSPORTE EDUARDO ARIZAFEBRERO SECCIONES ANDAMIO Y TABLONES | C31: 20000
B32: ALQUILER COLUMNAS A PARTIR DEL 26 LUIS SANCHEZ Cabecera | C32: 114500 | D32: NEQUI
B33: JUAN PABLO SARMIENTO ALQUYILER ANDAMIOS FEBRERO 2026 | C33: 300000
A34: 46080 | B34: ABONO ENERO CLAUDIA GIL | C34: 700000 | D34: NEQUI
B35: ABONO JORGE ALEXANDER | C35: 1200000
B36: HERNAN TORRADO FEBRERO 23 A MARZO 1 | C36: 100000
B37: PAGO ALQUILER 5 COLUMNAS DUBAN ORTEGA A PARTIR 2 DE MARZO | C37: 263200 | D37: NEQUI
B38: NELSON BERNAL ALQUILER | C38: 81500
A39: 46081 | B39: CESAR CACERES | C39: 12000
B40: SALDO YURANIS FEBRERO | C40: 101000 | D40: BBVA JIMMY
...

Sheet MARZO
B1: INGRESOS
B2: MARZO 1 AL 31/ 2026
C3: =FEBRERO!C117 -> 64040
C4: VALOR
A5: 46085 | B5: PAGO DE POLIMYS A AEO CUENTA ENERO 2026 | C5: 190350
B6: PAGO POLIMYS A AEO CUENTA FEBRERO | C6: 60180
B7: ABONO ALQUILER HERNAN TORRADO A MARZO 3 | C7: 1300000
B8: ALQUILER COLUMNAS MARZO 4 AL 8 LUDWING | C8: 600000 | D8: NEQUI
B9: PAGO ANDRERA CONKASA A MARZO 1 | C9: 1926830 | D9: BBVA
B10: PAGO HERNAN TORRADO MARZO 2026 | C10: 600000
B11: ALQUILER ESCALERA 4M A 8M | C11: 80000
B12: BERNABE ALQUILER PARALES 24 FEBRERO A MARZO 6 2026 | C12: 65000
B13: RETIRO BBVA | C13: 500000 | D13: RETIRO BBVA
B14: PEDRO ROSAS MARZO 2 AL 10 | C14: 1206000
B15: FELIZ CARRILLO | C15: 28000
A16: 46088 | B16: ALQUILER EMILIANO OLIVEROS | C16: 50000 | D16: nequi
B17: ABONO ALQUILER LUIS SANCHEZ MARZO 2026 | C17: 339000 | D17: NEQUI
B18: LUIS ANTONIO CACERES | C18: 647400 | D18: BBVA JIMMY
A19: 46092 | B19: FEBRERO 27 A MARZO 11 YEISON BARBA ANDAMIO | C19: 221000
B20: YORGUIN JAIMES ALQUILER MARZO | C20: 125000
A21: 46094 | B21: ELIAS RIOS ALQUILER MARZO 2026 | C21: 57600
B22: ALQUILER ALBA FEBRERO 27 A MARZO 12 | C22: 530000 | D22: 533350
B23: DIEGO GUTIERREZ ALQUILER 55 PARALES 6 MTS 14 AL 28 MARZO | C23: 250000 | D23: NEQUI
A24: 46095 | B24: RETIRO NEQUI | C24: 1000000 | D24: NEQUI
B25: LUIS SANCHEZ ALQUILER A 31 MARZO 2026 | C25: 727500
A26: 46097 | B26: PEDRO ROSAS SECCION DE ANDAMIOS MARZO 13 AL 17 | C26: 55000
B27: MAESTRO VIDAL COLUMNAS MARZO 12 AL 16 | C27: 250000
B28: RETIRO NEQUI | C28: 410620 | D28: NEQUI
A29: 46098 | B29: HERNAN TORRADO SALDO PLACA A 18 MARZO | C29: 247000
B30: ANDAMIOS DEL 2 AL 15 MARZO HERNAN TORRADO | C30: 200000
A31: 46100 | B31: CRUCE CUENTAS AFEBRERO CLAUDIA GIL | C31: 342135 | D31: NEQUI
B32: MAESTRO VIDAL ALQUILER 20 DE MARZO AL 3 DE ABRIL 2026 | C32: 1320000
A33: 46101 | B33: ABONO DIEGO GUTIERREZ | C33: 300000
A34: 46104 | B34: ABONO DIEGO GUTIERREZ | C34: 300000 | D34: NEQUI
A35: 46107 | B35: DANIEL CORREDOR MARZO | C35: 72000
B36: PEDRO JULIO MARZO | C36: 26350
B37: ELIBARDO GARCIA | C37: 96000
B38: BRAYAN MARZO | C38: 88000
B39: HERNAN TORRADO ALQUILER ANDAMIO 16 AL 22 MARZO | C39: 100000
B40: ALQUILER ESCALERA YORGUIN JAIMES | C40: 20000
...

Sheet ABRIL
B1: INGRESOS
B2: ABRIL 1 AL 30/ 2026
C3: =MARZO!C123 -> 4581555
A5: 46119 | B5: MARIA RUTH SAAVEDRA | C5: 900000 | D5: NEQUI
A6: 46120 | B6: DUBAN ORTEGA | C6: 500000 | D6: NEQUI
B7: JORGE ALEXANDER | C7: 800000 | D7: NEQUI
B8: RAUL DELGADO CARREÑO | C8: 300000 | D8: NEQUI
A9: 46127 | B9: RAUL QUINTERO | C9: 112000
A10: 46128 | B10: TILCIA URIBE DURAN | C10: 200000 | D10: NEQUI
B11: YINA MARCELA RAMOS | C11: 333683 | D11: NEQUI
B12: ALQUILER ANDAMIOS NARYAM BLANDON | C12: 25000
B13: ABONO PLACA 20 ABRIL DIEGO | C13: 300000 | D13: NEQUI
A14: 46131 | B14: ABRIL 11 AL 19 ANTONIO GUTIERREZ | C14: 314000
B15: ALQUILER MAESTRO RIGO ABRIL 21 A MAYO 5 | C15: 1500000
B16: EDUARDO CORREDOR ANDAMIOS | C16: 20000
B17: WILSON PARRA ANDAMIOS 21 AL 25 ABRIL | C17: 55000
B18: PARALES HERNANDO GARCIA | C18: 22000
A19: 46132 | B19: RETIRO POR NEQUI | C19: 2000000 | D19: NEQUI
A20: 46134 | B20: BRYAN GARZON ALQUILER ABRIL MARZO | C20: 30000
B21: NELSON PADILLA PAGO HASTA EL 21 ABRIL | C21: 722340
B22: HOLGUER ALQUILER PLACA | C22: 1300000
B23: LUIS CACERES A ABRIL 22 PARALES Y FORMALETA | C23: 79300
B24: GRERORIO HERNAN DEZ A ABRIL 21 | C24: 183700
A25: 46136 | B25: CESAR AUGUSTO HERNANDEZ | C25: 602500 | D25: NEQUI
A26: 46139 | B26: LUIS SANCHEZ ALQUILER ABRIL 1 AL 24 | C26: 966000
B27: EDUARDO TOLOZA ALQUILER FORMALETA 21 AL 24 ABRIL | C27: 210350
B28: ANDREI ALQUILER COLUMNAS PRIMER PISO ANDREI | C28: 917450 | D28: DAVIPLATA
A29: 46141 | B29: DUBAN ORTEGA 42 CHAPETAS | C29: 126000
B30: DUBAN ORTEGA SALDOALQUILE | C30: 91600
B31: PARALES DUBAN | C31: 56000
B32: HERNAN TORRADO ABRIL 1 AL 30 | C32: 687000
B33: JOSE LUIS SILVA 1 ANDAMIO | C33: 7500
B34: ELIAS RIOS | C34: 46400
B35: LAURA ROCHA | C35: 30000
C36: =SUM(C5:C35) -> 13437823
B38: EGRESOS
B39: ABRIL 1 AL 30/ 2026
A40: 46119 | B40: PAGO LINEA EMPRESA TIGO | C40: 26950 | D40: NEQUI
B41: PAGO LINEA EMPRESA TIGO | C41: 26950 | D41: NEQUI
A42: 46123 | B42: YANETH LUNA ABRIL 6 AL 11 ABRIL | C42: 400000
...

Sheet MAYO
B1: INGRESOS
B2: MAYO 1 AL 31/ 2026
C3: =ABRIL!C94 -> 6567088
A5: 46149 | B5: DIEGO GUTIERREZ PAGO ALQUILER DE 8 MAYO EN ADELANTE POR 15 DIAS TABLEROS MADERA Y CERCHAS | C5: 387000
B6: SACADOS DE NEQUI | C6: 200000
A7: 46150 | B7: ALQUILER YESENIA MURILLO | C7: 135000
B8: ALQUILER RAMIRO DULCEY | C8: 180000
A9: 46151 | B9: alquiler 4 columnas 30 x 20 del 11 al 15 myo villa carmelo GUSTAVO AFANADOR RUBIO | C9: 77750
A10: 46151 | B10: pago abril a mayo 5 adrian bravo JOHANA GUTIERREZ MORELOS | C10: 781740
B11: MAESTRO VIDAL ALQUILER COLUMNAS PRIMER PIS9O MAYO 12 AL 17 | C11: 400000
A12: 46155 | B12: ALQUILER ANDAMIOS ALINA | C12: BBVA
B13: MAESTERO RIGOBWERTO VARELA | C13: 250000
B14: ABONO ALQUILER ANDAMIOS JUAN DAVID ANGARITSA GUTIERREZ | C14: 300000
B15: ALQUILER COLUMNAS ROSA MAYO 14 AL 18 | C15: 300000
A16: 46157 | B16: ABONO JHON JIMENEZ ALQUILER A PARTIR 19 MAYO | C16: 500000
B17: ANDAMIOS LADI | C17: 50000
B18: FIDEL CARO MAYO | C18: 89000
B19: PEDRO ALQUILER AL 22 ABRIL | C19: 407000
A20: 46163 | B20: ALQUILER COLUMNAS MAESTRORONDON | C20: 352000
A21: 46164 | B21: CESAR ANDAMIOS A 21 MAYO | C21: 302000
A22: 46165 | B22: SACADOS CDE NEQUI | C22: 1000000
B23: ESCALERA VERDE LIDA | C23: 30000
A24: 46168 | B24: ALQUILER DIANA PUERTO RICO A PARTIR 27 MAYO 2026 | C24: 500000
B25: ALQUILER PLACA DIANA PUERTO RICO | C25: 1000000
B26: GIOVANI SIERRA ALQUILER 18 PARALES 4 MTS | C26: 93000
A27: 46170 | B27: PAGO ALQUILER COLUMNAS MAESTRO VIDAL | C27: 171200
A28: 46171 | B28: FABIANH ANDRES GARCIA PORTILLA SALIDA 13759 DEL 29 MAYO AL 5 5 JUNIO 2026 | C28: 388400
B29: DIEGO ARMANDO GUTIERREZ FLOREZ 13 760 29 MAYO AL 4 JUNIO PARALES 6 MTS Y CERVHA 2 MTS | C29: 18000
B30: FREDDY ESCAMILLA SAL 13761 12 PARALES 3 MTS Y 4 CERCHAS 3 MTS | C30: 100000
B31: ALQUILER ELIAS RIOS ALQUILER MAYO 2026 | C31: 500000
B32: ALQUILER EDUARDO TOLOZA | C32: 690000
B33: ALQUILER ANDAMIOS PEDRO JULIO PABON ENTRADA 133358 | C33: 25000
B34: MAESTRO VIDAL ALQUILER PLACA MAYO 20 AL 29 | C34: 445000
A35: 46173 | B35: ALQUILER HERNAN TORRADO MES DE MAYO 2026 | C35: 617000
C36: =SUM(C5:C35) -> 10289090
B38: EGRESOS
B39: MAYO 1 AL 31/ 2026
A41: 46146 | B41: 3 DISCOS E CORTE FERRERIA LA 21 | C41: 7500
A42: 46147 | B42: DESPINCHE CAMION JAC | C42: 25000
B43: PAGO 2 LINEAS TIGO EQUIORIENTE | C43: 53900 | D43: NEQUI
...

Sheet JUNIO
B1: INGRESOS
B2: JUNIO 1 AL 30/ 2026
C3: =MAYO!C94 -> 6038303
A5: 46174 | B5: ANTONIO GUTIERREZ ALQUILER PLACA BERLIN | C5: 1000000
B6: SERGIOP RUEDA ALQUILER PLACA METALICA | C6: 2000000
A7: 46176 | B7: SALDO ROSA A 29 MAYO | C7: 476000
B8: SALDO LUDWING MAYO 2026 | C8: 295700
A9: 46180 | B9: PAGO ALQUILER YURANIS | C9: 138100 | D9: BBVA
B10: BBVA DEPOSITO POR ALQUILER PLACA LA INDEPENDENCIA LUDWING | C10: 1500000 | D10: BBVA
B11: SALDO 7 MAYO A JUNIO 6 ELIAS RIOS | C11: 688000
B12: HERNAN TORRADO ALQUILER SECCIONES ANDAMIO CG Y TABLONES JUNIO 2 AL 8 | C12: 246300
B13: HERNAN TORRADO ALQUILER ANDAMIOS COLGANTES 9 DE JUNIO AL 23 | C13: 407500
B14: ALQUILER ESCALERA EXTENSION 6 MTS | C14: 90000
B15: EDUARDO TOLOZA MAYO 17 A JUNIO 5/2026 | C15: 1208000
B16: PAGO DE ALQUILER PLACA A JULIO 10 ANDREI | C16: 1000000 | D16: DAVIPLATA
A17: 46183 | B17: DEPOSITO POR NEQUI LUZ MARINAPEREZ ALQUILER POLEAS SALIDA 13792 | C17: 700000 | D17: NEQUI
B18: DEPOSITO POR NEQUI LUZ MARINA PEREZ ALQUILER POLEAS SALIDA 13792 | C18: 300000 | D18: NEQUI
B19: ALQUILER PRESTAMO ANDAMIOS SHIRLEY16 JUNIO2026 | C19: 151500 | D19: NEQUI | E19: 300000
A20: 46185 | B20: ALQUILER DE FORMALETA 60 X 120; FORMALETA 25 X 120 CSAR RINCON | C20: 273520 | D20: NEQUI
B21: ALQUILER YAZMIN PACHECO ALQUILER COLUMNAS DE 30 X 120 | C21: 277150 | D21: NEQUI | E21: 500000
A22: 46190 | B22: RETIRO NEQUI | C22: 1200000 | D22: NEQUI
B23: cesar augusto alquiler JUNIO 11 AL 17 | C23: 190600 | D23: EFECTIVO | E23: 500000 | F23: 339400
A24: 46191 | B24: ALQUILER FORMALETA COLUMNAS JOSE DAVID 19 AL 23 JUNIO | C24: 305500 | D24: NEQUI
B25: ALQUILER MAYO 29 A JUNIO 14 C ARLOS PINILLA | C25: 500000
B26: ALQUILER PLACA DOÑA ROSA SALIDA 13720 A PARTIR 19 JUNIO | C26: 1000000
B27: ELISEO ALQUILER ANDAMIOS JUNIO | C27: 257300
B28: RETIRO NEQUI | C28: 1300000 | D28: NEQUI
A29: 46197 | B29: ALQUILER FORMALETA COLUMNAS ELCY ANGELICA NIÑO AGUDELO | C29: 216000 | D29: NEQUI
B30: DEPOSITO ALQUILER FORMALETA COLUMNAS ELCY ANGELICA NIÑO AGUDELO | C30: 584800 | D30: NEQUI
B31: SALDO ADEUDADO JHON JIMENEZ A JUNIO 11 2026 | C31: 512500 | D31: NEQUI
A32: 46229 | B32: SALDO ALQUILER SAN FRANCISCO ANDREA A 19 JUNIO | C32: 184250 | D32: NEQUI
A33: 46200 | B33: ANTONIO GUTIERREZ PAGO 100 PARALES MAYO 7 A JUNIO 26 | C33: 845000
B34: NELSON PADILLA ALQUILER POLEAS JUNIO 14 AL 26 | C34: 445000
B35: JEFERSON ALQUILER JUNIO 22 AL 26 | C35: 82500
B36: ANTONIO GUTIERREZ ABONO PLACA MADERA JUNIO 5 AL 26 | C36: 500000
B37: FREDDY ESCAMILLA ALQUILER MAYO 29 A JUNIO 26 | C37: 39000
A38: 46203 | B38: PAGOSALDO PENDIENTE ALQUILER ROSA | C38: 316000
B39: PAGO REPOSICIONPENDIENTE ROSA | C39: 326000
B40: PAGO EN EFECTIVO EL 4 DE JULIO ALQUILER LUDWING JUNIO 9 AL 26 2026 | C40: 1957000
B41: PAGO ALQUILER PLACA CESAR RINCON | C41: 1500000 | D41: BBVA JIMMY
...

Sheet JULIO
B1: INGRESOS
B2: JULIO 1 AL 31/ 2026
C3: =JUNIO!C101 -> 15170981
A4: 46204 | B4: ALQUILER MAYO 29 A JUNIO 14 CARLOS MIGUEL MAYO | C4: 210840 | D4: NEQUI
B5: PAGO 10 CHAPETAS EXTRAVIADAS JUNIO CARLOS MIGUEL RAZON DE $3000 / UNIDAD | C5: 30000 | D5: NEQUI
B6: ABONO ALQUILER MATERIAL PLACA DE JULIO 1 AL 8 INCLUYE TRANSPORTE ANGELICA CONCORDIA | C6: 511000 | D6: NEQUI
B7: NELSON BERNAL JULIO | C7: 83000 | D7: NEQUI
A8: 46209 | B8: RECARGA DESDE BANCOLOMBIA POR ANDAMIOS | C8: 400000 | D8: NEQUI
B9: ANDREI CADENA ADICIONAL PLACA HASTA 10 DE JULIOY CIMENTACION DEL 8 AL 12 JULIO | C9: 804000 | D9: DAVIPLATA
A10: 46211 | B10: PAGO SALDO SERGIO JULIO 8 /2026 | C10: 2310880
B11: SACADOS DE NEQUI | C11: 630000 | D11: NEQUI
B12: ALFONSO GARCIA ALQUILER 5 DIAS COLUMNAS | C12: 237000
B13: ALFOSOL ALQUIKLER CORBATAS Y PLACA | C13: 215000
B14: HERNAN TORRADO ABONO ALQUILER JUNIO- JULIO 2026 | C14: 500000
B15: WILSON PAEZ DEPOS ITO POR ALQUILER | C15: 500000
B16: ALFONSO LIZCANO ESCALERA | C16: 30000
B17: JUAN DAVID ANGARITA | C17: 15000 | D17: EFECTIVO
A18: 46217 | B18: DEPOSITO WILSON PAEZ | C18: 200000 | D18: NEQUI
B19: SALDO ALQUIOBRAS A JUNIO 30 2026 | C19: 375550 | D19: NEQUI
A20: 46218 | B20: YURANIS JULIO 7 AL 13 | C20: 123400 | D20: NEQUI
B21: CONSIGNADO EN DAVIPLATA POR ANDREI | C21: 50000 | D21: DAVIPLATA
B22: WILSON PAEZ DEPOSITO | C22: 700000 | D22: NEQUI
B23: RETIRO BBVA PARA PAGO DIEGO ROJAS | C23: 1050000 | D23: BBVA EMPRESA
B24: PAGO ALQUILER TROMPO JAVIER MALDONADO | C24: 305000 | D24: BBVA JIMMY | E24: 1500000
B25: PAGO SALDO FVE 645 Y FVE 651 CICOM A JUNIO 30/2026 | C25: BBVA | D25: NEQUI503934
A26: 46219 | B26: ANGELICA SALDO VIEJO A 15 JULIO Y NUEVO A 31 JULIO | C26: 1717640 | D26: BBVA JIMMY
A27: 46220 | B27: ABONO ALQUILER PLACA WILSON PAEZ A PARTIR DEL 18 DE JULIO | C27: 1000000
A28: 46224 | B28: ALQUILER FORMALETA METALICA ALIRIO SUAREZ 22 JULIO EN ADELANTE | C28: 1000000
B29: ANDREI DAVIPLATA ABONO ALQUILER PLACA 11 AL 31 DE JULIO 2026 | C29: 1000000 | D29: DAVIPLATA | E29: SALDO $386,410
A30: 46225 | B30: SALDO A 31 JULIO ANDREI | C30: 313650 | D30: DAVIPLATA
B31: MIGUEL ANGEL FLOREZ CORREA ALQUILER ANDAMIOS JULIO | C31: 164000 | D31: NEQUI | E31: 300000
B32: DEPOSITO POR ALQUILER PLACA ALIRIO SUAREZ | C32: 101000
A33: 46226 | B33: DEPOSITO WILMER RONDON ALQUILER POLEAS | C33: 1000000 | D33: NEQUI
A34: 46227 | B34: RETIRO BBVA EMPRESA PARA COMPRA TRANSMISION | C34: 1500000 | D34: BBVA EMPRESA
B35: MAESTRO VIDAL ALQUILER POLEAS | C35: 900000 | D35: BBVA JIMMY
B36: 5 CONSTRUCCIONES ALQUILER RUEDAS DE ANDAMIO JUNIO | C36: BBVA EMPRESA | D36: NEQUI | E36: 190000
B37: MAESTRO JOSE ALQUILER PLACA 24 DE JULIO POR 14 DIAS CON TRANSPORTE | C37: 2050000 | D37: BBVA
B38: ALQUILER ALINA HACER FACTURA | D38: CONSIGNADO BBVA | E38: 44650
B39: HERNAN TORRADO SALDO ALQUILER A 24 JULIO 2026 | C39: 393000
A40: 46230 | B40: PAGO ALIRIO SUAREZ JULIO 27 A AGOSTO 7 | C40: 172680
...

Sheet AGOSTO
B1: INGRESOS
B2: AGOSTO 1 AL 31/ 2026
C3: =JULIO!C150 -> 25373983
A5: 46238 | B5: SALDO ALQUILER ANGELICA A 31 DE JULIO 2026 | C5: 1803000 | D5: BBVA JIMMY
A6: 46239 | B6: ALQUILER ANDAMIOS Y TABLONES JUAN CARLOS BAUTISTA | C6: NEQUI | D6: 100000
B7: ANDREI PAGO ALQUILER COLUMNAS A PARTIR AGOSTO 10 AL 14 | C7: 1000000 | D7: DAVIPLATA
B8: ANDREI ABONO A PLACA A PARTIR DEL 1 DE AGOSTO 2026
B9: ABONO PLACA MADERA MAURICIO CACERES LUIS A PARTIR 3 DE AGOSTO | C9: 2500000 | D9: BBVA JIMMY
A10: 46240 | B10: ABONO ALQUILER WILSON PAEZ | C10: 500000
A11: 46244 | B11: ABONO JOSE REDIN PLACA 11 AL 23 AGOPSTO 2026 | C11: 1000000
B12: pago alquiler julio GIOVANI SIERRA | C12: NEQUI | D12: 544000
B13: PAGO SALDO SERGIO ALQUILER AGOSTO PLACA MADERA | C13: 102000
A14: 46245 | B14: PAGO DE 2FORMALETA 60 X120; 1 FORMALETAS DE 30X 120 SACAR DEL INVENTARIO CONSORCIO EN AGOSTO | C14: 660000 | D14: NEQUI
B15: ELIAS RIOS ALQUILER JULIO | C15: 163000
B16: ESCALERA | C16: 30000
B17: PAGO ALQUILER ANDAMIOS WILLIAM PARRA | C17: 68000
B18: PAGO ALDO ALIRIO SUAREZ | C18: 157000
B19: ABONO PEDRO ROSAS POLEAS JULIO | C19: 250000
A20: 46246 | B20: ALEXANDER BAUYTISTA ALQUILER SECCIONES ANDAMIO | C20: 57500 | D20: NEQUI
A21: 46248 | B21: sacados de nequi PRESTADO A DIEGO Y DEVOLVIO CON 1 BILLETE DE $100,000 | C21: 50000 | D21: NEQUI
B22: HERNAN TORRADO SALDO A AGOSTO 15 2026 | C22: 114000
A23: 46249 | B23: SACADOS BBVA PAGAR PRIMERA DIEGO ROJAS QUINCENA AGOSTO 2026 | C23: 950000 | D23: BBVA EMPRESA
B24: YORGUIN JAIMES ALQUILER COLUMNAS AGOSTO | C24: 110000
B25: FELIX CARRILLO ALQUILER JULIO | C25: 347600
B26: YORGUIN JAIMES ALQUILER ANDAMIOS | D26: 50000
B27: GUILLERMO HERNANDEZ ALQUILER ANDAMIOS 14 AL 18 AGOSTO | C27: 45000
A28: 46252 | B28: CRISTIAN RUGELES ALQUILER PLACA METALICA POR 15 DIAS | C28: 1500000 | D28: NEQUI
B29: ALQUILER ESCALERA YORGUIN JAIMES | C29: 20000
B30: PAGO ESCALERA EXTENSION 4M A 8 | C30: 30000
A31: 46253 | B31: ALQUILER COLUMNAS 14 AL 19 AGOSTO 2026 PEDRO JUAN PRADA | D31: 732000
B32: ANGELICA ALQUILER AGOSTO 1 AL 10 | C32: 690120 | D32: BANCOLOMBIA
B33: ANGELICA 1 PARAL 3, 1 CERCHA DE 1 MTS Y 19 CHAPETAS EXTRAVIADAS; DAÑO CERCHA 3 MTS | C33: 232500 | D33: BANCOLOMBIA
B34: ALEX BAUTISTA ALQUILER ESCALERA EXTENSION 2M A 8 M 20 Y 21| AGOSTO | C34: 40000
A35: 46255 | B35: PAGO ALQUILER PLACA PEQUEÑA VIDAL | C35: 348500
A36: 46256 | B36: ALQUILER LUZ MARINA CARREÑO AGOSTO 11 AL 22 | D36: 145500
B37: ABONO AL PRESTAMO DE EIDER | C37: 400000 | D37: NEQUI
B38: GUSTAVO ADOLFO RUBIO ABONO ALQUILER PLACA VILLACARMELO A PARTIR AGOSTO 25 2026 | C38: 1200000 | D38: BANCOLOMBIA
A39: 46258 | B39: ABONO ALQUILER 4 POLEAS FRANCY LILIANA | C39: 304000
B40: PAGO ALQUILER DE 5 DIAS OMAR PABON AGOSTO 24 AL 28 2026 | C40: 253600 | D40: NEQUI
B41: ALQUILER ROBINSON MUÑOZ CASTRO | D41: 127500
...

Sheet SEPTIEMBRE
B1: INGRESOS
B2: SEPTIEMBRE 1 AL 30/ 2026
C3: =AGOSTO!C146 -> 34228579
A4: 46266 | B4: ALQUILER ESCALERQA SEPTIEMBRE 1 Y 2 EDINSON JAIMES | C4: 30000
B5: SALDO JOHANA EL PEDREGAL | C5: 60240 | D5: NEQUI
B6: DEPOSITO FREDY LENGUA | C6: 500000 | D6: NEQUI
B7: MAESTRO VIDAL ALQUILER COLUMNAS | C7: 272000 | D7: NEQUI
A8: 46267 | B8: ENRIQUE PEREZ ALQUILER ANDAMIOS | C8: 122500
B9: JOSE MAURICIO CACERES ORTIZ SALDO PLACA | C9: 681300 | D9: NEQUI
A10: 46268 | B10: MIGUEL ANGEL FLOREZ DEPOSITO SAL 3988 | C10: 300000 | D10: NEQUI
B11: GONZALO PAGO ALQUILER2 SECCIONES Y 1 TABLON | C11: NEQUI | D11: 20000
B12: PAGO SALDO ELIAS PATIÑO | D12: 26000
A13: 46269 | B13: SACADOS DE NEQUI ( ENVIADOS A FRANCY LILIANA) | C13: 1000000 | D13: NEQUI
C22: =SUM(C4:C21) -> 2966040
B26: EGRESOS
B27: SEPTIEMBRE 1 AL 30/ 2026
A28: 46266 | B28: INDURRUEDAS COMPRA DE 25 LIBRAS PUNTILLAS CABALLO | C28: 201320
B29: ABONO HECHURA TABLAS | C29: 100000
A30: 46267 | B30: vueltos cristian rugeles | C30: 427960 | D30: nequi
B31: pago aldo rabac salidas | C31: 80900 | D31: pendiente factura
B32: FERRETERIA FIXXY 26233( 2 BERMELLON) | C32: 20000
B33: FEJG1930 SILENCIADORES LA 14 ( VENTA E INSTALACION DE FLEXIBLE ECUALIZABLE EN ACERO INOXIDABLE PO 2 | C33: 300000 | D33: IVA
B34: TRANSPORTE AMIGUEL ANGERL FLOREZ ALFONSO LOPEZ | C34: 50000 | D34: NEQUI
A35: 46268 | B35: FREDY LENGUA VUELTOS | C35: 407775 | D35: NEQUI
B36: PAGO RECOGIDA NOEL GUERRA | C36: 40000 | D36: NEQUI
B37: TODO ELCTRICOS FVE TDE50568 ( 1 VALCULA DE FRENO AHOGO JAC Y CONECTOR | C37: 150000
B38: ALMACEN REYCOL SAS 1 TUBERIA DE HIERRO Y SILICONA | C38: 51826
A39: 46269 | B39: ALMACEN REYCOL SAS COMP. No 5A 33131( PEDAZO DE MANGUERA Y DOS ABRAZADERAS) | C39: 6609
C105: =SUM(C28:C104) -> 1836390
C106: =C3+C22-C105 -> 35358229

Sheet ALQUILER NO FISCAL 
